Workbook

Sheet README
A1: Field | B1: Value
A2: File | B2: Baseline_summary_result.xlsx
A3: Source | B3: Phylospec/multi_models/results/holdout
A4: Generated | B4: 2026-09-11
A5: Results included | B5: 130 CSV files; 650 per-flag rows and 130 supplied MACRO rows.
A6: Evaluation | B6: Single holdout split; point estimates only. No CV repeats or confidence intervals are supplied.
A7: Macro values | B7: Copied directly from each source CSV MACRO row; not recomputed.
A8: Injection | B8: with/without are copied from source metadata. unspecified means the source CSV has no injection field; these runs are retained separately.
A9: Missing values | B9: Empty or non-finite source values appear as blank cells.
A10: Source traceability | B10: source_file identifies the original CSV for every result and support row.
A11: Genus_PerFlag / Genus_MacroAvg | B11: Genus-tree results, including separately reported injection variants.
A12: ASV_PerFlag / ASV_MacroAvg | B12: ASV-tree results, including separately reported injection variants.
... A18: threshold | B18: Decision threshold supplied for each flag.

Sheet Summary
B1: 1) TaxLevel
B2: Dataset | C2: Flag | D2: n_pos | E2: prevalence | F2: MCC | K2: AUPR | P2: F2
F3: Phylum | G3: Class | H3: Order | I3: Family | J3: Genus | K3: Phylum | L3: Class | M3: Order | N3: Family | O3: Genus | P3: Phylum | Q3: Class | R3: Order | S3: Family | T3: Genus
B4: ARC | C4: buffer_capacity | D4: 9 | E4: 0.065217391 | F4: =_xlfn.MAXIFS(TaxLevel_PerFlag!$K:$K,TaxLevel_PerFlag!$A:$A,F$3,TaxLevel_PerFlag!$B:$B,$B$4,TaxLevel_PerFlag!$E:$E,$C4) -> 0.47245559 | G4: =_xlfn.MAXIFS(TaxLevel_PerFlag!$K:$K,TaxLevel_PerFlag!$A:$A,G$3,TaxLevel_PerFlag!$B:$B,$B$4,TaxLevel_PerFlag!$E:$E,$C4) -> 0.18257419 | H4: =_xlfn.MAXIFS(TaxLevel_PerFlag!$K:$K,TaxLevel_PerFlag!$A:$A,H$3,TaxLevel_PerFlag!$B:$B,$B$4,TaxLevel_PerFlag!$E:$E,$C4) -> 0.20965697 | I4: =_xlfn.MAXIFS(TaxLevel_PerFlag!$K:$K,TaxLevel_PerFlag!$A:$A,I$3,TaxLevel_PerFlag!$B:$B,$B$4,TaxLevel_PerFlag!$E:$E,$C4) -> 0.18257419 | J4: =_xlfn.MAXIFS(TaxLevel_PerFlag!$K:$K,TaxLevel_PerFlag!$A:$A,J$3,TaxLevel_PerFlag!$B:$B,$B$4,TaxLevel_PerFlag!$E:$E,$C4) -> 0.15877684 | K4: =_xlfn.MAXIFS(TaxLevel_PerFlag!$H:$H,TaxLevel_PerFlag!$A:$A,K$3,TaxLevel_PerFlag!$B:$B,$B$4,TaxLevel_PerFlag!$E:$E,$C4) -> 0.33333333 | L4: =_xlfn.MAXIFS(TaxLevel_PerFlag!$H:$H,TaxLevel_PerFlag!$A:$A,L$3,TaxLevel_PerFlag!$B:$B,$B$4,TaxLevel_PerFlag!$E:$E,$C4) -> 1 | M4: =_xlfn.MAXIFS(TaxLevel_PerFlag!$H:$H,TaxLevel_PerFlag!$A:$A,M$3,TaxLevel_PerFlag!$B:$B,$B$4,TaxLevel_PerFlag!$E:$E,$C4) -> 1 | N4: =_xlfn.MAXIFS(TaxLevel_PerFlag!$H:$H,TaxLevel_PerFlag!$A:$A,N$3,TaxLevel_PerFlag!$B:$B,$B$4,TaxLevel_PerFlag!$E:$E,$C4) -> 0.083333333 | O4: =_xlfn.MAXIFS(TaxLevel_PerFlag!$H:$H,TaxLevel_PerFlag!$A:$A,O$3,TaxLevel_PerFlag!$B:$B,$B$4,TaxLevel_PerFlag!$E:$E,$C4) -> 0.2 | P4: =_xlfn.MAXIFS(TaxLevel_PerFlag!$L:$L,TaxLevel_PerFlag!$A:$A,P$3,TaxLevel_PerFlag!$B:$B,$B$4,TaxLevel_PerFlag!$E:$E,$C4) -> 0.625 | Q4: =_xlfn.MAXIFS(TaxLevel_PerFlag!$L:$L,TaxLevel_PerFlag!$A:$A,Q$3,TaxLevel_PerFlag!$B:$B,$B$4,TaxLevel_PerFlag!$E:$E,$C4) -> 0.26315789 | R4: =_xlfn.MAXIFS(TaxLevel_PerFlag!$L:$L,TaxLevel_PerFlag!$A:$A,R$3,TaxLevel_PerFlag!$B:$B,$B$4,TaxLevel_PerFlag!$E:$E,$C4) -> 0.29411765 | S4: =_xlfn.MAXIFS(TaxLevel_PerFlag!$L:$L,TaxLevel_PerFlag!$A:$A,S$3,TaxLevel_PerFlag!$B:$B,$B$4,TaxLevel_PerFlag!$E:$E,$C4) -> 0.26315789 | T4: =_xlfn.MAXIFS(TaxLevel_PerFlag!$L:$L,TaxLevel_PerFlag!$A:$A,T$3,TaxLevel_PerFlag!$B:$B,$B$4,TaxLevel_PerFlag!$E:$E,$C4) -> 0.23809524
C5: acid_base_balance | D5: 4 | E5: 0.028985507 | F5: =_xlfn.MAXIFS(TaxLevel_PerFlag!$K:$K,TaxLevel_PerFlag!$A:$A,F$3,TaxLevel_PerFlag!$B:$B,$B$4,TaxLevel_PerFlag!$E:$E,$C5) -> 0.16919084 | G5: =_xlfn.MAXIFS(TaxLevel_PerFlag!$K:$K,TaxLevel_PerFlag!$A:$A,G$3,TaxLevel_PerFlag!$B:$B,$B$4,TaxLevel_PerFlag!$E:$E,$C5) -> 0.275 | H5: =_xlfn.MAXIFS(TaxLevel_PerFlag!$K:$K,TaxLevel_PerFlag!$A:$A,H$3,TaxLevel_PerFlag!$B:$B,$B$4,TaxLevel_PerFlag!$E:$E,$C5) -> 0.033333333 | I5: =_xlfn.MAXIFS(TaxLevel_PerFlag!$K:$K,TaxLevel_PerFlag!$A:$A,I$3,TaxLevel_PerFlag!$B:$B,$B$4,TaxLevel_PerFlag!$E:$E,$C5) -> 0.38251843 | J5: =_xlfn.MAXIFS(TaxLevel_PerFlag!$K:$K,TaxLevel_PerFlag!$A:$A,J$3,TaxLevel_PerFlag!$B:$B,$B$4,TaxLevel_PerFlag!$E:$E,$C5) -> 0 | K5: =_xlfn.MAXIFS(TaxLevel_PerFlag!$H:$H,TaxLevel_PerFlag!$A:$A,K$3,TaxLevel_PerFlag!$B:$B,$B$4,TaxLevel_PerFlag!$E:$E,$C5) -> 0.56114943 | L5: =_xlfn.MAXIFS(TaxLevel_PerFlag!$H:$H,TaxLevel_PerFlag!$A:$A,L$3,TaxLevel_PerFlag!$B:$B,$B$4,TaxLevel_PerFlag!$E:$E,$C5) -> 0.3654386 | M5: =_xlfn.MAXIFS(TaxLevel_PerFlag!$H:$H,TaxLevel_PerFlag!$A:$A,M$3,TaxLevel_PerFlag!$B:$B,$B$4,TaxLevel_PerFlag!$E:$E,$C5) -> 0.27594771 | N5: =_xlfn.MAXIFS(TaxLevel_PerFlag!$H:$H,TaxLevel_PerFlag!$A:$A,N$3,TaxLevel_PerFlag!$B:$B,$B$4,TaxLevel_PerFlag!$E:$E,$C5) -> 0.33238095 | O5: =_xlfn.MAXIFS(TaxLevel_PerFlag!$H:$H,TaxLevel_PerFlag!$A:$A,O$3,TaxLevel_PerFlag!$B:$B,$B$4,TaxLevel_PerFlag!$E:$E,$C5) -> 0.23520817 | P5: =_xlfn.MAXIFS(TaxLevel_PerFlag!$L:$L,TaxLevel_PerFlag!$A:$A,P$3,TaxLevel_PerFlag!$B:$B,$B$4,TaxLevel_PerFlag!$E:$E,$C5) -> 0.37037037 | Q5: =_xlfn.MAXIFS(TaxLevel_PerFlag!$L:$L,TaxLevel_PerFlag!$A:$A,Q$3,TaxLevel_PerFlag!$B:$B,$B$4,TaxLevel_PerFlag!$E:$E,$C5) -> 0.4 | R5: =_xlfn.MAXIFS(TaxLevel_PerFlag!$L:$L,TaxLevel_PerFlag!$A:$A,R$3,TaxLevel_PerFlag!$B:$B,$B$4,TaxLevel_PerFlag!$E:$E,$C5) -> 0.2 | S5: =_xlfn.MAXIFS(TaxLevel_PerFlag!$L:$L,TaxLevel_PerFlag!$A:$A,S$3,TaxLevel_PerFlag!$B:$B,$B$4,TaxLevel_PerFlag!$E:$E,$C5) -> 0.55555556 | T5: =_xlfn.MAXIFS(TaxLevel_PerFlag!$L:$L,TaxLevel_PerFlag!$A:$A,T$3,TaxLevel_PerFlag!$B:$B,$B$4,TaxLevel_PerFlag!$E:$E,$C5) -> 0.29411765
C6: acid_accumulation | D6: 20 | E6: 0.14492754 | F6: =_xlfn.MAXIFS(TaxLevel_PerFlag!$K:$K,TaxLevel_PerFlag!$A:$A,F$3,TaxLevel_PerFlag!$B:$B,$B$4,TaxLevel_PerFlag!$E:$E,$C6) -> 1 | G6: =_xlfn.MAXIFS(TaxLevel_PerFlag!$K:$K,TaxLevel_PerFlag!$A:$A,G$3,TaxLevel_PerFlag!$B:$B,$B$4,TaxLevel_PerFlag!$E:$E,$C6) -> 0 | H6: =_xlfn.MAXIFS(TaxLevel_PerFlag!$K:$K,TaxLevel_PerFlag!$A:$A,H$3,TaxLevel_PerFlag!$B:$B,$B$4,TaxLevel_PerFlag!$E:$E,$C6) -> 0 | I6: =_xlfn.MAXIFS(TaxLevel_PerFlag!$K:$K,TaxLevel_PerFlag!$A:$A,I$3,TaxLevel_PerFlag!$B:$B,$B$4,TaxLevel_PerFlag!$E:$E,$C6) -> 0.69436507 | J6: =_xlfn.MAXIFS(TaxLevel_PerFlag!$K:$K,TaxLevel_PerFlag!$A:$A,J$3,TaxLevel_PerFlag!$B:$B,$B$4,TaxLevel_PerFlag!$E:$E,$C6) -> 1 | K6: =_xlfn.MAXIFS(TaxLevel_PerFlag!$H:$H,TaxLevel_PerFlag!$A:$A,K$3,TaxLevel_PerFlag!$B:$B,$B$4,TaxLevel_PerFlag!$E:$E,$C6) -> 1 | L6: =_xlfn.MAXIFS(TaxLevel_PerFlag!$H:$H,TaxLevel_PerFlag!$A:$A,L$3,TaxLevel_PerFlag!$B:$B,$B$4,TaxLevel_PerFlag!$E:$E,$C6) -> 0.33333333 | M6: =_xlfn.MAXIFS(TaxLevel_PerFlag!$H:$H,TaxLevel_PerFlag!$A:$A,M$3,TaxLevel_PerFlag!$B:$B,$B$4,TaxLevel_PerFlag!$E:$E,$C6) -> 0.33333333 | N6: =_xlfn.MAXIFS(TaxLevel_PerFlag!$H:$H,TaxLevel_PerFlag!$A:$A,N$3,TaxLevel_PerFlag!$B:$B,$B$4,TaxLevel_PerFlag!$E:$E,$C6) -> 1 | O6: =_xlfn.MAXIFS(TaxLevel_PerFlag!$H:$H,TaxLevel_PerFlag!$A:$A,O$3,TaxLevel_PerFlag!$B:$B,$B$4,TaxLevel_PerFlag!$E:$E,$C6) -> 1 | P6: =_xlfn.MAXIFS(TaxLevel_PerFlag!$L:$L,TaxLevel_PerFlag!$A:$A,P$3,TaxLevel_PerFlag!$B:$B,$B$4,TaxLevel_PerFlag!$E:$E,$C6) -> 1 | Q6: =_xlfn.MAXIFS(TaxLevel_PerFlag!$L:$L,TaxLevel_PerFlag!$A:$A,Q$3,TaxLevel_PerFlag!$B:$B,$B$4,TaxLevel_PerFlag!$E:$E,$C6) -> 0 | R6: =_xlfn.MAXIFS(TaxLevel_PerFlag!$L:$L,TaxLevel_PerFlag!$A:$A,R$3,TaxLevel_PerFlag!$B:$B,$B$4,TaxLevel_PerFlag!$E:$E,$C6) -> 0 | S6: =_xlfn.MAXIFS(TaxLevel_PerFlag!$L:$L,TaxLevel_PerFlag!$A:$A,S$3,TaxLevel_PerFlag!$B:$B,$B$4,TaxLevel_PerFlag!$E:$E,$C6) -> 0.83333333 | T6: =_xlfn.MAXIFS(TaxLevel_PerFlag!$L:$L,TaxLevel_PerFlag!$A:$A,T$3,TaxLevel_PerFlag!$B:$B,$B$4,TaxLevel_PerFlag!$E:$E,$C6) -> 1
C7: ammonia_toxicity | D7: 26 | E7: 0.1884058 | F7: =_xlfn.MAXIFS(TaxLevel_PerFlag!$K:$K,TaxLevel_PerFlag!$A:$A,F$3,TaxLevel_PerFlag!$B:$B,$B$4,TaxLevel_PerFlag!$E:$E,$C7) -> 0.61162352 | G7: =_xlfn.MAXIFS(TaxLevel_PerFlag!$K:$K,TaxLevel_PerFlag!$A:$A,G$3,TaxLevel_PerFlag!$B:$B,$B$4,TaxLevel_PerFlag!$E:$E,$C7) -> 0.61162352 | H7: =_xlfn.MAXIFS(TaxLevel_PerFlag!$K:$K,TaxLevel_PerFlag!$A:$A,H$3,TaxLevel_PerFlag!$B:$B,$B$4,TaxLevel_PerFlag!$E:$E,$C7) -> 0.61162352 | I7: =_xlfn.MAXIFS(TaxLevel_PerFlag!$K:$K,TaxLevel_PerFlag!$A:$A,I$3,TaxLevel_PerFlag!$B:$B,$B$4,TaxLevel_PerFlag!$E:$E,$C7) -> 0.70912421 | J7: =_xlfn.MAXIFS(TaxLevel_PerFlag!$K:$K,TaxLevel_PerFlag!$A:$A,J$3,TaxLevel_PerFlag!$B:$B,$B$4,TaxLevel_PerFlag!$E:$E,$C7) -> 0.64807407 | K7: =_xlfn.MAXIFS(TaxLevel_PerFlag!$H:$H,TaxLevel_PerFlag!$A:$A,K$3,TaxLevel_PerFlag!$B:$B,$B$4,TaxLevel_PerFlag!$E:$E,$C7) -> 0.72916667 | L7: =_xlfn.MAXIFS(TaxLevel_PerFlag!$H:$H,TaxLevel_PerFlag!$A:$A,L$3,TaxLevel_PerFlag!$B:$B,$B$4,TaxLevel_PerFlag!$E:$E,$C7) -> 0.53448276 | M7: =_xlfn.MAXIFS(TaxLevel_PerFlag!$H:$H,TaxLevel_PerFlag!$A:$A,M$3,TaxLevel_PerFlag!$B:$B,$B$4,TaxLevel_PerFlag!$E:$E,$C7) -> 0.53448276 | N7: =_xlfn.MAXIFS(TaxLevel_PerFlag!$H:$H,TaxLevel_PerFlag!$A:$A,N$3,TaxLevel_PerFlag!$B:$B,$B$4,TaxLevel_PerFlag!$E:$E,$C7) -> 0.85 | O7: =_xlfn.MAXIFS(TaxLevel_PerFlag!$H:$H,TaxLevel_PerFlag!$A:$A,O$3,TaxLevel_PerFlag!$B:$B,$B$4,TaxLevel_PerFlag!$E:$E,$C7) -> 0.70952381 | P7: =_xlfn.MAXIFS(TaxLevel_PerFlag!$L:$L,TaxLevel_PerFlag!$A:$A,P$3,TaxLevel_PerFlag!$B:$B,$B$4,TaxLevel_PerFlag!$E:$E,$C7) -> 0.76923077 | Q7: =_xlfn.MAXIFS(TaxLevel_PerFlag!$L:$L,TaxLevel_PerFlag!$A:$A,Q$3,TaxLevel_PerFlag!$B:$B,$B$4,TaxLevel_PerFlag!$E:$E,$C7) -> 0.71428571 | R7: =_xlfn.MAXIFS(TaxLevel_PerFlag!$L:$L,TaxLevel_PerFlag!$A:$A,R$3,TaxLevel_PerFlag!$B:$B,$B$4,TaxLevel_PerFlag!$E:$E,$C7) -> 0.71428571 | S7: =_xlfn.MAXIFS(TaxLevel_PerFlag!$L:$L,TaxLevel_PerFlag!$A:$A,S$3,TaxLevel_PerFlag!$B:$B,$B$4,TaxLevel_PerFlag!$E:$E,$C7) -> 0.86956522 | T7: =_xlfn.MAXIFS(TaxLevel_PerFlag!$L:$L,TaxLevel_PerFlag!$A:$A,T$3,TaxLevel_PerFlag!$B:$B,$B$4,TaxLevel_PerFlag!$E:$E,$C7) -> 0.83333333
C8: biogas_quality | D8: 7 | E8: 0.050724638 | F8: =_xlfn.MAXIFS(TaxLevel_PerFlag!$K:$K,TaxLevel_PerFlag!$A:$A,F$3,TaxLevel_PerFlag!$B:$B,$B$4,TaxLevel_PerFlag!$E:$E,$C8) -> 0 | G8: =_xlfn.MAXIFS(TaxLevel_PerFlag!$K:$K,TaxLevel_PerFlag!$A:$A,G$3,TaxLevel_PerFlag!$B:$B,$B$4,TaxLevel_PerFlag!$E:$E,$C8) -> 0 | H8: =_xlfn.MAXIFS(TaxLevel_PerFlag!$K:$K,TaxLevel_PerFlag!$A:$A,H$3,TaxLevel_PerFlag!$B:$B,$B$4,TaxLevel_PerFlag!$E:$E,$C8) -> 0 | I8: =_xlfn.MAXIFS(TaxLevel_PerFlag!$K:$K,TaxLevel_PerFlag!$A:$A,I$3,TaxLevel_PerFlag!$B:$B,$B$4,TaxLevel_PerFlag!$E:$E,$C8) -> 0.2360294 | J8: =_xlfn.MAXIFS(TaxLevel_PerFlag!$K:$K,TaxLevel_PerFlag!$A:$A,J$3,TaxLevel_PerFlag!$B:$B,$B$4,TaxLevel_PerFlag!$E:$E,$C8) -> 0 | K8: =_xlfn.MAXIFS(TaxLevel_PerFlag!$H:$H,TaxLevel_PerFlag!$A:$A,K$3,TaxLevel_PerFlag!$B:$B,$B$4,TaxLevel_PerFlag!$E:$E,$C8) -> 0.14215686 | L8: =_xlfn.MAXIFS(TaxLevel_PerFlag!$H:$H,TaxLevel_PerFlag!$A:$A,L$3,TaxLevel_PerFlag!$B:$B,$B$4,TaxLevel_PerFlag!$E:$E,$C8) -> 0.175 | M8: =_xlfn.MAXIFS(TaxLevel_PerFlag!$H:$H,TaxLevel_PerFlag!$A:$A,M$3,TaxLevel_PerFlag!$B:$B,$B$4,TaxLevel_PerFlag!$E:$E,$C8) -> 0.19642857 | N8: =_xlfn.MAXIFS(TaxLevel_PerFlag!$H:$H,TaxLevel_PerFlag!$A:$A,N$3,TaxLevel_PerFlag!$B:$B,$B$4,TaxLevel_PerFlag!$E:$E,$C8) -> 0.225 | O8: =_xlfn.MAXIFS(TaxLevel_PerFlag!$H:$H,TaxLevel_PerFlag!$A:$A,O$3,TaxLevel_PerFlag!$B:$B,$B$4,TaxLevel_PerFlag!$E:$E,$C8) -> 0.18333333 | P8: =_xlfn.MAXIFS(TaxLevel_PerFlag!$L:$L,TaxLevel_PerFlag!$A:$A,P$3,TaxLevel_PerFlag!$B:$B,$B$4,TaxLevel_PerFlag!$E:$E,$C8) -> 0 | Q8: =_xlfn.MAXIFS(TaxLevel_PerFlag!$L:$L,TaxLevel_PerFlag!$A:$A,Q$3,TaxLevel_PerFlag!$B:$B,$B$4,TaxLevel_PerFlag!$E:$E,$C8) -> 0 | R8: =_xlfn.MAXIFS(TaxLevel_PerFlag!$L:$L,TaxLevel_PerFlag!$A:$A,R$3,TaxLevel_PerFlag!$B:$B,$B$4,TaxLevel_PerFlag!$E:$E,$C8) -> 0 | S8: =_xlfn.MAXIFS(TaxLevel_PerFlag!$L:$L,TaxLevel_PerFlag!$A:$A,S$3,TaxLevel_PerFlag!$B:$B,$B$4,TaxLevel_PerFlag!$E:$E,$C8) -> 0.38461538 | T8: =_xlfn.MAXIFS(TaxLevel_PerFlag!$L:$L,TaxLevel_PerFlag!$A:$A,T$3,TaxLevel_PerFlag!$B:$B,$B$4,TaxLevel_PerFlag!$E:$E,$C8) -> 0
C9: Macro-avg | F9: =AVERAGE(F4:F8) -> 0.45065399 | G9: =AVERAGE(G4:G8) -> 0.21383954 | H9: =AVERAGE(H4:H8) -> 0.17092276 | I9: =AVERAGE(I4:I8) -> 0.44092226 | J9: =AVERAGE(J4:J8) -> 0.36137018 | K9: =AVERAGE(K4:K8) -> 0.55316126 | L9: =AVERAGE(L4:L8) -> 0.48165094 | M9: =AVERAGE(M4:M8) -> 0.46803848 | ... T9: =AVERAGE(T4:T8) -> 0.47310924
B10: BAC | C10: buffer_capacity | D10: 9 | E10: 0.065217391 | F10: =_xlfn.MAXIFS(TaxLevel_PerFlag!$K:$K,TaxLevel_PerFlag!$A:$A,F$3,TaxLevel_PerFlag!$B:$B,$B$10,TaxLevel_PerFlag!$E:$E,$C10) -> 0.37000643 | G10: =_xlfn.MAXIFS(TaxLevel_PerFlag!$K:$K,TaxLevel_PerFlag!$A:$A,G$3,TaxLevel_PerFlag!$B:$B,$B$10,TaxLevel_PerFlag!$E:$E,$C10) -> 1 | H10: =_xlfn.MAXIFS(TaxLevel_PerFlag!$K:$K,TaxLevel_PerFlag!$A:$A,H$3,TaxLevel_PerFlag!$B:$B,$B$10,TaxLevel_PerFlag!$E:$E,$C10) -> 0.47245559 | I10: =_xlfn.MAXIFS(TaxLevel_PerFlag!$K:$K,TaxLevel_PerFlag!$A:$A,I$3,TaxLevel_PerFlag!$B:$B,$B$10,TaxLevel_PerFlag!$E:$E,$C10) -> 0.3350297 | J10: =_xlfn.MAXIFS(TaxLevel_PerFlag!$K:$K,TaxLevel_PerFlag!$A:$A,J$3,TaxLevel_PerFlag!$B:$B,$B$10,TaxLevel_PerFlag!$E:$E,$C10) -> 0.37000643 | K10: =_xlfn.MAXIFS(TaxLevel_PerFlag!$H:$H,TaxLevel_PerFlag!$A:$A,K$3,TaxLevel_PerFlag!$B:$B,$B$10,TaxLevel_PerFlag!$E:$E,$C10) -> 0.25 | L10: =_xlfn.MAXIFS(TaxLevel_PerFlag!$H:$H,TaxLevel_PerFlag!$A:$A,L$3,TaxLevel_PerFlag!$B:$B,$B$10,TaxLevel_PerFlag!$E:$E,$C10) -> 1 | M10: =_xlfn.MAXIFS(TaxLevel_PerFlag!$H:$H,TaxLevel_PerFlag!$A:$A,M$3,TaxLevel_PerFlag!$B:$B,$B$10,TaxLevel_PerFlag!$E:$E,$C10) -> 0.5 | N10: =_xlfn.MAXIFS(TaxLevel_PerFlag!$H:$H,TaxLevel_PerFlag!$A:$A,N$3,TaxLevel_PerFlag!$B:$B,$B$10,TaxLevel_PerFlag!$E:$E,$C10) -> 0.5 | O10: =_xlfn.MAXIFS(TaxLevel_PerFlag!$H:$H,TaxLevel_PerFlag!$A:$A,O$3,TaxLevel_PerFlag!$B:$B,$B$10,TaxLevel_PerFlag!$E:$E,$C10) -> 0.5 | P10: =_xlfn.MAXIFS(TaxLevel_PerFlag!$L:$L,TaxLevel_PerFlag!$A:$A,P$3,TaxLevel_PerFlag!$B:$B,$B$10,TaxLevel_PerFlag!$E:$E,$C10) -> 0.5 | Q10: =_xlfn.MAXIFS(TaxLevel_PerFlag!$L:$L,TaxLevel_PerFlag!$A:$A,Q$3,TaxLevel_PerFlag!$B:$B,$B$10,TaxLevel_PerFlag!$E:$E,$C10) -> 1 | R10: =_xlfn.MAXIFS(TaxLevel_PerFlag!$L:$L,TaxLevel_PerFlag!$A:$A,R$3,TaxLevel_PerFlag!$B:$B,$B$10,TaxLevel_PerFlag!$E:$E,$C10) -> 0.625 | S10: =_xlfn.MAXIFS(TaxLevel_PerFlag!$L:$L,TaxLevel_PerFlag!$A:$A,S$3,TaxLevel_PerFlag!$B:$B,$B$10,TaxLevel_PerFlag!$E:$E,$C10) -> 0.45454545 | T10: =_xlfn.MAXIFS(TaxLevel_PerFlag!$L:$L,TaxLevel_PerFlag!$A:$A,T$3,TaxLevel_PerFlag!$B:$B,$B$10,TaxLevel_PerFlag!$E:$E,$C10) -> 0.5
C11: acid_base_balance | D11: 4 | E11: 0.028985507 | F11: =_xlfn.MAXIFS(TaxLevel_PerFlag!$K:$K,TaxLevel_PerFlag!$A:$A,F$3,TaxLevel_PerFlag!$B:$B,$B$10,TaxLevel_PerFlag!$E:$E,$C11) -> 0.4444578 | G11: =_xlfn.MAXIFS(TaxLevel_PerFlag!$K:$K,TaxLevel_PerFlag!$A:$A,G$3,TaxLevel_PerFlag!$B:$B,$B$10,TaxLevel_PerFlag!$E:$E,$C11) -> 0.35791699 | H11: =_xlfn.MAXIFS(TaxLevel_PerFlag!$K:$K,TaxLevel_PerFlag!$A:$A,H$3,TaxLevel_PerFlag!$B:$B,$B$10,TaxLevel_PerFlag!$E:$E,$C11) -> 0.74420841 | I11: =_xlfn.MAXIFS(TaxLevel_PerFlag!$K:$K,TaxLevel_PerFlag!$A:$A,I$3,TaxLevel_PerFlag!$B:$B,$B$10,TaxLevel_PerFlag!$E:$E,$C11) -> 0.41403934 | J11: =_xlfn.MAXIFS(TaxLevel_PerFlag!$K:$K,TaxLevel_PerFlag!$A:$A,J$3,TaxLevel_PerFlag!$B:$B,$B$10,TaxLevel_PerFlag!$E:$E,$C11) -> 0.66829511 | K11: =_xlfn.MAXIFS(TaxLevel_PerFlag!$H:$H,TaxLevel_PerFlag!$A:$A,K$3,TaxLevel_PerFlag!$B:$B,$B$10,TaxLevel_PerFlag!$E:$E,$C11) -> 0.85285714 | L11: =_xlfn.MAXIFS(TaxLevel_PerFlag!$H:$H,TaxLevel_PerFlag!$A:$A,L$3,TaxLevel_PerFlag!$B:$B,$B$10,TaxLevel_PerFlag!$E:$E,$C11) -> 1 | M11: =_xlfn.MAXIFS(TaxLevel_PerFlag!$H:$H,TaxLevel_PerFlag!$A:$A,M$3,TaxLevel_PerFlag!$B:$B,$B$10,TaxLevel_PerFlag!$E:$E,$C11) -> 0.77692308 | N11: =_xlfn.MAXIFS(TaxLevel_PerFlag!$H:$H,TaxLevel_PerFlag!$A:$A,N$3,TaxLevel_PerFlag!$B:$B,$B$10,TaxLevel_PerFlag!$E:$E,$C11) -> 0.69619048 | O11: =_xlfn.MAXIFS(TaxLevel_PerFlag!$H:$H,TaxLevel_PerFlag!$A:$A,O$3,TaxLevel_PerFlag!$B:$B,$B$10,TaxLevel_PerFlag!$E:$E,$C11) -> 0.75444444 | P11: =_xlfn.MAXIFS(TaxLevel_PerFlag!$L:$L,TaxLevel_PerFlag!$A:$A,P$3,TaxLevel_PerFlag!$B:$B,$B$10,TaxLevel_PerFlag!$E:$E,$C11) -> 0.55555556 | Q11: =_xlfn.MAXIFS(TaxLevel_PerFlag!$L:$L,TaxLevel_PerFlag!$A:$A,Q$3,TaxLevel_PerFlag!$B:$B,$B$10,TaxLevel_PerFlag!$E:$E,$C11) -> 0.625 | R11: =_xlfn.MAXIFS(TaxLevel_PerFlag!$L:$L,TaxLevel_PerFlag!$A:$A,R$3,TaxLevel_PerFlag!$B:$B,$B$10,TaxLevel_PerFlag!$E:$E,$C11) -> 0.65217391 | S11: =_xlfn.MAXIFS(TaxLevel_PerFlag!$L:$L,TaxLevel_PerFlag!$A:$A,S$3,TaxLevel_PerFlag!$B:$B,$B$10,TaxLevel_PerFlag!$E:$E,$C11) -> 0.41666667 | T11: =_xlfn.MAXIFS(TaxLevel_PerFlag!$L:$L,TaxLevel_PerFlag!$A:$A,T$3,TaxLevel_PerFlag!$B:$B,$B$10,TaxLevel_PerFlag!$E:$E,$C11) -> 0.76923077
C12: acid_accumulation | D12: 20 | E12: 0.14492754 | F12: =_xlfn.MAXIFS(TaxLevel_PerFlag!$K:$K,TaxLevel_PerFlag!$A:$A,F$3,TaxLevel_PerFlag!$B:$B,$B$10,TaxLevel_PerFlag!$E:$E,$C12) -> 0.69436507 | G12: =_xlfn.MAXIFS(TaxLevel_PerFlag!$K:$K,TaxLevel_PerFlag!$A:$A,G$3,TaxLevel_PerFlag!$B:$B,$B$10,TaxLevel_PerFlag!$E:$E,$C12) -> 0.47245559 | H12: =_xlfn.MAXIFS(TaxLevel_PerFlag!$K:$K,TaxLevel_PerFlag!$A:$A,H$3,TaxLevel_PerFlag!$B:$B,$B$10,TaxLevel_PerFlag!$E:$E,$C12) -> 1 | I12: =_xlfn.MAXIFS(TaxLevel_PerFlag!$K:$K,TaxLevel_PerFlag!$A:$A,I$3,TaxLevel_PerFlag!$B:$B,$B$10,TaxLevel_PerFlag!$E:$E,$C12) -> 0.55634864 | J12: =_xlfn.MAXIFS(TaxLevel_PerFlag!$K:$K,TaxLevel_PerFlag!$A:$A,J$3,TaxLevel_PerFlag!$B:$B,$B$10,TaxLevel_PerFlag!$E:$E,$C12) -> 0 | K12: =_xlfn.MAXIFS(TaxLevel_PerFlag!$H:$H,TaxLevel_PerFlag!$A:$A,K$3,TaxLevel_PerFlag!$B:$B,$B$10,TaxLevel_PerFlag!$E:$E,$C12) -> 1 | L12: =_xlfn.MAXIFS(TaxLevel_PerFlag!$H:$H,TaxLevel_PerFlag!$A:$A,L$3,TaxLevel_PerFlag!$B:$B,$B$10,TaxLevel_PerFlag!$E:$E,$C12) -> 1 | M12: =_xlfn.MAXIFS(TaxLevel_PerFlag!$H:$H,TaxLevel_PerFlag!$A:$A,M$3,TaxLevel_PerFlag!$B:$B,$B$10,TaxLevel_PerFlag!$E:$E,$C12) -> 1 | N12: =_xlfn.MAXIFS(TaxLevel_PerFlag!$H:$H,TaxLevel_PerFlag!$A:$A,N$3,TaxLevel_PerFlag!$B:$B,$B$10,TaxLevel_PerFlag!$E:$E,$C12) -> 1 | O12: =_xlfn.MAXIFS(TaxLevel_PerFlag!$H:$H,TaxLevel_PerFlag!$A:$A,O$3,TaxLevel_PerFlag!$B:$B,$B$10,TaxLevel_PerFlag!$E:$E,$C12) -> 1 | P12: =_xlfn.MAXIFS(TaxLevel_PerFlag!$L:$L,TaxLevel_PerFlag!$A:$A,P$3,TaxLevel_PerFlag!$B:$B,$B$10,TaxLevel_PerFlag!$E:$E,$C12) -> 0.83333333 | Q12: =_xlfn.MAXIFS(TaxLevel_PerFlag!$L:$L,TaxLevel_PerFlag!$A:$A,Q$3,TaxLevel_PerFlag!$B:$B,$B$10,TaxLevel_PerFlag!$E:$E,$C12) -> 0.625 | R12: =_xlfn.MAXIFS(TaxLevel_PerFlag!$L:$L,TaxLevel_PerFlag!$A:$A,R$3,TaxLevel_PerFlag!$B:$B,$B$10,TaxLevel_PerFlag!$E:$E,$C12) -> 1 | S12: =_xlfn.MAXIFS(TaxLevel_PerFlag!$L:$L,TaxLevel_PerFlag!$A:$A,S$3,TaxLevel_PerFlag!$B:$B,$B$10,TaxLevel_PerFlag!$E:$E,$C12) -> 0.71428571 | T12: =_xlfn.MAXIFS(TaxLevel_PerFlag!$L:$L,TaxLevel_PerFlag!$A:$A,T$3,TaxLevel_PerFlag!$B:$B,$B$10,TaxLevel_PerFlag!$E:$E,$C12) -> 0
C13: ammonia_toxicity | D13: 26 | E13: 0.1884058 | F13: =_xlfn.MAXIFS(TaxLevel_PerFlag!$K:$K,TaxLevel_PerFlag!$A:$A,F$3,TaxLevel_PerFlag!$B:$B,$B$10,TaxLevel_PerFlag!$E:$E,$C13) -> 0.70912421 | G13: =_xlfn.MAXIFS(TaxLevel_PerFlag!$K:$K,TaxLevel_PerFlag!$A:$A,G$3,TaxLevel_PerFlag!$B:$B,$B$10,TaxLevel_PerFlag!$E:$E,$C13) -> 0.87635609 | H13: =_xlfn.MAXIFS(TaxLevel_PerFlag!$K:$K,TaxLevel_PerFlag!$A:$A,H$3,TaxLevel_PerFlag!$B:$B,$B$10,TaxLevel_PerFlag!$E:$E,$C13) -> 0.87635609 | I13: =_xlfn.MAXIFS(TaxLevel_PerFlag!$K:$K,TaxLevel_PerFlag!$A:$A,I$3,TaxLevel_PerFlag!$B:$B,$B$10,TaxLevel_PerFlag!$E:$E,$C13) -> 0.71 | J13: =_xlfn.MAXIFS(TaxLevel_PerFlag!$K:$K,TaxLevel_PerFlag!$A:$A,J$3,TaxLevel_PerFlag!$B:$B,$B$10,TaxLevel_PerFlag!$E:$E,$C13) -> 1 | K13: =_xlfn.MAXIFS(TaxLevel_PerFlag!$H:$H,TaxLevel_PerFlag!$A:$A,K$3,TaxLevel_PerFlag!$B:$B,$B$10,TaxLevel_PerFlag!$E:$E,$C13) -> 0.81666667 | L13: =_xlfn.MAXIFS(TaxLevel_PerFlag!$H:$H,TaxLevel_PerFlag!$A:$A,L$3,TaxLevel_PerFlag!$B:$B,$B$10,TaxLevel_PerFlag!$E:$E,$C13) -> 1 | M13: =_xlfn.MAXIFS(TaxLevel_PerFlag!$H:$H,TaxLevel_PerFlag!$A:$A,M$3,TaxLevel_PerFlag!$B:$B,$B$10,TaxLevel_PerFlag!$E:$E,$C13) -> 1 | N13: =_xlfn.MAXIFS(TaxLevel_PerFlag!$H:$H,TaxLevel_PerFlag!$A:$A,N$3,TaxLevel_PerFlag!$B:$B,$B$10,TaxLevel_PerFlag!$E:$E,$C13) -> 0.95 | O13: =_xlfn.MAXIFS(TaxLevel_PerFlag!$H:$H,TaxLevel_PerFlag!$A:$A,O$3,TaxLevel_PerFlag!$B:$B,$B$10,TaxLevel_PerFlag!$E:$E,$C13) -> 1 | P13: =_xlfn.MAXIFS(TaxLevel_PerFlag!$L:$L,TaxLevel_PerFlag!$A:$A,P$3,TaxLevel_PerFlag!$B:$B,$B$10,TaxLevel_PerFlag!$E:$E,$C13) -> 0.86956522 | Q13: =_xlfn.MAXIFS(TaxLevel_PerFlag!$L:$L,TaxLevel_PerFlag!$A:$A,Q$3,TaxLevel_PerFlag!$B:$B,$B$10,TaxLevel_PerFlag!$E:$E,$C13) -> 0.95238095 | R13: =_xlfn.MAXIFS(TaxLevel_PerFlag!$L:$L,TaxLevel_PerFlag!$A:$A,R$3,TaxLevel_PerFlag!$B:$B,$B$10,TaxLevel_PerFlag!$E:$E,$C13) -> 0.95238095 | S13: =_xlfn.MAXIFS(TaxLevel_PerFlag!$L:$L,TaxLevel_PerFlag!$A:$A,S$3,TaxLevel_PerFlag!$B:$B,$B$10,TaxLevel_PerFlag!$E:$E,$C13) -> 0.86956522 | T13: =_xlfn.MAXIFS(TaxLevel_PerFlag!$L:$L,TaxLevel_PerFlag!$A:$A,T$3,TaxLevel_PerFlag!$B:$B,$B$10,TaxLevel_PerFlag!$E:$E,$C13) -> 1
C14: biogas_quality | D14: 7 | E14: 0.050724638 | F14: =_xlfn.MAXIFS(TaxLevel_PerFlag!$K:$K,TaxLevel_PerFlag!$A:$A,F$3,TaxLevel_PerFlag!$B:$B,$B$10,TaxLevel_PerFlag!$E:$E,$C14) -> 0 | G14: =_xlfn.MAXIFS(TaxLevel_PerFlag!$K:$K,TaxLevel_PerFlag!$A:$A,G$3,TaxLevel_PerFlag!$B:$B,$B$10,TaxLevel_PerFlag!$E:$E,$C14) -> 0 | H14: =_xlfn.MAXIFS(TaxLevel_PerFlag!$K:$K,TaxLevel_PerFlag!$A:$A,H$3,TaxLevel_PerFlag!$B:$B,$B$10,TaxLevel_PerFlag!$E:$E,$C14) -> 0 | I14: =_xlfn.MAXIFS(TaxLevel_PerFlag!$K:$K,TaxLevel_PerFlag!$A:$A,I$3,TaxLevel_PerFlag!$B:$B,$B$10,TaxLevel_PerFlag!$E:$E,$C14) -> 0.69436507 | J14: =_xlfn.MAXIFS(TaxLevel_PerFlag!$K:$K,TaxLevel_PerFlag!$A:$A,J$3,TaxLevel_PerFlag!$B:$B,$B$10,TaxLevel_PerFlag!$E:$E,$C14) -> 0.35439179 | K14: =_xlfn.MAXIFS(TaxLevel_PerFlag!$H:$H,TaxLevel_PerFlag!$A:$A,K$3,TaxLevel_PerFlag!$B:$B,$B$10,TaxLevel_PerFlag!$E:$E,$C14) -> 0.29166667 | L14: =_xlfn.MAXIFS(TaxLevel_PerFlag!$H:$H,TaxLevel_PerFlag!$A:$A,L$3,TaxLevel_PerFlag!$B:$B,$B$10,TaxLevel_PerFlag!$E:$E,$C14) -> 0.30882353 | M14: =_xlfn.MAXIFS(TaxLevel_PerFlag!$H:$H,TaxLevel_PerFlag!$A:$A,M$3,TaxLevel_PerFlag!$B:$B,$B$10,TaxLevel_PerFlag!$E:$E,$C14) -> 0.29 | N14: =_xlfn.MAXIFS(TaxLevel_PerFlag!$H:$H,TaxLevel_PerFlag!$A:$A,N$3,TaxLevel_PerFlag!$B:$B,$B$10,TaxLevel_PerFlag!$E:$E,$C14) -> 0.54166667 | O14: =_xlfn.MAXIFS(TaxLevel_PerFlag!$H:$H,TaxLevel_PerFlag!$A:$A,O$3,TaxLevel_PerFlag!$B:$B,$B$10,TaxLevel_PerFlag!$E:$E,$C14) -> 0.66666667 | P14: =_xlfn.MAXIFS(TaxLevel_PerFlag!$L:$L,TaxLevel_PerFlag!$A:$A,P$3,TaxLevel_PerFlag!$B:$B,$B$10,TaxLevel_PerFlag!$E:$E,$C14) -> 0 | Q14: =_xlfn.MAXIFS(TaxLevel_PerFlag!$L:$L,TaxLevel_PerFlag!$A:$A,Q$3,TaxLevel_PerFlag!$B:$B,$B$10,TaxLevel_PerFlag!$E:$E,$C14) -> 0.15151515 | R14: =_xlfn.MAXIFS(TaxLevel_PerFlag!$L:$L,TaxLevel_PerFlag!$A:$A,R$3,TaxLevel_PerFlag!$B:$B,$B$10,TaxLevel_PerFlag!$E:$E,$C14) -> 0 | S14: =_xlfn.MAXIFS(TaxLevel_PerFlag!$L:$L,TaxLevel_PerFlag!$A:$A,S$3,TaxLevel_PerFlag!$B:$B,$B$10,TaxLevel_PerFlag!$E:$E,$C14) -> 0.55555556 | T14: =_xlfn.MAXIFS(TaxLevel_PerFlag!$L:$L,TaxLevel_PerFlag!$A:$A,T$3,TaxLevel_PerFlag!$B:$B,$B$10,TaxLevel_PerFlag!$E:$E,$C14) -> 0.45454545
C15: Macro-avg | F15: =AVERAGE(F10:F14) -> 0.4435907 | G15: =AVERAGE(G10:G14) -> 0.54134574 | H15: =AVERAGE(H10:H14) -> 0.61860402 | I15: =AVERAGE(I10:I14) -> 0.54195655 | J15: =AVERAGE(J10:J14) -> 0.47853867 | K15: =AVERAGE(K10:K14) -> 0.6422381 | L15: =AVERAGE(L10:L14) -> 0.86176471 | M15: =AVERAGE(M10:M14) -> 0.71338462 | ... T15: =AVERAGE(T10:T14) -> 0.54475524
B16: merged | C16: buffer_capacity | D16: 9 | E16: 0.065217391 | F16: =_xlfn.MAXIFS(TaxLevel_PerFlag!$K:$K,TaxLevel_PerFlag!$A:$A,F$3,TaxLevel_PerFlag!$B:$B,$B$16,TaxLevel_PerFlag!$E:$E,$C16) -> 0.20965697 | G16: =_xlfn.MAXIFS(TaxLevel_PerFlag!$K:$K,TaxLevel_PerFlag!$A:$A,G$3,TaxLevel_PerFlag!$B:$B,$B$16,TaxLevel_PerFlag!$E:$E,$C16) -> 0.41403934 | H16: =_xlfn.MAXIFS(TaxLevel_PerFlag!$K:$K,TaxLevel_PerFlag!$A:$A,H$3,TaxLevel_PerFlag!$B:$B,$B$16,TaxLevel_PerFlag!$E:$E,$C16) -> 0.41403934 | I16: =_xlfn.MAXIFS(TaxLevel_PerFlag!$K:$K,TaxLevel_PerFlag!$A:$A,I$3,TaxLevel_PerFlag!$B:$B,$B$16,TaxLevel_PerFlag!$E:$E,$C16) -> 0.22493385 | J16: =_xlfn.MAXIFS(TaxLevel_PerFlag!$K:$K,TaxLevel_PerFlag!$A:$A,J$3,TaxLevel_PerFlag!$B:$B,$B$16,TaxLevel_PerFlag!$E:$E,$C16) -> 0.30618622 | K16: =_xlfn.MAXIFS(TaxLevel_PerFlag!$H:$H,TaxLevel_PerFlag!$A:$A,K$3,TaxLevel_PerFlag!$B:$B,$B$16,TaxLevel_PerFlag!$E:$E,$C16) -> 1 | L16: =_xlfn.MAXIFS(TaxLevel_PerFlag!$H:$H,TaxLevel_PerFlag!$A:$A,L$3,TaxLevel_PerFlag!$B:$B,$B$16,TaxLevel_PerFlag!$E:$E,$C16) -> 0.5 | M16: =_xlfn.MAXIFS(TaxLevel_PerFlag!$H:$H,TaxLevel_PerFlag!$A:$A,M$3,TaxLevel_PerFlag!$B:$B,$B$16,TaxLevel_PerFlag!$E:$E,$C16) -> 0.5 | N16: =_xlfn.MAXIFS(TaxLevel_PerFlag!$H:$H,TaxLevel_PerFlag!$A:$A,N$3,TaxLevel_PerFlag!$B:$B,$B$16,TaxLevel_PerFlag!$E:$E,$C16) -> 0.5 | O16: =_xlfn.MAXIFS(TaxLevel_PerFlag!$H:$H,TaxLevel_PerFlag!$A:$A,O$3,TaxLevel_PerFlag!$B:$B,$B$16,TaxLevel_PerFlag!$E:$E,$C16) -> 0.33333333 | P16: =_xlfn.MAXIFS(TaxLevel_PerFlag!$L:$L,TaxLevel_PerFlag!$A:$A,P$3,TaxLevel_PerFlag!$B:$B,$B$16,TaxLevel_PerFlag!$E:$E,$C16) -> 0.29411765 | Q16: =_xlfn.MAXIFS(TaxLevel_PerFlag!$L:$L,TaxLevel_PerFlag!$A:$A,Q$3,TaxLevel_PerFlag!$B:$B,$B$16,TaxLevel_PerFlag!$E:$E,$C16) -> 0.55555556 | R16: =_xlfn.MAXIFS(TaxLevel_PerFlag!$L:$L,TaxLevel_PerFlag!$A:$A,R$3,TaxLevel_PerFlag!$B:$B,$B$16,TaxLevel_PerFlag!$E:$E,$C16) -> 0.55555556 | S16: =_xlfn.MAXIFS(TaxLevel_PerFlag!$L:$L,TaxLevel_PerFlag!$A:$A,S$3,TaxLevel_PerFlag!$B:$B,$B$16,TaxLevel_PerFlag!$E:$E,$C16) -> 0.3125 | T16: =_xlfn.MAXIFS(TaxLevel_PerFlag!$L:$L,TaxLevel_PerFlag!$A:$A,T$3,TaxLevel_PerFlag!$B:$B,$B$16,TaxLevel_PerFlag!$E:$E,$C16) -> 0.41666667
C17: acid_base_balance | D17: 4 | E17: 0.028985507 | F17: =_xlfn.MAXIFS(TaxLevel_PerFlag!$K:$K,TaxLevel_PerFlag!$A:$A,F$3,TaxLevel_PerFlag!$B:$B,$B$16,TaxLevel_PerFlag!$E:$E,$C17) -> 0.73950997 | G17: =_xlfn.MAXIFS(TaxLevel_PerFlag!$K:$K,TaxLevel_PerFlag!$A:$A,G$3,TaxLevel_PerFlag!$B:$B,$B$16,TaxLevel_PerFlag!$E:$E,$C17) -> 0.75833333 | H17: =_xlfn.MAXIFS(TaxLevel_PerFlag!$K:$K,TaxLevel_PerFlag!$A:$A,H$3,TaxLevel_PerFlag!$B:$B,$B$16,TaxLevel_PerFlag!$E:$E,$C17) -> 0.34689095 | I17: =_xlfn.MAXIFS(TaxLevel_PerFlag!$K:$K,TaxLevel_PerFlag!$A:$A,I$3,TaxLevel_PerFlag!$B:$B,$B$16,TaxLevel_PerFlag!$E:$E,$C17) -> 0.34689095 | J17: =_xlfn.MAXIFS(TaxLevel_PerFlag!$K:$K,TaxLevel_PerFlag!$A:$A,J$3,TaxLevel_PerFlag!$B:$B,$B$16,TaxLevel_PerFlag!$E:$E,$C17) -> 0.75833333 | K17: =_xlfn.MAXIFS(TaxLevel_PerFlag!$H:$H,TaxLevel_PerFlag!$A:$A,K$3,TaxLevel_PerFlag!$B:$B,$B$16,TaxLevel_PerFlag!$E:$E,$C17) -> 0.90285714 | L17: =_xlfn.MAXIFS(TaxLevel_PerFlag!$H:$H,TaxLevel_PerFlag!$A:$A,L$3,TaxLevel_PerFlag!$B:$B,$B$16,TaxLevel_PerFlag!$E:$E,$C17) -> 0.83703704 | M17: =_xlfn.MAXIFS(TaxLevel_PerFlag!$H:$H,TaxLevel_PerFlag!$A:$A,M$3,TaxLevel_PerFlag!$B:$B,$B$16,TaxLevel_PerFlag!$E:$E,$C17) -> 0.74166667 | N17: =_xlfn.MAXIFS(TaxLevel_PerFlag!$H:$H,TaxLevel_PerFlag!$A:$A,N$3,TaxLevel_PerFlag!$B:$B,$B$16,TaxLevel_PerFlag!$E:$E,$C17) -> 0.69619048 | O17: =_xlfn.MAXIFS(TaxLevel_PerFlag!$H:$H,TaxLevel_PerFlag!$A:$A,O$3,TaxLevel_PerFlag!$B:$B,$B$16,TaxLevel_PerFlag!$E:$E,$C17) -> 0.66444444 | P17: =_xlfn.MAXIFS(TaxLevel_PerFlag!$L:$L,TaxLevel_PerFlag!$A:$A,P$3,TaxLevel_PerFlag!$B:$B,$B$16,TaxLevel_PerFlag!$E:$E,$C17) -> 0.89285714 | Q17: =_xlfn.MAXIFS(TaxLevel_PerFlag!$L:$L,TaxLevel_PerFlag!$A:$A,Q$3,TaxLevel_PerFlag!$B:$B,$B$16,TaxLevel_PerFlag!$E:$E,$C17) -> 0.8 | R17: =_xlfn.MAXIFS(TaxLevel_PerFlag!$L:$L,TaxLevel_PerFlag!$A:$A,R$3,TaxLevel_PerFlag!$B:$B,$B$16,TaxLevel_PerFlag!$E:$E,$C17) -> 0.41666667 | S17: =_xlfn.MAXIFS(TaxLevel_PerFlag!$L:$L,TaxLevel_PerFlag!$A:$A,S$3,TaxLevel_PerFlag!$B:$B,$B$16,TaxLevel_PerFlag!$E:$E,$C17) -> 0.625 | T17: =_xlfn.MAXIFS(TaxLevel_PerFlag!$L:$L,TaxLevel_PerFlag!$A:$A,T$3,TaxLevel_PerFlag!$B:$B,$B$16,TaxLevel_PerFlag!$E:$E,$C17) -> 0.8
C18: acid_accumulation | D18: 20 | E18: 0.14492754 | F18: =_xlfn.MAXIFS(TaxLevel_PerFlag!$K:$K,TaxLevel_PerFlag!$A:$A,F$3,TaxLevel_PerFlag!$B:$B,$B$16,TaxLevel_PerFlag!$E:$E,$C18) -> 1 | G18: =_xlfn.MAXIFS(TaxLevel_PerFlag!$K:$K,TaxLevel_PerFlag!$A:$A,G$3,TaxLevel_PerFlag!$B:$B,$B$16,TaxLevel_PerFlag!$E:$E,$C18) -> 0.55634864 | H18: =_xlfn.MAXIFS(TaxLevel_PerFlag!$K:$K,TaxLevel_PerFlag!$A:$A,H$3,TaxLevel_PerFlag!$B:$B,$B$16,TaxLevel_PerFlag!$E:$E,$C18) -> 1 | I18: =_xlfn.MAXIFS(TaxLevel_PerFlag!$K:$K,TaxLevel_PerFlag!$A:$A,I$3,TaxLevel_PerFlag!$B:$B,$B$16,TaxLevel_PerFlag!$E:$E,$C18) -> 0.47245559 | J18: =_xlfn.MAXIFS(TaxLevel_PerFlag!$K:$K,TaxLevel_PerFlag!$A:$A,J$3,TaxLevel_PerFlag!$B:$B,$B$16,TaxLevel_PerFlag!$E:$E,$C18) -> 0.26049404 | K18: =_xlfn.MAXIFS(TaxLevel_PerFlag!$H:$H,TaxLevel_PerFlag!$A:$A,K$3,TaxLevel_PerFlag!$B:$B,$B$16,TaxLevel_PerFlag!$E:$E,$C18) -> 1 | L18: =_xlfn.MAXIFS(TaxLevel_PerFlag!$H:$H,TaxLevel_PerFlag!$A:$A,L$3,TaxLevel_PerFlag!$B:$B,$B$16,TaxLevel_PerFlag!$E:$E,$C18) -> 1 | M18: =_xlfn.MAXIFS(TaxLevel_PerFlag!$H:$H,TaxLevel_PerFlag!$A:$A,M$3,TaxLevel_PerFlag!$B:$B,$B$16,TaxLevel_PerFlag!$E:$E,$C18) -> 1 | N18: =_xlfn.MAXIFS(TaxLevel_PerFlag!$H:$H,TaxLevel_PerFlag!$A:$A,N$3,TaxLevel_PerFlag!$B:$B,$B$16,TaxLevel_PerFlag!$E:$E,$C18) -> 1 | O18: =_xlfn.MAXIFS(TaxLevel_PerFlag!$H:$H,TaxLevel_PerFlag!$A:$A,O$3,TaxLevel_PerFlag!$B:$B,$B$16,TaxLevel_PerFlag!$E:$E,$C18) -> 1 | P18: =_xlfn.MAXIFS(TaxLevel_PerFlag!$L:$L,TaxLevel_PerFlag!$A:$A,P$3,TaxLevel_PerFlag!$B:$B,$B$16,TaxLevel_PerFlag!$E:$E,$C18) -> 1 | Q18: =_xlfn.MAXIFS(TaxLevel_PerFlag!$L:$L,TaxLevel_PerFlag!$A:$A,Q$3,TaxLevel_PerFlag!$B:$B,$B$16,TaxLevel_PerFlag!$E:$E,$C18) -> 0.71428571 | R18: =_xlfn.MAXIFS(TaxLevel_PerFlag!$L:$L,TaxLevel_PerFlag!$A:$A,R$3,TaxLevel_PerFlag!$B:$B,$B$16,TaxLevel_PerFlag!$E:$E,$C18) -> 1 | S18: =_xlfn.MAXIFS(TaxLevel_PerFlag!$L:$L,TaxLevel_PerFlag!$A:$A,S$3,TaxLevel_PerFlag!$B:$B,$B$16,TaxLevel_PerFlag!$E:$E,$C18) -> 0.625 | T18: =_xlfn.MAXIFS(TaxLevel_PerFlag!$L:$L,TaxLevel_PerFlag!$A:$A,T$3,TaxLevel_PerFlag!$B:$B,$B$16,TaxLevel_PerFlag!$E:$E,$C18) -> 0.35714286
C19: ammonia_toxicity | D19: 26 | E19: 0.1884058 | F19: =_xlfn.MAXIFS(TaxLevel_PerFlag!$K:$K,TaxLevel_PerFlag!$A:$A,F$3,TaxLevel_PerFlag!$B:$B,$B$16,TaxLevel_PerFlag!$E:$E,$C19) -> 0.70912421 | G19: =_xlfn.MAXIFS(TaxLevel_PerFlag!$K:$K,TaxLevel_PerFlag!$A:$A,G$3,TaxLevel_PerFlag!$B:$B,$B$16,TaxLevel_PerFlag!$E:$E,$C19) -> 0.87635609 | H19: =_xlfn.MAXIFS(TaxLevel_PerFlag!$K:$K,TaxLevel_PerFlag!$A:$A,H$3,TaxLevel_PerFlag!$B:$B,$B$16,TaxLevel_PerFlag!$E:$E,$C19) -> 0.87635609 | I19: =_xlfn.MAXIFS(TaxLevel_PerFlag!$K:$K,TaxLevel_PerFlag!$A:$A,I$3,TaxLevel_PerFlag!$B:$B,$B$16,TaxLevel_PerFlag!$E:$E,$C19) -> 0.71 | J19: =_xlfn.MAXIFS(TaxLevel_PerFlag!$K:$K,TaxLevel_PerFlag!$A:$A,J$3,TaxLevel_PerFlag!$B:$B,$B$16,TaxLevel_PerFlag!$E:$E,$C19) -> 0.87635609 | K19: =_xlfn.MAXIFS(TaxLevel_PerFlag!$H:$H,TaxLevel_PerFlag!$A:$A,K$3,TaxLevel_PerFlag!$B:$B,$B$16,TaxLevel_PerFlag!$E:$E,$C19) -> 0.8875 | L19: =_xlfn.MAXIFS(TaxLevel_PerFlag!$H:$H,TaxLevel_PerFlag!$A:$A,L$3,TaxLevel_PerFlag!$B:$B,$B$16,TaxLevel_PerFlag!$E:$E,$C19) -> 1 | M19: =_xlfn.MAXIFS(TaxLevel_PerFlag!$H:$H,TaxLevel_PerFlag!$A:$A,M$3,TaxLevel_PerFlag!$B:$B,$B$16,TaxLevel_PerFlag!$E:$E,$C19) -> 1 | N19: =_xlfn.MAXIFS(TaxLevel_PerFlag!$H:$H,TaxLevel_PerFlag!$A:$A,N$3,TaxLevel_PerFlag!$B:$B,$B$16,TaxLevel_PerFlag!$E:$E,$C19) -> 1 | O19: =_xlfn.MAXIFS(TaxLevel_PerFlag!$H:$H,TaxLevel_PerFlag!$A:$A,O$3,TaxLevel_PerFlag!$B:$B,$B$16,TaxLevel_PerFlag!$E:$E,$C19) -> 0.95 | P19: =_xlfn.MAXIFS(TaxLevel_PerFlag!$L:$L,TaxLevel_PerFlag!$A:$A,P$3,TaxLevel_PerFlag!$B:$B,$B$16,TaxLevel_PerFlag!$E:$E,$C19) -> 0.86956522 | Q19: =_xlfn.MAXIFS(TaxLevel_PerFlag!$L:$L,TaxLevel_PerFlag!$A:$A,Q$3,TaxLevel_PerFlag!$B:$B,$B$16,TaxLevel_PerFlag!$E:$E,$C19) -> 0.95238095 | R19: =_xlfn.MAXIFS(TaxLevel_PerFlag!$L:$L,TaxLevel_PerFlag!$A:$A,R$3,TaxLevel_PerFlag!$B:$B,$B$16,TaxLevel_PerFlag!$E:$E,$C19) -> 0.95238095 | S19: =_xlfn.MAXIFS(TaxLevel_PerFlag!$L:$L,TaxLevel_PerFlag!$A:$A,S$3,TaxLevel_PerFlag!$B:$B,$B$16,TaxLevel_PerFlag!$E:$E,$C19) -> 0.86956522 | T19: =_xlfn.MAXIFS(TaxLevel_PerFlag!$L:$L,TaxLevel_PerFlag!$A:$A,T$3,TaxLevel_PerFlag!$B:$B,$B$16,TaxLevel_PerFlag!$E:$E,$C19) -> 0.95238095
C20: biogas_quality | D20: 7 | E20: 0.050724638 | F20: =_xlfn.MAXIFS(TaxLevel_PerFlag!$K:$K,TaxLevel_PerFlag!$A:$A,F$3,TaxLevel_PerFlag!$B:$B,$B$16,TaxLevel_PerFlag!$E:$E,$C20) -> 0 | G20: =_xlfn.MAXIFS(TaxLevel_PerFlag!$K:$K,TaxLevel_PerFlag!$A:$A,G$3,TaxLevel_PerFlag!$B:$B,$B$16,TaxLevel_PerFlag!$E:$E,$C20) -> 0 | H20: =_xlfn.MAXIFS(TaxLevel_PerFlag!$K:$K,TaxLevel_PerFlag!$A:$A,H$3,TaxLevel_PerFlag!$B:$B,$B$16,TaxLevel_PerFlag!$E:$E,$C20) -> 0.2857738 | I20: =_xlfn.MAXIFS(TaxLevel_PerFlag!$K:$K,TaxLevel_PerFlag!$A:$A,I$3,TaxLevel_PerFlag!$B:$B,$B$16,TaxLevel_PerFlag!$E:$E,$C20) -> 0.69436507 | J20: =_xlfn.MAXIFS(TaxLevel_PerFlag!$K:$K,TaxLevel_PerFlag!$A:$A,J$3,TaxLevel_PerFlag!$B:$B,$B$16,TaxLevel_PerFlag!$E:$E,$C20) -> 0.35439179 | K20: =_xlfn.MAXIFS(TaxLevel_PerFlag!$H:$H,TaxLevel_PerFlag!$A:$A,K$3,TaxLevel_PerFlag!$B:$B,$B$16,TaxLevel_PerFlag!$E:$E,$C20) -> 0.17261905 | L20: =_xlfn.MAXIFS(TaxLevel_PerFlag!$H:$H,TaxLevel_PerFlag!$A:$A,L$3,TaxLevel_PerFlag!$B:$B,$B$16,TaxLevel_PerFlag!$E:$E,$C20) -> 0.28703704 | M20: =_xlfn.MAXIFS(TaxLevel_PerFlag!$H:$H,TaxLevel_PerFlag!$A:$A,M$3,TaxLevel_PerFlag!$B:$B,$B$16,TaxLevel_PerFlag!$E:$E,$C20) -> 0.41666667 | N20: =_xlfn.MAXIFS(TaxLevel_PerFlag!$H:$H,TaxLevel_PerFlag!$A:$A,N$3,TaxLevel_PerFlag!$B:$B,$B$16,TaxLevel_PerFlag!$E:$E,$C20) -> 0.54 | O20: =_xlfn.MAXIFS(TaxLevel_PerFlag!$H:$H,TaxLevel_PerFlag!$A:$A,O$3,TaxLevel_PerFlag!$B:$B,$B$16,TaxLevel_PerFlag!$E:$E,$C20) -> 0.66666667 | P20: =_xlfn.MAXIFS(TaxLevel_PerFlag!$L:$L,TaxLevel_PerFlag!$A:$A,P$3,TaxLevel_PerFlag!$B:$B,$B$16,TaxLevel_PerFlag!$E:$E,$C20) -> 0 | Q20: =_xlfn.MAXIFS(TaxLevel_PerFlag!$L:$L,TaxLevel_PerFlag!$A:$A,Q$3,TaxLevel_PerFlag!$B:$B,$B$16,TaxLevel_PerFlag!$E:$E,$C20) -> 0 | R20: =_xlfn.MAXIFS(TaxLevel_PerFlag!$L:$L,TaxLevel_PerFlag!$A:$A,R$3,TaxLevel_PerFlag!$B:$B,$B$16,TaxLevel_PerFlag!$E:$E,$C20) -> 0.41666667 | S20: =_xlfn.MAXIFS(TaxLevel_PerFlag!$L:$L,TaxLevel_PerFlag!$A:$A,S$3,TaxLevel_PerFlag!$B:$B,$B$16,TaxLevel_PerFlag!$E:$E,$C20) -> 0.55555556 | T20: =_xlfn.MAXIFS(TaxLevel_PerFlag!$L:$L,TaxLevel_PerFlag!$A:$A,T$3,TaxLevel_PerFlag!$B:$B,$B$16,TaxLevel_PerFlag!$E:$E,$C20) -> 0.45454545
C21: Macro-avg | F21: =AVERAGE(F16:F20) -> 0.53165823 | G21: =AVERAGE(G16:G20) -> 0.52101548 | H21: =AVERAGE(H16:H20) -> 0.58461204 | I21: =AVERAGE(I16:I20) -> 0.48972909 | J21: =AVERAGE(J16:J20) -> 0.51115229 | K21: =AVERAGE(K16:K20) -> 0.79259524 | L21: =AVERAGE(L16:L20) -> 0.72481481 | M21: =AVERAGE(M16:M20) -> 0.73166667 | ... T21: =AVERAGE(T16:T20) -> 0.59614719
B22: 2) ASV-tree
B23: Dataset | C23: Flag | D23: n_pos | E23: prevalence | F23: MCC | I23: AUPR | L23: F2
F24: DeepPhylo | G24: MetaDR | H24: Phylospec | I24: DeepPhylo | J24: MetaDR | K24: Phylospec | L24: DeepPhylo | M24: MetaDR | N24: Phylospec
B25: ARC | C25: buffer_capacity | D25: 9 | E25: 0.065217391 | F25: =_xlfn.MAXIFS(ASV_PerFlag!$J:$J,ASV_PerFlag!$A:$A,$B$25,ASV_PerFlag!$B:$B,F$24,ASV_PerFlag!$C:$C,"unspecified",ASV_PerFlag!$D:$D,$C25) -> 0.12677314 | G25: =_xlfn.MAXIFS(ASV_PerFlag!$J:$J,ASV_PerFlag!$A:$A,$B$25,ASV_PerFlag!$B:$B,G$24,ASV_PerFlag!$C:$C,"unspecified",ASV_PerFlag!$D:$D,$C25) -> 0.18257419 | H25: =_xlfn.MAXIFS(ASV_PerFlag!$J:$J,ASV_PerFlag!$A:$A,$B$25,ASV_PerFlag!$B:$B,H$24,ASV_PerFlag!$C:$C,"unspecified",ASV_PerFlag!$D:$D,$C25) -> -0.12677314 | I25: =_xlfn.MAXIFS(ASV_PerFlag!$G:$G,ASV_PerFlag!$A:$A,$B$25,ASV_PerFlag!$B:$B,I$24,ASV_PerFlag!$C:$C,"unspecified",ASV_PerFlag!$D:$D,$C25) -> 0.071428571 | J25: =_xlfn.MAXIFS(ASV_PerFlag!$G:$G,ASV_PerFlag!$A:$A,$B$25,ASV_PerFlag!$B:$B,J$24,ASV_PerFlag!$C:$C,"unspecified",ASV_PerFlag!$D:$D,$C25) -> 0.066666667 | K25: =_xlfn.MAXIFS(ASV_PerFlag!$G:$G,ASV_PerFlag!$A:$A,$B$25,ASV_PerFlag!$B:$B,K$24,ASV_PerFlag!$C:$C,"unspecified",ASV_PerFlag!$D:$D,$C25) -> 0.055555556 | L25: =_xlfn.MAXIFS(ASV_PerFlag!$K:$K,ASV_PerFlag!$A:$A,$B$25,ASV_PerFlag!$B:$B,L$24,ASV_PerFlag!$C:$C,"unspecified",ASV_PerFlag!$D:$D,$C25) -> 0.20833333 | M25: =_xlfn.MAXIFS(ASV_PerFlag!$K:$K,ASV_PerFlag!$A:$A,$B$25,ASV_PerFlag!$B:$B,M$24,ASV_PerFlag!$C:$C,"unspecified",ASV_PerFlag!$D:$D,$C25) -> 0.26315789 | N25: =_xlfn.MAXIFS(ASV_PerFlag!$K:$K,ASV_PerFlag!$A:$A,$B$25,ASV_PerFlag!$B:$B,N$24,ASV_PerFlag!$C:$C,"unspecified",ASV_PerFlag!$D:$D,$C25) -> 0
C26: acid_base_balance | D26: 20 | E26: 0.14 | F26: =_xlfn.MAXIFS(ASV_PerFlag!$J:$J,ASV_PerFlag!$A:$A,$B$25,ASV_PerFlag!$B:$B,F$24,ASV_PerFlag!$C:$C,"unspecified",ASV_PerFlag!$D:$D,$C26) -> 0.30618622 | G26: =_xlfn.MAXIFS(ASV_PerFlag!$J:$J,ASV_PerFlag!$A:$A,$B$25,ASV_PerFlag!$B:$B,G$24,ASV_PerFlag!$C:$C,"unspecified",ASV_PerFlag!$D:$D,$C26) -> 0.4444578 | H26: =_xlfn.MAXIFS(ASV_PerFlag!$J:$J,ASV_PerFlag!$A:$A,$B$25,ASV_PerFlag!$B:$B,H$24,ASV_PerFlag!$C:$C,"unspecified",ASV_PerFlag!$D:$D,$C26) -> 0 | I26: =_xlfn.MAXIFS(ASV_PerFlag!$G:$G,ASV_PerFlag!$A:$A,$B$25,ASV_PerFlag!$B:$B,I$24,ASV_PerFlag!$C:$C,"unspecified",ASV_PerFlag!$D:$D,$C26) -> 0.35714286 | J26: =_xlfn.MAXIFS(ASV_PerFlag!$G:$G,ASV_PerFlag!$A:$A,$B$25,ASV_PerFlag!$B:$B,J$24,ASV_PerFlag!$C:$C,"unspecified",ASV_PerFlag!$D:$D,$C26) -> 0.47681159 | K26: =_xlfn.MAXIFS(ASV_PerFlag!$G:$G,ASV_PerFlag!$A:$A,$B$25,ASV_PerFlag!$B:$B,K$24,ASV_PerFlag!$C:$C,"unspecified",ASV_PerFlag!$D:$D,$C26) -> 0.28387042 | L26: =_xlfn.MAXIFS(ASV_PerFlag!$K:$K,ASV_PerFlag!$A:$A,$B$25,ASV_PerFlag!$B:$B,L$24,ASV_PerFlag!$C:$C,"unspecified",ASV_PerFlag!$D:$D,$C26) -> 0.625 | M26: =_xlfn.MAXIFS(ASV_PerFlag!$K:$K,ASV_PerFlag!$A:$A,$B$25,ASV_PerFlag!$B:$B,M$24,ASV_PerFlag!$C:$C,"unspecified",ASV_PerFlag!$D:$D,$C26) -> 0.43478261 | N26: =_xlfn.MAXIFS(ASV_PerFlag!$K:$K,ASV_PerFlag!$A:$A,$B$25,ASV_PerFlag!$B:$B,N$24,ASV_PerFlag!$C:$C,"unspecified",ASV_PerFlag!$D:$D,$C26) -> 0
C27: acid_accumulation | D27: 4 | E27: 0.03 | F27: =_xlfn.MAXIFS(ASV_PerFlag!$J:$J,ASV_PerFlag!$A:$A,$B$25,ASV_PerFlag!$B:$B,F$24,ASV_PerFlag!$C:$C,"unspecified",ASV_PerFlag!$D:$D,$C27) -> 0.69436507 | G27: =_xlfn.MAXIFS(ASV_PerFlag!$J:$J,ASV_PerFlag!$A:$A,$B$25,ASV_PerFlag!$B:$B,G$24,ASV_PerFlag!$C:$C,"unspecified",ASV_PerFlag!$D:$D,$C27) -> 1 | H27: =_xlfn.MAXIFS(ASV_PerFlag!$J:$J,ASV_PerFlag!$A:$A,$B$25,ASV_PerFlag!$B:$B,H$24,ASV_PerFlag!$C:$C,"unspecified",ASV_PerFlag!$D:$D,$C27) -> 0.69436507 | I27: =_xlfn.MAXIFS(ASV_PerFlag!$G:$G,ASV_PerFlag!$A:$A,$B$25,ASV_PerFlag!$B:$B,I$24,ASV_PerFlag!$C:$C,"unspecified",ASV_PerFlag!$D:$D,$C27) -> 1 | J27: =_xlfn.MAXIFS(ASV_PerFlag!$G:$G,ASV_PerFlag!$A:$A,$B$25,ASV_PerFlag!$B:$B,J$24,ASV_PerFlag!$C:$C,"unspecified",ASV_PerFlag!$D:$D,$C27) -> 1 | K27: =_xlfn.MAXIFS(ASV_PerFlag!$G:$G,ASV_PerFlag!$A:$A,$B$25,ASV_PerFlag!$B:$B,K$24,ASV_PerFlag!$C:$C,"unspecified",ASV_PerFlag!$D:$D,$C27) -> 1 | L27: =_xlfn.MAXIFS(ASV_PerFlag!$K:$K,ASV_PerFlag!$A:$A,$B$25,ASV_PerFlag!$B:$B,L$24,ASV_PerFlag!$C:$C,"unspecified",ASV_PerFlag!$D:$D,$C27) -> 0.83333333 | M27: =_xlfn.MAXIFS(ASV_PerFlag!$K:$K,ASV_PerFlag!$A:$A,$B$25,ASV_PerFlag!$B:$B,M$24,ASV_PerFlag!$C:$C,"unspecified",ASV_PerFlag!$D:$D,$C27) -> 1 | N27: =_xlfn.MAXIFS(ASV_PerFlag!$K:$K,ASV_PerFlag!$A:$A,$B$25,ASV_PerFlag!$B:$B,N$24,ASV_PerFlag!$C:$C,"unspecified",ASV_PerFlag!$D:$D,$C27) -> 0.83333333
C28: ammonia_toxicity | D28: 26 | E28: 0.1884058 | F28: =_xlfn.MAXIFS(ASV_PerFlag!$J:$J,ASV_PerFlag!$A:$A,$B$25,ASV_PerFlag!$B:$B,F$24,ASV_PerFlag!$C:$C,"unspecified",ASV_PerFlag!$D:$D,$C28) -> 0.24268134 | G28: =_xlfn.MAXIFS(ASV_PerFlag!$J:$J,ASV_PerFlag!$A:$A,$B$25,ASV_PerFlag!$B:$B,G$24,ASV_PerFlag!$C:$C,"unspecified",ASV_PerFlag!$D:$D,$C28) -> 0.61162352 | H28: =_xlfn.MAXIFS(ASV_PerFlag!$J:$J,ASV_PerFlag!$A:$A,$B$25,ASV_PerFlag!$B:$B,H$24,ASV_PerFlag!$C:$C,"unspecified",ASV_PerFlag!$D:$D,$C28) -> 0.64807407 | I28: =_xlfn.MAXIFS(ASV_PerFlag!$G:$G,ASV_PerFlag!$A:$A,$B$25,ASV_PerFlag!$B:$B,I$24,ASV_PerFlag!$C:$C,"unspecified",ASV_PerFlag!$D:$D,$C28) -> 0.25892857 | J28: =_xlfn.MAXIFS(ASV_PerFlag!$G:$G,ASV_PerFlag!$A:$A,$B$25,ASV_PerFlag!$B:$B,J$24,ASV_PerFlag!$C:$C,"unspecified",ASV_PerFlag!$D:$D,$C28) -> 0.89285714 | K28: =_xlfn.MAXIFS(ASV_PerFlag!$G:$G,ASV_PerFlag!$A:$A,$B$25,ASV_PerFlag!$B:$B,K$24,ASV_PerFlag!$C:$C,"unspecified",ASV_PerFlag!$D:$D,$C28) -> 0.8875 | L28: =_xlfn.MAXIFS(ASV_PerFlag!$K:$K,ASV_PerFlag!$A:$A,$B$25,ASV_PerFlag!$B:$B,L$24,ASV_PerFlag!$C:$C,"unspecified",ASV_PerFlag!$D:$D,$C28) -> 0.51724138 | M28: =_xlfn.MAXIFS(ASV_PerFlag!$K:$K,ASV_PerFlag!$A:$A,$B$25,ASV_PerFlag!$B:$B,M$24,ASV_PerFlag!$C:$C,"unspecified",ASV_PerFlag!$D:$D,$C28) -> 0.71428571 | N28: =_xlfn.MAXIFS(ASV_PerFlag!$K:$K,ASV_PerFlag!$A:$A,$B$25,ASV_PerFlag!$B:$B,N$24,ASV_PerFlag!$C:$C,"unspecified",ASV_PerFlag!$D:$D,$C28) -> 0.83333333
C29: biogas_quality | D29: 7 | E29: 0.050724638 | F29: =_xlfn.MAXIFS(ASV_PerFlag!$J:$J,ASV_PerFlag!$A:$A,$B$25,ASV_PerFlag!$B:$B,F$24,ASV_PerFlag!$C:$C,"unspecified",ASV_PerFlag!$D:$D,$C29) -> -0.074074074 | G29: =_xlfn.MAXIFS(ASV_PerFlag!$J:$J,ASV_PerFlag!$A:$A,$B$25,ASV_PerFlag!$B:$B,G$24,ASV_PerFlag!$C:$C,"unspecified",ASV_PerFlag!$D:$D,$C29) -> -0.074074074 | H29: =_xlfn.MAXIFS(ASV_PerFlag!$J:$J,ASV_PerFlag!$A:$A,$B$25,ASV_PerFlag!$B:$B,H$24,ASV_PerFlag!$C:$C,"unspecified",ASV_PerFlag!$D:$D,$C29) -> 0.19693028 | I29: =_xlfn.MAXIFS(ASV_PerFlag!$G:$G,ASV_PerFlag!$A:$A,$B$25,ASV_PerFlag!$B:$B,I$24,ASV_PerFlag!$C:$C,"unspecified",ASV_PerFlag!$D:$D,$C29) -> 0.14285714 | J29: =_xlfn.MAXIFS(ASV_PerFlag!$G:$G,ASV_PerFlag!$A:$A,$B$25,ASV_PerFlag!$B:$B,J$24,ASV_PerFlag!$C:$C,"unspecified",ASV_PerFlag!$D:$D,$C29) -> 0.063894523 | K29: =_xlfn.MAXIFS(ASV_PerFlag!$G:$G,ASV_PerFlag!$A:$A,$B$25,ASV_PerFlag!$B:$B,K$24,ASV_PerFlag!$C:$C,"unspecified",ASV_PerFlag!$D:$D,$C29) -> 0.17763158 | L29: =_xlfn.MAXIFS(ASV_PerFlag!$K:$K,ASV_PerFlag!$A:$A,$B$25,ASV_PerFlag!$B:$B,L$24,ASV_PerFlag!$C:$C,"unspecified",ASV_PerFlag!$D:$D,$C29) -> 0 | M29: =_xlfn.MAXIFS(ASV_PerFlag!$K:$K,ASV_PerFlag!$A:$A,$B$25,ASV_PerFlag!$B:$B,M$24,ASV_PerFlag!$C:$C,"unspecified",ASV_PerFlag!$D:$D,$C29) -> 0 | N29: =_xlfn.MAXIFS(ASV_PerFlag!$K:$K,ASV_PerFlag!$A:$A,$B$25,ASV_PerFlag!$B:$B,N$24,ASV_PerFlag!$C:$C,"unspecified",ASV_PerFlag!$D:$D,$C29) -> 0.35714286
C30: Macro-avg | F30: =AVERAGE(F25:F29) -> 0.25918634 | G30: =AVERAGE(G25:G29) -> 0.43291629 | H30: =AVERAGE(H25:H29) -> 0.28251926 | I30: =AVERAGE(I25:I29) -> 0.36607143 | J30: =AVERAGE(J25:J29) -> 0.50004599 | K30: =AVERAGE(K25:K29) -> 0.48091151 | L30: =AVERAGE(L25:L29) -> 0.43678161 | M30: =AVERAGE(M25:M29) -> 0.48244524 | N30: =AVERAGE(N25:N29) -> 0.4047619
B31: BAC | C31: buffer_capacity | D31: 9 | E31: 0.065217391 | F31: =_xlfn.MAXIFS(ASV_PerFlag!$J:$J,ASV_PerFlag!$A:$A,$B$31,ASV_PerFlag!$B:$B,F$24,ASV_PerFlag!$C:$C,"unspecified",ASV_PerFlag!$D:$D,$C31) -> 0.075592895 | G31: =_xlfn.MAXIFS(ASV_PerFlag!$J:$J,ASV_PerFlag!$A:$A,$B$31,ASV_PerFlag!$B:$B,G$24,ASV_PerFlag!$C:$C,"unspecified",ASV_PerFlag!$D:$D,$C31) -> 0 | H31: =_xlfn.MAXIFS(ASV_PerFlag!$J:$J,ASV_PerFlag!$A:$A,$B$31,ASV_PerFlag!$B:$B,H$24,ASV_PerFlag!$C:$C,"unspecified",ASV_PerFlag!$D:$D,$C31) -> 0.28171808 | I31: =_xlfn.MAXIFS(ASV_PerFlag!$G:$G,ASV_PerFlag!$A:$A,$B$31,ASV_PerFlag!$B:$B,I$24,ASV_PerFlag!$C:$C,"unspecified",ASV_PerFlag!$D:$D,$C31) -> 0.04 | J31: =_xlfn.MAXIFS(ASV_PerFlag!$G:$G,ASV_PerFlag!$A:$A,$B$31,ASV_PerFlag!$B:$B,J$24,ASV_PerFlag!$C:$C,"unspecified",ASV_PerFlag!$D:$D,$C31) -> 0.25 | K31: =_xlfn.MAXIFS(ASV_PerFlag!$G:$G,ASV_PerFlag!$A:$A,$B$31,ASV_PerFlag!$B:$B,K$24,ASV_PerFlag!$C:$C,"unspecified",ASV_PerFlag!$D:$D,$C31) -> 0.11111111 | L31: =_xlfn.MAXIFS(ASV_PerFlag!$K:$K,ASV_PerFlag!$A:$A,$B$31,ASV_PerFlag!$B:$B,L$24,ASV_PerFlag!$C:$C,"unspecified",ASV_PerFlag!$D:$D,$C31) -> 0.17241379 | M31: =_xlfn.MAXIFS(ASV_PerFlag!$K:$K,ASV_PerFlag!$A:$A,$B$31,ASV_PerFlag!$B:$B,M$24,ASV_PerFlag!$C:$C,"unspecified",ASV_PerFlag!$D:$D,$C31) -> 0.15151515 | N31: =_xlfn.MAXIFS(ASV_PerFlag!$K:$K,ASV_PerFlag!$A:$A,$B$31,ASV_PerFlag!$B:$B,N$24,ASV_PerFlag!$C:$C,"unspecified",ASV_PerFlag!$D:$D,$C31) -> 0.38461538
C32: acid_base_balance | D32: 20 | E32: 0.14 | F32: =_xlfn.MAXIFS(ASV_PerFlag!$J:$J,ASV_PerFlag!$A:$A,$B$31,ASV_PerFlag!$B:$B,F$24,ASV_PerFlag!$C:$C,"unspecified",ASV_PerFlag!$D:$D,$C32) -> -0.082158384 | G32: =_xlfn.MAXIFS(ASV_PerFlag!$J:$J,ASV_PerFlag!$A:$A,$B$31,ASV_PerFlag!$B:$B,G$24,ASV_PerFlag!$C:$C,"unspecified",ASV_PerFlag!$D:$D,$C32) -> 0 | H32: =_xlfn.MAXIFS(ASV_PerFlag!$J:$J,ASV_PerFlag!$A:$A,$B$31,ASV_PerFlag!$B:$B,H$24,ASV_PerFlag!$C:$C,"unspecified",ASV_PerFlag!$D:$D,$C32) -> 0.32281067 | I32: =_xlfn.MAXIFS(ASV_PerFlag!$G:$G,ASV_PerFlag!$A:$A,$B$31,ASV_PerFlag!$B:$B,I$24,ASV_PerFlag!$C:$C,"unspecified",ASV_PerFlag!$D:$D,$C32) -> 0.16248276 | J32: =_xlfn.MAXIFS(ASV_PerFlag!$G:$G,ASV_PerFlag!$A:$A,$B$31,ASV_PerFlag!$B:$B,J$24,ASV_PerFlag!$C:$C,"unspecified",ASV_PerFlag!$D:$D,$C32) -> 0.70114943 | K32: =_xlfn.MAXIFS(ASV_PerFlag!$G:$G,ASV_PerFlag!$A:$A,$B$31,ASV_PerFlag!$B:$B,K$24,ASV_PerFlag!$C:$C,"unspecified",ASV_PerFlag!$D:$D,$C32) -> 0.695 | L32: =_xlfn.MAXIFS(ASV_PerFlag!$K:$K,ASV_PerFlag!$A:$A,$B$31,ASV_PerFlag!$B:$B,L$24,ASV_PerFlag!$C:$C,"unspecified",ASV_PerFlag!$D:$D,$C32) -> 0.44444444 | M32: =_xlfn.MAXIFS(ASV_PerFlag!$K:$K,ASV_PerFlag!$A:$A,$B$31,ASV_PerFlag!$B:$B,M$24,ASV_PerFlag!$C:$C,"unspecified",ASV_PerFlag!$D:$D,$C32) -> 0 | N32: =_xlfn.MAXIFS(ASV_PerFlag!$K:$K,ASV_PerFlag!$A:$A,$B$31,ASV_PerFlag!$B:$B,N$24,ASV_PerFlag!$C:$C,"unspecified",ASV_PerFlag!$D:$D,$C32) -> 0.60606061
C33: acid_accumulation | D33: 4 | E33: 0.03 | F33: =_xlfn.MAXIFS(ASV_PerFlag!$J:$J,ASV_PerFlag!$A:$A,$B$31,ASV_PerFlag!$B:$B,F$24,ASV_PerFlag!$C:$C,"unspecified",ASV_PerFlag!$D:$D,$C33) -> 0 | G33: =_xlfn.MAXIFS(ASV_PerFlag!$J:$J,ASV_PerFlag!$A:$A,$B$31,ASV_PerFlag!$B:$B,G$24,ASV_PerFlag!$C:$C,"unspecified",ASV_PerFlag!$D:$D,$C33) -> 0 | H33: =_xlfn.MAXIFS(ASV_PerFlag!$J:$J,ASV_PerFlag!$A:$A,$B$31,ASV_PerFlag!$B:$B,H$24,ASV_PerFlag!$C:$C,"unspecified",ASV_PerFlag!$D:$D,$C33) -> -0.05143445 | I33: =_xlfn.MAXIFS(ASV_PerFlag!$G:$G,ASV_PerFlag!$A:$A,$B$31,ASV_PerFlag!$B:$B,I$24,ASV_PerFlag!$C:$C,"unspecified",ASV_PerFlag!$D:$D,$C33) -> 0.04 | J33: =_xlfn.MAXIFS(ASV_PerFlag!$G:$G,ASV_PerFlag!$A:$A,$B$31,ASV_PerFlag!$B:$B,J$24,ASV_PerFlag!$C:$C,"unspecified",ASV_PerFlag!$D:$D,$C33) -> 0.5 | K33: =_xlfn.MAXIFS(ASV_PerFlag!$G:$G,ASV_PerFlag!$A:$A,$B$31,ASV_PerFlag!$B:$B,K$24,ASV_PerFlag!$C:$C,"unspecified",ASV_PerFlag!$D:$D,$C33) -> 0.16666667 | L33: =_xlfn.MAXIFS(ASV_PerFlag!$K:$K,ASV_PerFlag!$A:$A,$B$31,ASV_PerFlag!$B:$B,L$24,ASV_PerFlag!$C:$C,"unspecified",ASV_PerFlag!$D:$D,$C33) -> 0 | M33: =_xlfn.MAXIFS(ASV_PerFlag!$K:$K,ASV_PerFlag!$A:$A,$B$31,ASV_PerFlag!$B:$B,M$24,ASV_PerFlag!$C:$C,"unspecified",ASV_PerFlag!$D:$D,$C33) -> 0 | N33: =_xlfn.MAXIFS(ASV_PerFlag!$K:$K,ASV_PerFlag!$A:$A,$B$31,ASV_PerFlag!$B:$B,N$24,ASV_PerFlag!$C:$C,"unspecified",ASV_PerFlag!$D:$D,$C33) -> 0
C34: ammonia_toxicity | D34: 26 | E34: 0.1884058 | F34: =_xlfn.MAXIFS(ASV_PerFlag!$J:$J,ASV_PerFlag!$A:$A,$B$31,ASV_PerFlag!$B:$B,F$24,ASV_PerFlag!$C:$C,"unspecified",ASV_PerFlag!$D:$D,$C34) -> 0.10886621 | G34: =_xlfn.MAXIFS(ASV_PerFlag!$J:$J,ASV_PerFlag!$A:$A,$B$31,ASV_PerFlag!$B:$B,G$24,ASV_PerFlag!$C:$C,"unspecified",ASV_PerFlag!$D:$D,$C34) -> 0.70912421 | H34: =_xlfn.MAXIFS(ASV_PerFlag!$J:$J,ASV_PerFlag!$A:$A,$B$31,ASV_PerFlag!$B:$B,H$24,ASV_PerFlag!$C:$C,"unspecified",ASV_PerFlag!$D:$D,$C34) -> 0.64807407 | I34: =_xlfn.MAXIFS(ASV_PerFlag!$G:$G,ASV_PerFlag!$A:$A,$B$31,ASV_PerFlag!$B:$B,I$24,ASV_PerFlag!$C:$C,"unspecified",ASV_PerFlag!$D:$D,$C34) -> 0.14814815 | J34: =_xlfn.MAXIFS(ASV_PerFlag!$G:$G,ASV_PerFlag!$A:$A,$B$31,ASV_PerFlag!$B:$B,J$24,ASV_PerFlag!$C:$C,"unspecified",ASV_PerFlag!$D:$D,$C34) -> 0.95 | K34: =_xlfn.MAXIFS(ASV_PerFlag!$G:$G,ASV_PerFlag!$A:$A,$B$31,ASV_PerFlag!$B:$B,K$24,ASV_PerFlag!$C:$C,"unspecified",ASV_PerFlag!$D:$D,$C34) -> 0.8875 | L34: =_xlfn.MAXIFS(ASV_PerFlag!$K:$K,ASV_PerFlag!$A:$A,$B$31,ASV_PerFlag!$B:$B,L$24,ASV_PerFlag!$C:$C,"unspecified",ASV_PerFlag!$D:$D,$C34) -> 0.46511628 | M34: =_xlfn.MAXIFS(ASV_PerFlag!$K:$K,ASV_PerFlag!$A:$A,$B$31,ASV_PerFlag!$B:$B,M$24,ASV_PerFlag!$C:$C,"unspecified",ASV_PerFlag!$D:$D,$C34) -> 0.86956522 | N34: =_xlfn.MAXIFS(ASV_PerFlag!$K:$K,ASV_PerFlag!$A:$A,$B$31,ASV_PerFlag!$B:$B,N$24,ASV_PerFlag!$C:$C,"unspecified",ASV_PerFlag!$D:$D,$C34) -> 0.83333333
C35: biogas_quality | D35: 7 | E35: 0.050724638 | F35: =_xlfn.MAXIFS(ASV_PerFlag!$J:$J,ASV_PerFlag!$A:$A,$B$31,ASV_PerFlag!$B:$B,F$24,ASV_PerFlag!$C:$C,"unspecified",ASV_PerFlag!$D:$D,$C35) -> 0 | G35: =_xlfn.MAXIFS(ASV_PerFlag!$J:$J,ASV_PerFlag!$A:$A,$B$31,ASV_PerFlag!$B:$B,G$24,ASV_PerFlag!$C:$C,"unspecified",ASV_PerFlag!$D:$D,$C35) -> 0 | H35: =_xlfn.MAXIFS(ASV_PerFlag!$J:$J,ASV_PerFlag!$A:$A,$B$31,ASV_PerFlag!$B:$B,H$24,ASV_PerFlag!$C:$C,"unspecified",ASV_PerFlag!$D:$D,$C35) -> 0.11157311 | I35: =_xlfn.MAXIFS(ASV_PerFlag!$G:$G,ASV_PerFlag!$A:$A,$B$31,ASV_PerFlag!$B:$B,I$24,ASV_PerFlag!$C:$C,"unspecified",ASV_PerFlag!$D:$D,$C35) -> 0.08 | J35: =_xlfn.MAXIFS(ASV_PerFlag!$G:$G,ASV_PerFlag!$A:$A,$B$31,ASV_PerFlag!$B:$B,J$24,ASV_PerFlag!$C:$C,"unspecified",ASV_PerFlag!$D:$D,$C35) -> 0.21929825 | K35: =_xlfn.MAXIFS(ASV_PerFlag!$G:$G,ASV_PerFlag!$A:$A,$B$31,ASV_PerFlag!$B:$B,K$24,ASV_PerFlag!$C:$C,"unspecified",ASV_PerFlag!$D:$D,$C35) -> 0.22222222 | L35: =_xlfn.MAXIFS(ASV_PerFlag!$K:$K,ASV_PerFlag!$A:$A,$B$31,ASV_PerFlag!$B:$B,L$24,ASV_PerFlag!$C:$C,"unspecified",ASV_PerFlag!$D:$D,$C35) -> 0 | M35: =_xlfn.MAXIFS(ASV_PerFlag!$K:$K,ASV_PerFlag!$A:$A,$B$31,ASV_PerFlag!$B:$B,M$24,ASV_PerFlag!$C:$C,"unspecified",ASV_PerFlag!$D:$D,$C35) -> 0 | N35: =_xlfn.MAXIFS(ASV_PerFlag!$K:$K,ASV_PerFlag!$A:$A,$B$31,ASV_PerFlag!$B:$B,N$24,ASV_PerFlag!$C:$C,"unspecified",ASV_PerFlag!$D:$D,$C35) -> 0.29411765
C36: Macro-avg | F36: =AVERAGE(F31:F35) -> 0.020460144 | G36: =AVERAGE(G31:G35) -> 0.14182484 | H36: =AVERAGE(H31:H35) -> 0.2625483 | I36: =AVERAGE(I31:I35) -> 0.094126181 | J36: =AVERAGE(J31:J35) -> 0.52408953 | K36: =AVERAGE(K31:K35) -> 0.4165 | L36: =AVERAGE(L31:L35) -> 0.2163949 | M36: =AVERAGE(M31:M35) -> 0.20421607 | N36: =AVERAGE(N31:N35) -> 0.42362539
B37: merged | C37: buffer_capacity | D37: 9 | E37: 0.065217391 | F37: =_xlfn.MAXIFS(ASV_PerFlag!$J:$J,ASV_PerFlag!$A:$A,$B$37,ASV_PerFlag!$B:$B,F$24,ASV_PerFlag!$C:$C,"unspecified",ASV_PerFlag!$D:$D,$C37) -> 0 | G37: =_xlfn.MAXIFS(ASV_PerFlag!$J:$J,ASV_PerFlag!$A:$A,$B$37,ASV_PerFlag!$B:$B,G$24,ASV_PerFlag!$C:$C,"unspecified",ASV_PerFlag!$D:$D,$C37) -> 0.086258195 | H37: =_xlfn.MAXIFS(ASV_PerFlag!$J:$J,ASV_PerFlag!$A:$A,$B$37,ASV_PerFlag!$B:$B,H$24,ASV_PerFlag!$C:$C,"unspecified",ASV_PerFlag!$D:$D,$C37) -> 0 | I37: =_xlfn.MAXIFS(ASV_PerFlag!$G:$G,ASV_PerFlag!$A:$A,$B$37,ASV_PerFlag!$B:$B,I$24,ASV_PerFlag!$C:$C,"unspecified",ASV_PerFlag!$D:$D,$C37) -> 0.055555556 | J37: =_xlfn.MAXIFS(ASV_PerFlag!$G:$G,ASV_PerFlag!$A:$A,$B$37,ASV_PerFlag!$B:$B,J$24,ASV_PerFlag!$C:$C,"unspecified",ASV_PerFlag!$D:$D,$C37) -> 0.066666667 | K37: =_xlfn.MAXIFS(ASV_PerFlag!$G:$G,ASV_PerFlag!$A:$A,$B$37,ASV_PerFlag!$B:$B,K$24,ASV_PerFlag!$C:$C,"unspecified",ASV_PerFlag!$D:$D,$C37) -> 0.055555556 | L37: =_xlfn.MAXIFS(ASV_PerFlag!$K:$K,ASV_PerFlag!$A:$A,$B$37,ASV_PerFlag!$B:$B,L$24,ASV_PerFlag!$C:$C,"unspecified",ASV_PerFlag!$D:$D,$C37) -> 0.15151515 | M37: =_xlfn.MAXIFS(ASV_PerFlag!$K:$K,ASV_PerFlag!$A:$A,$B$37,ASV_PerFlag!$B:$B,M$24,ASV_PerFlag!$C:$C,"unspecified",ASV_PerFlag!$D:$D,$C37) -> 0.17857143 | N37: =_xlfn.MAXIFS(ASV_PerFlag!$K:$K,ASV_PerFlag!$A:$A,$B$37,ASV_PerFlag!$B:$B,N$24,ASV_PerFlag!$C:$C,"unspecified",ASV_PerFlag!$D:$D,$C37) -> 0
C38: acid_base_balance | D38: 20 | E38: 0.14 | F38: =_xlfn.MAXIFS(ASV_PerFlag!$J:$J,ASV_PerFlag!$A:$A,$B$37,ASV_PerFlag!$B:$B,F$24,ASV_PerFlag!$C:$C,"unspecified",ASV_PerFlag!$D:$D,$C38) -> 0.082158384 | G38: =_xlfn.MAXIFS(ASV_PerFlag!$J:$J,ASV_PerFlag!$A:$A,$B$37,ASV_PerFlag!$B:$B,G$24,ASV_PerFlag!$C:$C,"unspecified",ASV_PerFlag!$D:$D,$C38) -> 0 | H38: =_xlfn.MAXIFS(ASV_PerFlag!$J:$J,ASV_PerFlag!$A:$A,$B$37,ASV_PerFlag!$B:$B,H$24,ASV_PerFlag!$C:$C,"unspecified",ASV_PerFlag!$D:$D,$C38) -> -0.086258195 | I38: =_xlfn.MAXIFS(ASV_PerFlag!$G:$G,ASV_PerFlag!$A:$A,$B$37,ASV_PerFlag!$B:$B,I$24,ASV_PerFlag!$C:$C,"unspecified",ASV_PerFlag!$D:$D,$C38) -> 0.52126984 | J38: =_xlfn.MAXIFS(ASV_PerFlag!$G:$G,ASV_PerFlag!$A:$A,$B$37,ASV_PerFlag!$B:$B,J$24,ASV_PerFlag!$C:$C,"unspecified",ASV_PerFlag!$D:$D,$C38) -> 0.81 | K38: =_xlfn.MAXIFS(ASV_PerFlag!$G:$G,ASV_PerFlag!$A:$A,$B$37,ASV_PerFlag!$B:$B,K$24,ASV_PerFlag!$C:$C,"unspecified",ASV_PerFlag!$D:$D,$C38) -> 0.495 | L38: =_xlfn.MAXIFS(ASV_PerFlag!$K:$K,ASV_PerFlag!$A:$A,$B$37,ASV_PerFlag!$B:$B,L$24,ASV_PerFlag!$C:$C,"unspecified",ASV_PerFlag!$D:$D,$C38) -> 0.20833333 | M38: =_xlfn.MAXIFS(ASV_PerFlag!$K:$K,ASV_PerFlag!$A:$A,$B$37,ASV_PerFlag!$B:$B,M$24,ASV_PerFlag!$C:$C,"unspecified",ASV_PerFlag!$D:$D,$C38) -> 0 | N38: =_xlfn.MAXIFS(ASV_PerFlag!$K:$K,ASV_PerFlag!$A:$A,$B$37,ASV_PerFlag!$B:$B,N$24,ASV_PerFlag!$C:$C,"unspecified",ASV_PerFlag!$D:$D,$C38) -> 0
C39: acid_accumulation | D39: 4 | E39: 0.03 | F39: =_xlfn.MAXIFS(ASV_PerFlag!$J:$J,ASV_PerFlag!$A:$A,$B$37,ASV_PerFlag!$B:$B,F$24,ASV_PerFlag!$C:$C,"unspecified",ASV_PerFlag!$D:$D,$C39) -> 1 | G39: =_xlfn.MAXIFS(ASV_PerFlag!$J:$J,ASV_PerFlag!$A:$A,$B$37,ASV_PerFlag!$B:$B,G$24,ASV_PerFlag!$C:$C,"unspecified",ASV_PerFlag!$D:$D,$C39) -> 0 | H39: =_xlfn.MAXIFS(ASV_PerFlag!$J:$J,ASV_PerFlag!$A:$A,$B$37,ASV_PerFlag!$B:$B,H$24,ASV_PerFlag!$C:$C,"unspecified",ASV_PerFlag!$D:$D,$C39) -> 0.55634864 | I39: =_xlfn.MAXIFS(ASV_PerFlag!$G:$G,ASV_PerFlag!$A:$A,$B$37,ASV_PerFlag!$B:$B,I$24,ASV_PerFlag!$C:$C,"unspecified",ASV_PerFlag!$D:$D,$C39) -> 1 | J39: =_xlfn.MAXIFS(ASV_PerFlag!$G:$G,ASV_PerFlag!$A:$A,$B$37,ASV_PerFlag!$B:$B,J$24,ASV_PerFlag!$C:$C,"unspecified",ASV_PerFlag!$D:$D,$C39) -> 0.2 | K39: =_xlfn.MAXIFS(ASV_PerFlag!$G:$G,ASV_PerFlag!$A:$A,$B$37,ASV_PerFlag!$B:$B,K$24,ASV_PerFlag!$C:$C,"unspecified",ASV_PerFlag!$D:$D,$C39) -> 0.5 | L39: =_xlfn.MAXIFS(ASV_PerFlag!$K:$K,ASV_PerFlag!$A:$A,$B$37,ASV_PerFlag!$B:$B,L$24,ASV_PerFlag!$C:$C,"unspecified",ASV_PerFlag!$D:$D,$C39) -> 1 | M39: =_xlfn.MAXIFS(ASV_PerFlag!$K:$K,ASV_PerFlag!$A:$A,$B$37,ASV_PerFlag!$B:$B,M$24,ASV_PerFlag!$C:$C,"unspecified",ASV_PerFlag!$D:$D,$C39) -> 0 | N39: =_xlfn.MAXIFS(ASV_PerFlag!$K:$K,ASV_PerFlag!$A:$A,$B$37,ASV_PerFlag!$B:$B,N$24,ASV_PerFlag!$C:$C,"unspecified",ASV_PerFlag!$D:$D,$C39) -> 0.71428571
C40: ammonia_toxicity | D40: 26 | E40: 0.1884058 | F40: =_xlfn.MAXIFS(ASV_PerFlag!$J:$J,ASV_PerFlag!$A:$A,$B$37,ASV_PerFlag!$B:$B,F$24,ASV_PerFlag!$C:$C,"unspecified",ASV_PerFlag!$D:$D,$C40) -> 0.64807407 | G40: =_xlfn.MAXIFS(ASV_PerFlag!$J:$J,ASV_PerFlag!$A:$A,$B$37,ASV_PerFlag!$B:$B,G$24,ASV_PerFlag!$C:$C,"unspecified",ASV_PerFlag!$D:$D,$C40) -> 0.70912421 | H40: =_xlfn.MAXIFS(ASV_PerFlag!$J:$J,ASV_PerFlag!$A:$A,$B$37,ASV_PerFlag!$B:$B,H$24,ASV_PerFlag!$C:$C,"unspecified",ASV_PerFlag!$D:$D,$C40) -> 0.59628479 | I40: =_xlfn.MAXIFS(ASV_PerFlag!$G:$G,ASV_PerFlag!$A:$A,$B$37,ASV_PerFlag!$B:$B,I$24,ASV_PerFlag!$C:$C,"unspecified",ASV_PerFlag!$D:$D,$C40) -> 0.525 | J40: =_xlfn.MAXIFS(ASV_PerFlag!$G:$G,ASV_PerFlag!$A:$A,$B$37,ASV_PerFlag!$B:$B,J$24,ASV_PerFlag!$C:$C,"unspecified",ASV_PerFlag!$D:$D,$C40) -> 0.8875 | K40: =_xlfn.MAXIFS(ASV_PerFlag!$G:$G,ASV_PerFlag!$A:$A,$B$37,ASV_PerFlag!$B:$B,K$24,ASV_PerFlag!$C:$C,"unspecified",ASV_PerFlag!$D:$D,$C40) -> 0.80416667 | L40: =_xlfn.MAXIFS(ASV_PerFlag!$K:$K,ASV_PerFlag!$A:$A,$B$37,ASV_PerFlag!$B:$B,L$24,ASV_PerFlag!$C:$C,"unspecified",ASV_PerFlag!$D:$D,$C40) -> 0.83333333 | M40: =_xlfn.MAXIFS(ASV_PerFlag!$K:$K,ASV_PerFlag!$A:$A,$B$37,ASV_PerFlag!$B:$B,M$24,ASV_PerFlag!$C:$C,"unspecified",ASV_PerFlag!$D:$D,$C40) -> 0.86956522 | N40: =_xlfn.MAXIFS(ASV_PerFlag!$K:$K,ASV_PerFlag!$A:$A,$B$37,ASV_PerFlag!$B:$B,N$24,ASV_PerFlag!$C:$C,"unspecified",ASV_PerFlag!$D:$D,$C40) -> 0.8
...

Sheet Genus_PerFlag
A1: domain | B1: model | C1: injection | D1: flag | E1: n_pos | F1: prevalence | G1: auprc | H1: auprc_lift | I1: auroc | J1: mcc | K1: f2 | L1: precision | M1: recall | N1: threshold | O1: source_file
A2: ARC | B2: CNN | C2: unspecified | D2: acid_accumulation | E2: 1 | F2: 0.034482759 | G2: 1 | H2: 29 | I2: 1 | J2: 0 | K2: 0 | L2: 0 | M2: 0 | N2: 0.5 | O2: results_genustree_ARC_CNN.csv
A3: ARC | B3: CNN | C3: unspecified | D3: acid_base_balance | E3: 5 | F3: 0.17241379 | G3: 0.51490683 | H3: 2.9864596 | I3: 0.675 | J3: 0.41403934 | K3: 0.23809524 | L3: 1 | M3: 0.2 | N3: 0.50817544 | O3: results_genustree_ARC_CNN.csv
A4: ARC | B4: CNN | C4: unspecified | D4: ammonia_toxicity | E4: 4 | F4: 0.13793103 | G4: 0.11700369 | H4: 0.84827678 | I4: 0.28 | J4: 0.10886621 | K4: 0.46511628 | L4: 0.14814815 | M4: 1 | N4: 0.47507489 | O4: results_genustree_ARC_CNN.csv
A5: ARC | B5: CNN | C5: unspecified | D5: biogas_quality | E5: 2 | F5: 0.068965517 | G5: 0.078787879 | H5: 1.1424242 | I5: 0.37037037 | J5: 0 | K5: 0 | L5: 0 | M5: 0 | N5: 0.5 | O5: results_genustree_ARC_CNN.csv
A6: ARC | B6: CNN | C6: unspecified | D6: buffer_capacity | E6: 1 | F6: 0.034482759 | G6: 0.041666667 | H6: 1.2083333 | I6: 0.17857143 | J6: -0.30618622 | K6: 0 | L6: 0 | M6: 0 | N6: 0.45342842 | O6: results_genustree_ARC_CNN.csv
A7: ARC | B7: DeepPhylo | C7: unspecified | D7: acid_accumulation | E7: 1 | F7: 0.034482759 | G7: 0.066666667 | H7: 1.9333333 | I7: 0.75 | J7: 0 | K7: 0 | L7: 0 | M7: 0 | N7: 0.5 | O7: results_genustree_ARC_DeepPhylo.csv
A8: ARC | B8: DeepPhylo | C8: unspecified | D8: acid_base_balance | E8: 5 | F8: 0.17241379 | G8: 0.26333333 | H8: 1.5273333 | I8: 0.69166667 | J8: 0 | K8: 0.51020408 | L8: 0.17241379 | M8: 1 | N8: 0 | O8: results_genustree_ARC_DeepPhylo.csv
A9: ARC | B9: DeepPhylo | C9: unspecified | D9: ammonia_toxicity | E9: 4 | F9: 0.13793103 | G9: 0.26666667 | H9: 1.9333333 | I9: 0.78 | J9: 0.16 | K9: 0.48780488 | L9: 0.16 | M9: 1 | N9: 8.1436693e-09 | O9: results_genustree_ARC_DeepPhylo.csv
A10: ARC | B10: DeepPhylo | C10: unspecified | D10: biogas_quality | E10: 2 | F10: 0.068965517 | G10: 0.13333333 | H10: 1.9333333 | I10: 0.75925926 | J10: 0 | K10: 0 | L10: 0 | M10: 0 | N10: 0.5 | O10: results_genustree_ARC_DeepPhylo.csv
A11: ARC | B11: DeepPhylo | C11: unspecified | D11: buffer_capacity | E11: 1 | F11: 0.034482759 | G11: 0.066666667 | H11: 1.9333333 | I11: 0.75 | J11: 0.035714286 | K11: 0.15625 | L11: 0.035714286 | M11: 1 | N11: 1.7289912e-20 | O11: results_genustree_ARC_DeepPhylo.csv
A12: ARC | B12: MetaDR | C12: unspecified | D12: acid_accumulation | E12: 1 | F12: 0.034482759 | G12: 1 | H12: 29 | I12: 1 | J12: 1 | K12: 1 | L12: 1 | M12: 1 | N12: 0.5 | O12: results_genustree_ARC_MetaDR.csv
A13: ARC | B13: MetaDR | C13: unspecified | D13: acid_base_balance | E13: 5 | F13: 0.17241379 | G13: 0.58878788 | H13: 3.4149697 | I13: 0.825 | J13: 0.2360294 | K13: 0.22727273 | L13: 0.5 | M13: 0.2 | N13: 0.69585047 | O13: results_genustree_ARC_MetaDR.csv
... A101: merged | B101: RF | C101: unspecified | D101: buffer_capacity | E101: 1 | F101: 0.034482759 | G101: 0.11111111 | H101: 3.2222222 | I101: 0.71428571 | J101: 0.17034629 | K101: 0.25 | L101: 0.0625 | M101: 1 | N101: 0.15411816 | O101: results_genustree_merged_RF.csv

Sheet Genus_MacroAvg
A1: domain | B1: model | C1: injection | D1: auprc | E1: auprc_lift | F1: auroc | G1: mcc | H1: f2 | I1: precision | J1: recall | K1: source_file
A2: ARC | B2: CNN | C2: unspecified | D2: 0.35047301 | E2: 7.0370988 | F2: 0.50078836 | G2: 0.043343866 | H2: 0.1406423 | I2: 0.22962963 | J2: 0.24 | K2: results_genustree_ARC_CNN.csv
A3: ARC | B3: DeepPhylo | C3: unspecified | D3: 0.15933333 | E3: 1.8521333 | F3: 0.74618519 | G3: 0.039142857 | H3: 0.23085179 | I3: 0.073625616 | J3: 0.6 | K3: results_genustree_ARC_DeepPhylo.csv
A4: ARC | B4: MetaDR | C4: unspecified | D4: 0.45101154 | E4: 7.8679741 | F4: 0.70661905 | G4: 0.34031699 | H4: 0.40922266 | I4: 0.39340659 | J4: 0.59 | K4: results_genustree_ARC_MetaDR.csv
A5: ARC | B5: PMCNN | C5: unspecified | D5: 0.29631148 | E5: 2.8051596 | F5: 0.58257672 | G5: 0.021370607 | H5: 0.090909091 | I5: 0.066666667 | J5: 0.1 | K5: results_genustree_ARC_PMCNN.csv
A6: ARC | B6: PhyloSpec | C6: unspecified | D6: 0.32476557 | E6: 4.6937987 | F6: 0.62150794 | G6: 0.066458761 | H6: 0.22142857 | I6: 0.14357143 | J6: 0.27 | K6: results_genustree_ARC_PhyloSpec.csv
A7: ARC | B7: RF | C7: unspecified | D7: 0.39474387 | E7: 7.3558259 | F7: 0.61192063 | G7: -0.013429677 | H7: 0.095238095 | I7: 0.08 | J7: 0.1 | K7: results_genustree_ARC_RF.csv
