Workbook

Sheet README
A1: Field | B1: Value
A2: Baseline_summary_result.xlsx
A4: Source | B4: Phylospec/multi_models/results/{site_grouped_cv, site_grouped_cv_taxlevel}
A5: Generated | B5: 2026-09-10
A7: Sheet | B7: Description
A8: README | B8: This sheet.
A9: Genus_PerFlag | B9: Per-label (flag) CV results at genus level for the advanced/embedding models: CNN, DeepPhylo, MetaDR, PMCNN, PhyloSpec, RF.
A10: Genus_MacroAvg | B10: Macro-averaged (across labels) results per domain x model, genus level.
A11: TaxLevel_PerFlag | B11: Per-label (flag) CV results across taxonomic levels (Phylum/Class/Order/Family/Genus) for classical baselines: GLMNET, KNN, NNET, RF, SVM, XGBoost.
A12: TaxLevel_MacroAvg | B12: Macro-averaged results per taxonomic level x domain x model.
A13: Combined_MacroAvg | B13: Genus_MacroAvg and TaxLevel_MacroAvg stacked for cross-experiment / cross-model comparison.
A14: Label_Support | B14: Number of positive samples/sites and total sites per label (flag), per domain. Identical across taxonomic levels.
A16: Column notes
A17: domain | B17: Dataset: ARC (archaea), BAC (bacteria), merged (ARC+BAC).
A18: flag | B18: Prediction target / warning label. 'MACRO' = macro-average across all flags.
A19: model | B19: Model name.
A20: level | B20: Taxonomic feature level used as model input (TaxLevel sheets only).
A21: n_pos / prevalence | B21: Number of positive samples and their prevalence for that flag.
A22: n_repeats_scored | B22: Number of CV repeats contributing to the metric.
A23: *_lo / *_hi | B23: Lower/upper bound of the bootstrap confidence interval for that metric.
A24: auprc_lift | B24: AUPRC divided by prevalence (lift over a random/no-skill baseline).

Sheet Summary
B1: 1) TaxLevel
B2: Dataset | C2: Flag | D2: n_pos | E2: prevalence | F2: MCC | K2: AUPR | P2: F2 | Z2: Dataset | AA2: Flag | AB2: n_pos | AC2: prevalence | AD2: MCC | AI2: AUPR | AN2: F2
F3: Phylum | G3: Class | H3: Order | I3: Family | J3: Genus | K3: Phylum | L3: Class | M3: Order | N3: Family | O3: Genus | P3: Phylum | Q3: Class | R3: Order | S3: Family | T3: Genus | AD3: Phylum | AE3: Class | AF3: Order | AG3: Family | AH3: Genus | AI3: Phylum | AJ3: Class | AK3: Order | AL3: Family | AM3: Genus | AN3: Phylum | AO3: Class | AP3: Order | AQ3: Family | AR3: Genus
B4: ARC | C4: buffer_capacity | D4: 9 | E4: 0.065217391 | F4: =_xlfn.MAXIFS(TaxLevel_PerFlag!$Q:$Q,TaxLevel_PerFlag!$A:$A,F$3,TaxLevel_PerFlag!$B:$B,$B$4,TaxLevel_PerFlag!$D:$D,$C4) -> 0.057615481 | G4: =_xlfn.MAXIFS(TaxLevel_PerFlag!$Q:$Q,TaxLevel_PerFlag!$A:$A,G$3,TaxLevel_PerFlag!$B:$B,$B$4,TaxLevel_PerFlag!$D:$D,$C4) -> 0.037926652 | H4: =_xlfn.MAXIFS(TaxLevel_PerFlag!$Q:$Q,TaxLevel_PerFlag!$A:$A,H$3,TaxLevel_PerFlag!$B:$B,$B$4,TaxLevel_PerFlag!$D:$D,$C4) -> 0.041511954 | I4: =_xlfn.MAXIFS(TaxLevel_PerFlag!$Q:$Q,TaxLevel_PerFlag!$A:$A,I$3,TaxLevel_PerFlag!$B:$B,$B$4,TaxLevel_PerFlag!$D:$D,$C4) -> 0.041158916 | J4: =_xlfn.MAXIFS(TaxLevel_PerFlag!$Q:$Q,TaxLevel_PerFlag!$A:$A,J$3,TaxLevel_PerFlag!$B:$B,$B$4,TaxLevel_PerFlag!$D:$D,$C4) -> 0.10923279 | K4: =_xlfn.MAXIFS(TaxLevel_PerFlag!$H:$H,TaxLevel_PerFlag!$A:$A,K$3,TaxLevel_PerFlag!$B:$B,$B$4,TaxLevel_PerFlag!$D:$D,$C4) -> 0.106328 | L4: =_xlfn.MAXIFS(TaxLevel_PerFlag!$H:$H,TaxLevel_PerFlag!$A:$A,L$3,TaxLevel_PerFlag!$B:$B,$B$4,TaxLevel_PerFlag!$D:$D,$C4) -> 0.097759423 | M4: =_xlfn.MAXIFS(TaxLevel_PerFlag!$H:$H,TaxLevel_PerFlag!$A:$A,M$3,TaxLevel_PerFlag!$B:$B,$B$4,TaxLevel_PerFlag!$D:$D,$C4) -> 0.10246996 | N4: =_xlfn.MAXIFS(TaxLevel_PerFlag!$H:$H,TaxLevel_PerFlag!$A:$A,N$3,TaxLevel_PerFlag!$B:$B,$B$4,TaxLevel_PerFlag!$D:$D,$C4) -> 0.12278991 | O4: =_xlfn.MAXIFS(TaxLevel_PerFlag!$H:$H,TaxLevel_PerFlag!$A:$A,O$3,TaxLevel_PerFlag!$B:$B,$B$4,TaxLevel_PerFlag!$D:$D,$C4) -> 0.11746652 | P4: =_xlfn.MAXIFS(TaxLevel_PerFlag!$T:$T,TaxLevel_PerFlag!$A:$A,P$3,TaxLevel_PerFlag!$B:$B,$B$4,TaxLevel_PerFlag!$D:$D,$C4) -> 0.25862069 | Q4: =_xlfn.MAXIFS(TaxLevel_PerFlag!$T:$T,TaxLevel_PerFlag!$A:$A,Q$3,TaxLevel_PerFlag!$B:$B,$B$4,TaxLevel_PerFlag!$D:$D,$C4) -> 0.25862069 | R4: =_xlfn.MAXIFS(TaxLevel_PerFlag!$T:$T,TaxLevel_PerFlag!$A:$A,R$3,TaxLevel_PerFlag!$B:$B,$B$4,TaxLevel_PerFlag!$D:$D,$C4) -> 0.26851765 | S4: =_xlfn.MAXIFS(TaxLevel_PerFlag!$T:$T,TaxLevel_PerFlag!$A:$A,S$3,TaxLevel_PerFlag!$B:$B,$B$4,TaxLevel_PerFlag!$D:$D,$C4) -> 0.22221159 | T4: =_xlfn.MAXIFS(TaxLevel_PerFlag!$T:$T,TaxLevel_PerFlag!$A:$A,T$3,TaxLevel_PerFlag!$B:$B,$B$4,TaxLevel_PerFlag!$D:$D,$C4) -> 0.27722369 | V4: buffer_capacity | W4: 9 | X4: 0.065217391 | Z4: ARC | AA4: buffer_capacity | AB4: 9 | AC4: 0.065217391 | AD4: =SUMIFS(TaxLevel_PerFlag!$Q:$Q,TaxLevel_PerFlag!$A:$A,AD$3,TaxLevel_PerFlag!$B:$B,$Z$4,TaxLevel_PerFlag!$C:$C,"XGBoost",TaxLevel_PerFlag!$D:$D,$AA4) -> -0.11561046 | AE4: =SUMIFS(TaxLevel_PerFlag!$Q:$Q,TaxLevel_PerFlag!$A:$A,AE$3,TaxLevel_PerFlag!$B:$B,$Z$4,TaxLevel_PerFlag!$C:$C,"XGBoost",TaxLevel_PerFlag!$D:$D,$AA4) -> -0.001990389 | AF4: =SUMIFS(TaxLevel_PerFlag!$Q:$Q,TaxLevel_PerFlag!$A:$A,AF$3,TaxLevel_PerFlag!$B:$B,$Z$4,TaxLevel_PerFlag!$C:$C,"XGBoost",TaxLevel_PerFlag!$D:$D,$AA4) -> -0.082215456 | AG4: =SUMIFS(TaxLevel_PerFlag!$Q:$Q,TaxLevel_PerFlag!$A:$A,AG$3,TaxLevel_PerFlag!$B:$B,$Z$4,TaxLevel_PerFlag!$C:$C,"XGBoost",TaxLevel_PerFlag!$D:$D,$AA4) -> 0.023245518 | AH4: =SUMIFS(TaxLevel_PerFlag!$Q:$Q,TaxLevel_PerFlag!$A:$A,AH$3,TaxLevel_PerFlag!$B:$B,$Z$4,TaxLevel_PerFlag!$C:$C,"XGBoost",TaxLevel_PerFlag!$D:$D,$AA4) -> 0.10923279 | AI4: =SUMIFS(TaxLevel_PerFlag!$H:$H,TaxLevel_PerFlag!$A:$A,AI$3,TaxLevel_PerFlag!$B:$B,$Z$4,TaxLevel_PerFlag!$C:$C,"XGBoost",TaxLevel_PerFlag!$D:$D,$AA4) -> 0.061493256 | AJ4: =SUMIFS(TaxLevel_PerFlag!$H:$H,TaxLevel_PerFlag!$A:$A,AJ$3,TaxLevel_PerFlag!$B:$B,$Z$4,TaxLevel_PerFlag!$C:$C,"XGBoost",TaxLevel_PerFlag!$D:$D,$AA4) -> 0.079390186 | AK4: =SUMIFS(TaxLevel_PerFlag!$H:$H,TaxLevel_PerFlag!$A:$A,AK$3,TaxLevel_PerFlag!$B:$B,$Z$4,TaxLevel_PerFlag!$C:$C,"XGBoost",TaxLevel_PerFlag!$D:$D,$AA4) -> 0.070087325 | AL4: =SUMIFS(TaxLevel_PerFlag!$H:$H,TaxLevel_PerFlag!$A:$A,AL$3,TaxLevel_PerFlag!$B:$B,$Z$4,TaxLevel_PerFlag!$C:$C,"XGBoost",TaxLevel_PerFlag!$D:$D,$AA4) -> 0.094839488 | AM4: =SUMIFS(TaxLevel_PerFlag!$H:$H,TaxLevel_PerFlag!$A:$A,AM$3,TaxLevel_PerFlag!$B:$B,$Z$4,TaxLevel_PerFlag!$C:$C,"XGBoost",TaxLevel_PerFlag!$D:$D,$AA4) -> 0.11746652 | AN4: =SUMIFS(TaxLevel_PerFlag!$T:$T,TaxLevel_PerFlag!$A:$A,AN$3,TaxLevel_PerFlag!$B:$B,$Z$4,TaxLevel_PerFlag!$C:$C,"XGBoost",TaxLevel_PerFlag!$D:$D,$AA4) -> 0.18514024 | AO4: =SUMIFS(TaxLevel_PerFlag!$T:$T,TaxLevel_PerFlag!$A:$A,AO$3,TaxLevel_PerFlag!$B:$B,$Z$4,TaxLevel_PerFlag!$C:$C,"XGBoost",TaxLevel_PerFlag!$D:$D,$AA4) -> 0.15918056 | AP4: =SUMIFS(TaxLevel_PerFlag!$T:$T,TaxLevel_PerFlag!$A:$A,AP$3,TaxLevel_PerFlag!$B:$B,$Z$4,TaxLevel_PerFlag!$C:$C,"XGBoost",TaxLevel_PerFlag!$D:$D,$AA4) -> 0.21807405 | AQ4: =SUMIFS(TaxLevel_PerFlag!$T:$T,TaxLevel_PerFlag!$A:$A,AQ$3,TaxLevel_PerFlag!$B:$B,$Z$4,TaxLevel_PerFlag!$C:$C,"XGBoost",TaxLevel_PerFlag!$D:$D,$AA4) -> 0.22221159 | AR4: =SUMIFS(TaxLevel_PerFlag!$T:$T,TaxLevel_PerFlag!$A:$A,AR$3,TaxLevel_PerFlag!$B:$B,$Z$4,TaxLevel_PerFlag!$C:$C,"XGBoost",TaxLevel_PerFlag!$D:$D,$AA4) -> 0.27722369
C5: acid_base_balance | D5: 4 | E5: 0.028985507 | F5: =_xlfn.MAXIFS(TaxLevel_PerFlag!$Q:$Q,TaxLevel_PerFlag!$A:$A,F$3,TaxLevel_PerFlag!$B:$B,$B$4,TaxLevel_PerFlag!$D:$D,$C5) -> 0.16502327 | G5: =_xlfn.MAXIFS(TaxLevel_PerFlag!$Q:$Q,TaxLevel_PerFlag!$A:$A,G$3,TaxLevel_PerFlag!$B:$B,$B$4,TaxLevel_PerFlag!$D:$D,$C5) -> 0.16507893 | H5: =_xlfn.MAXIFS(TaxLevel_PerFlag!$Q:$Q,TaxLevel_PerFlag!$A:$A,H$3,TaxLevel_PerFlag!$B:$B,$B$4,TaxLevel_PerFlag!$D:$D,$C5) -> 0.21032261 | I5: =_xlfn.MAXIFS(TaxLevel_PerFlag!$Q:$Q,TaxLevel_PerFlag!$A:$A,I$3,TaxLevel_PerFlag!$B:$B,$B$4,TaxLevel_PerFlag!$D:$D,$C5) -> 0.20485943 | J5: =_xlfn.MAXIFS(TaxLevel_PerFlag!$Q:$Q,TaxLevel_PerFlag!$A:$A,J$3,TaxLevel_PerFlag!$B:$B,$B$4,TaxLevel_PerFlag!$D:$D,$C5) -> 0.1184265 | K5: =_xlfn.MAXIFS(TaxLevel_PerFlag!$H:$H,TaxLevel_PerFlag!$A:$A,K$3,TaxLevel_PerFlag!$B:$B,$B$4,TaxLevel_PerFlag!$D:$D,$C5) -> 0.30912546 | L5: =_xlfn.MAXIFS(TaxLevel_PerFlag!$H:$H,TaxLevel_PerFlag!$A:$A,L$3,TaxLevel_PerFlag!$B:$B,$B$4,TaxLevel_PerFlag!$D:$D,$C5) -> 0.28527646 | M5: =_xlfn.MAXIFS(TaxLevel_PerFlag!$H:$H,TaxLevel_PerFlag!$A:$A,M$3,TaxLevel_PerFlag!$B:$B,$B$4,TaxLevel_PerFlag!$D:$D,$C5) -> 0.29751069 | N5: =_xlfn.MAXIFS(TaxLevel_PerFlag!$H:$H,TaxLevel_PerFlag!$A:$A,N$3,TaxLevel_PerFlag!$B:$B,$B$4,TaxLevel_PerFlag!$D:$D,$C5) -> 0.2954604 | O5: =_xlfn.MAXIFS(TaxLevel_PerFlag!$H:$H,TaxLevel_PerFlag!$A:$A,O$3,TaxLevel_PerFlag!$B:$B,$B$4,TaxLevel_PerFlag!$D:$D,$C5) -> 0.2753116 | P5: =_xlfn.MAXIFS(TaxLevel_PerFlag!$T:$T,TaxLevel_PerFlag!$A:$A,P$3,TaxLevel_PerFlag!$B:$B,$B$4,TaxLevel_PerFlag!$D:$D,$C5) -> 0.42589096 | Q5: =_xlfn.MAXIFS(TaxLevel_PerFlag!$T:$T,TaxLevel_PerFlag!$A:$A,Q$3,TaxLevel_PerFlag!$B:$B,$B$4,TaxLevel_PerFlag!$D:$D,$C5) -> 0.38926656 | R5: =_xlfn.MAXIFS(TaxLevel_PerFlag!$T:$T,TaxLevel_PerFlag!$A:$A,R$3,TaxLevel_PerFlag!$B:$B,$B$4,TaxLevel_PerFlag!$D:$D,$C5) -> 0.42355396 | S5: =_xlfn.MAXIFS(TaxLevel_PerFlag!$T:$T,TaxLevel_PerFlag!$A:$A,S$3,TaxLevel_PerFlag!$B:$B,$B$4,TaxLevel_PerFlag!$D:$D,$C5) -> 0.40671579 | T5: =_xlfn.MAXIFS(TaxLevel_PerFlag!$T:$T,TaxLevel_PerFlag!$A:$A,T$3,TaxLevel_PerFlag!$B:$B,$B$4,TaxLevel_PerFlag!$D:$D,$C5) -> 0.37723278 | V5: acid_accumulation | W5: 4 | X5: 0.028985507 | AA5: acid_base_balance | AB5: 4 | AC5: 0.028985507 | AD5: =SUMIFS(TaxLevel_PerFlag!$Q:$Q,TaxLevel_PerFlag!$A:$A,AD$3,TaxLevel_PerFlag!$B:$B,$Z$4,TaxLevel_PerFlag!$C:$C,"XGBoost",TaxLevel_PerFlag!$D:$D,$AA5) -> 0.1251079 | AE5: =SUMIFS(TaxLevel_PerFlag!$Q:$Q,TaxLevel_PerFlag!$A:$A,AE$3,TaxLevel_PerFlag!$B:$B,$Z$4,TaxLevel_PerFlag!$C:$C,"XGBoost",TaxLevel_PerFlag!$D:$D,$AA5) -> 0.16507893 | AF5: =SUMIFS(TaxLevel_PerFlag!$Q:$Q,TaxLevel_PerFlag!$A:$A,AF$3,TaxLevel_PerFlag!$B:$B,$Z$4,TaxLevel_PerFlag!$C:$C,"XGBoost",TaxLevel_PerFlag!$D:$D,$AA5) -> 0.15984085 | AG5: =SUMIFS(TaxLevel_PerFlag!$Q:$Q,TaxLevel_PerFlag!$A:$A,AG$3,TaxLevel_PerFlag!$B:$B,$Z$4,TaxLevel_PerFlag!$C:$C,"XGBoost",TaxLevel_PerFlag!$D:$D,$AA5) -> 0.17721741 | AH5: =SUMIFS(TaxLevel_PerFlag!$Q:$Q,TaxLevel_PerFlag!$A:$A,AH$3,TaxLevel_PerFlag!$B:$B,$Z$4,TaxLevel_PerFlag!$C:$C,"XGBoost",TaxLevel_PerFlag!$D:$D,$AA5) -> 0.1184265 | AI5: =SUMIFS(TaxLevel_PerFlag!$H:$H,TaxLevel_PerFlag!$A:$A,AI$3,TaxLevel_PerFlag!$B:$B,$Z$4,TaxLevel_PerFlag!$C:$C,"XGBoost",TaxLevel_PerFlag!$D:$D,$AA5) -> 0.30912546 | AJ5: =SUMIFS(TaxLevel_PerFlag!$H:$H,TaxLevel_PerFlag!$A:$A,AJ$3,TaxLevel_PerFlag!$B:$B,$Z$4,TaxLevel_PerFlag!$C:$C,"XGBoost",TaxLevel_PerFlag!$D:$D,$AA5) -> 0.28527646 | AK5: =SUMIFS(TaxLevel_PerFlag!$H:$H,TaxLevel_PerFlag!$A:$A,AK$3,TaxLevel_PerFlag!$B:$B,$Z$4,TaxLevel_PerFlag!$C:$C,"XGBoost",TaxLevel_PerFlag!$D:$D,$AA5) -> 0.29751069 | AL5: =SUMIFS(TaxLevel_PerFlag!$H:$H,TaxLevel_PerFlag!$A:$A,AL$3,TaxLevel_PerFlag!$B:$B,$Z$4,TaxLevel_PerFlag!$C:$C,"XGBoost",TaxLevel_PerFlag!$D:$D,$AA5) -> 0.2954604 | AM5: =SUMIFS(TaxLevel_PerFlag!$H:$H,TaxLevel_PerFlag!$A:$A,AM$3,TaxLevel_PerFlag!$B:$B,$Z$4,TaxLevel_PerFlag!$C:$C,"XGBoost",TaxLevel_PerFlag!$D:$D,$AA5) -> 0.2753116 | AN5: =SUMIFS(TaxLevel_PerFlag!$T:$T,TaxLevel_PerFlag!$A:$A,AN$3,TaxLevel_PerFlag!$B:$B,$Z$4,TaxLevel_PerFlag!$C:$C,"XGBoost",TaxLevel_PerFlag!$D:$D,$AA5) -> 0.26945282 | AO5: =SUMIFS(TaxLevel_PerFlag!$T:$T,TaxLevel_PerFlag!$A:$A,AO$3,TaxLevel_PerFlag!$B:$B,$Z$4,TaxLevel_PerFlag!$C:$C,"XGBoost",TaxLevel_PerFlag!$D:$D,$AA5) -> 0.33463072 | AP5: =SUMIFS(TaxLevel_PerFlag!$T:$T,TaxLevel_PerFlag!$A:$A,AP$3,TaxLevel_PerFlag!$B:$B,$Z$4,TaxLevel_PerFlag!$C:$C,"XGBoost",TaxLevel_PerFlag!$D:$D,$AA5) -> 0.29195855 | AQ5: =SUMIFS(TaxLevel_PerFlag!$T:$T,TaxLevel_PerFlag!$A:$A,AQ$3,TaxLevel_PerFlag!$B:$B,$Z$4,TaxLevel_PerFlag!$C:$C,"XGBoost",TaxLevel_PerFlag!$D:$D,$AA5) -> 0.40671579 | AR5: =SUMIFS(TaxLevel_PerFlag!$T:$T,TaxLevel_PerFlag!$A:$A,AR$3,TaxLevel_PerFlag!$B:$B,$Z$4,TaxLevel_PerFlag!$C:$C,"XGBoost",TaxLevel_PerFlag!$D:$D,$AA5) -> 0.37723278
C6: acid_accumulation | D6: 20 | E6: 0.14492754 | F6: =_xlfn.MAXIFS(TaxLevel_PerFlag!$Q:$Q,TaxLevel_PerFlag!$A:$A,F$3,TaxLevel_PerFlag!$B:$B,$B$4,TaxLevel_PerFlag!$D:$D,$C6) -> 0.10620714 | G6: =_xlfn.MAXIFS(TaxLevel_PerFlag!$Q:$Q,TaxLevel_PerFlag!$A:$A,G$3,TaxLevel_PerFlag!$B:$B,$B$4,TaxLevel_PerFlag!$D:$D,$C6) -> 0.063281053 | H6: =_xlfn.MAXIFS(TaxLevel_PerFlag!$Q:$Q,TaxLevel_PerFlag!$A:$A,H$3,TaxLevel_PerFlag!$B:$B,$B$4,TaxLevel_PerFlag!$D:$D,$C6) -> 0.088389388 | I6: =_xlfn.MAXIFS(TaxLevel_PerFlag!$Q:$Q,TaxLevel_PerFlag!$A:$A,I$3,TaxLevel_PerFlag!$B:$B,$B$4,TaxLevel_PerFlag!$D:$D,$C6) -> 0.18907876 | J6: =_xlfn.MAXIFS(TaxLevel_PerFlag!$Q:$Q,TaxLevel_PerFlag!$A:$A,J$3,TaxLevel_PerFlag!$B:$B,$B$4,TaxLevel_PerFlag!$D:$D,$C6) -> 0.15110532 | K6: =_xlfn.MAXIFS(TaxLevel_PerFlag!$H:$H,TaxLevel_PerFlag!$A:$A,K$3,TaxLevel_PerFlag!$B:$B,$B$4,TaxLevel_PerFlag!$D:$D,$C6) -> 0.062770049 | L6: =_xlfn.MAXIFS(TaxLevel_PerFlag!$H:$H,TaxLevel_PerFlag!$A:$A,L$3,TaxLevel_PerFlag!$B:$B,$B$4,TaxLevel_PerFlag!$D:$D,$C6) -> 0.079129264 | M6: =_xlfn.MAXIFS(TaxLevel_PerFlag!$H:$H,TaxLevel_PerFlag!$A:$A,M$3,TaxLevel_PerFlag!$B:$B,$B$4,TaxLevel_PerFlag!$D:$D,$C6) -> 0.078905245 | N6: =_xlfn.MAXIFS(TaxLevel_PerFlag!$H:$H,TaxLevel_PerFlag!$A:$A,N$3,TaxLevel_PerFlag!$B:$B,$B$4,TaxLevel_PerFlag!$D:$D,$C6) -> 0.24138277 | O6: =_xlfn.MAXIFS(TaxLevel_PerFlag!$H:$H,TaxLevel_PerFlag!$A:$A,O$3,TaxLevel_PerFlag!$B:$B,$B$4,TaxLevel_PerFlag!$D:$D,$C6) -> 0.20443605 | P6: =_xlfn.MAXIFS(TaxLevel_PerFlag!$T:$T,TaxLevel_PerFlag!$A:$A,P$3,TaxLevel_PerFlag!$B:$B,$B$4,TaxLevel_PerFlag!$D:$D,$C6) -> 0.18270628 | Q6: =_xlfn.MAXIFS(TaxLevel_PerFlag!$T:$T,TaxLevel_PerFlag!$A:$A,Q$3,TaxLevel_PerFlag!$B:$B,$B$4,TaxLevel_PerFlag!$D:$D,$C6) -> 0.17698968 | R6: =_xlfn.MAXIFS(TaxLevel_PerFlag!$T:$T,TaxLevel_PerFlag!$A:$A,R$3,TaxLevel_PerFlag!$B:$B,$B$4,TaxLevel_PerFlag!$D:$D,$C6) -> 0.17698968 | S6: =_xlfn.MAXIFS(TaxLevel_PerFlag!$T:$T,TaxLevel_PerFlag!$A:$A,S$3,TaxLevel_PerFlag!$B:$B,$B$4,TaxLevel_PerFlag!$D:$D,$C6) -> 0.29262189 | T6: =_xlfn.MAXIFS(TaxLevel_PerFlag!$T:$T,TaxLevel_PerFlag!$A:$A,T$3,TaxLevel_PerFlag!$B:$B,$B$4,TaxLevel_PerFlag!$D:$D,$C6) -> 0.23551784 | V6: acid_base_balance | W6: 20 | X6: 0.14492754 | AA6: acid_accumulation | AB6: 20 | AC6: 0.14492754 | AD6: =SUMIFS(TaxLevel_PerFlag!$Q:$Q,TaxLevel_PerFlag!$A:$A,AD$3,TaxLevel_PerFlag!$B:$B,$Z$4,TaxLevel_PerFlag!$C:$C,"XGBoost",TaxLevel_PerFlag!$D:$D,$AA6) -> 0.033545319 | AE6: =SUMIFS(TaxLevel_PerFlag!$Q:$Q,TaxLevel_PerFlag!$A:$A,AE$3,TaxLevel_PerFlag!$B:$B,$Z$4,TaxLevel_PerFlag!$C:$C,"XGBoost",TaxLevel_PerFlag!$D:$D,$AA6) -> -0.020264268 | AF6: =SUMIFS(TaxLevel_PerFlag!$Q:$Q,TaxLevel_PerFlag!$A:$A,AF$3,TaxLevel_PerFlag!$B:$B,$Z$4,TaxLevel_PerFlag!$C:$C,"XGBoost",TaxLevel_PerFlag!$D:$D,$AA6) -> 0.018531783 | AG6: =SUMIFS(TaxLevel_PerFlag!$Q:$Q,TaxLevel_PerFlag!$A:$A,AG$3,TaxLevel_PerFlag!$B:$B,$Z$4,TaxLevel_PerFlag!$C:$C,"XGBoost",TaxLevel_PerFlag!$D:$D,$AA6) -> 0.18907876 | AH6: =SUMIFS(TaxLevel_PerFlag!$Q:$Q,TaxLevel_PerFlag!$A:$A,AH$3,TaxLevel_PerFlag!$B:$B,$Z$4,TaxLevel_PerFlag!$C:$C,"XGBoost",TaxLevel_PerFlag!$D:$D,$AA6) -> 0.15110532 | AI6: =SUMIFS(TaxLevel_PerFlag!$H:$H,TaxLevel_PerFlag!$A:$A,AI$3,TaxLevel_PerFlag!$B:$B,$Z$4,TaxLevel_PerFlag!$C:$C,"XGBoost",TaxLevel_PerFlag!$D:$D,$AA6) -> 0.04387025 | AJ6: =SUMIFS(TaxLevel_PerFlag!$H:$H,TaxLevel_PerFlag!$A:$A,AJ$3,TaxLevel_PerFlag!$B:$B,$Z$4,TaxLevel_PerFlag!$C:$C,"XGBoost",TaxLevel_PerFlag!$D:$D,$AA6) -> 0.032770812 | AK6: =SUMIFS(TaxLevel_PerFlag!$H:$H,TaxLevel_PerFlag!$A:$A,AK$3,TaxLevel_PerFlag!$B:$B,$Z$4,TaxLevel_PerFlag!$C:$C,"XGBoost",TaxLevel_PerFlag!$D:$D,$AA6) -> 0.033856557 | AL6: =SUMIFS(TaxLevel_PerFlag!$H:$H,TaxLevel_PerFlag!$A:$A,AL$3,TaxLevel_PerFlag!$B:$B,$Z$4,TaxLevel_PerFlag!$C:$C,"XGBoost",TaxLevel_PerFlag!$D:$D,$AA6) -> 0.24138277 | AM6: =SUMIFS(TaxLevel_PerFlag!$H:$H,TaxLevel_PerFlag!$A:$A,AM$3,TaxLevel_PerFlag!$B:$B,$Z$4,TaxLevel_PerFlag!$C:$C,"XGBoost",TaxLevel_PerFlag!$D:$D,$AA6) -> 0.12146046 | AN6: =SUMIFS(TaxLevel_PerFlag!$T:$T,TaxLevel_PerFlag!$A:$A,AN$3,TaxLevel_PerFlag!$B:$B,$Z$4,TaxLevel_PerFlag!$C:$C,"XGBoost",TaxLevel_PerFlag!$D:$D,$AA6) -> 0.13018025 | AO6: =SUMIFS(TaxLevel_PerFlag!$T:$T,TaxLevel_PerFlag!$A:$A,AO$3,TaxLevel_PerFlag!$B:$B,$Z$4,TaxLevel_PerFlag!$C:$C,"XGBoost",TaxLevel_PerFlag!$D:$D,$AA6) -> 0.10049034 | AP6: =SUMIFS(TaxLevel_PerFlag!$T:$T,TaxLevel_PerFlag!$A:$A,AP$3,TaxLevel_PerFlag!$B:$B,$Z$4,TaxLevel_PerFlag!$C:$C,"XGBoost",TaxLevel_PerFlag!$D:$D,$AA6) -> 0.1180865 | AQ6: =SUMIFS(TaxLevel_PerFlag!$T:$T,TaxLevel_PerFlag!$A:$A,AQ$3,TaxLevel_PerFlag!$B:$B,$Z$4,TaxLevel_PerFlag!$C:$C,"XGBoost",TaxLevel_PerFlag!$D:$D,$AA6) -> 0.27017967 | AR6: =SUMIFS(TaxLevel_PerFlag!$T:$T,TaxLevel_PerFlag!$A:$A,AR$3,TaxLevel_PerFlag!$B:$B,$Z$4,TaxLevel_PerFlag!$C:$C,"XGBoost",TaxLevel_PerFlag!$D:$D,$AA6) -> 0.2352148
C7: ammonia_toxicity | D7: 26 | E7: 0.1884058 | F7: =_xlfn.MAXIFS(TaxLevel_PerFlag!$Q:$Q,TaxLevel_PerFlag!$A:$A,F$3,TaxLevel_PerFlag!$B:$B,$B$4,TaxLevel_PerFlag!$D:$D,$C7) -> 0.51941102 | G7: =_xlfn.MAXIFS(TaxLevel_PerFlag!$Q:$Q,TaxLevel_PerFlag!$A:$A,G$3,TaxLevel_PerFlag!$B:$B,$B$4,TaxLevel_PerFlag!$D:$D,$C7) -> 0.47368654 | H7: =_xlfn.MAXIFS(TaxLevel_PerFlag!$Q:$Q,TaxLevel_PerFlag!$A:$A,H$3,TaxLevel_PerFlag!$B:$B,$B$4,TaxLevel_PerFlag!$D:$D,$C7) -> 0.47861722 | I7: =_xlfn.MAXIFS(TaxLevel_PerFlag!$Q:$Q,TaxLevel_PerFlag!$A:$A,I$3,TaxLevel_PerFlag!$B:$B,$B$4,TaxLevel_PerFlag!$D:$D,$C7) -> 0.56848376 | J7: =_xlfn.MAXIFS(TaxLevel_PerFlag!$Q:$Q,TaxLevel_PerFlag!$A:$A,J$3,TaxLevel_PerFlag!$B:$B,$B$4,TaxLevel_PerFlag!$D:$D,$C7) -> 0.54889822 | K7: =_xlfn.MAXIFS(TaxLevel_PerFlag!$H:$H,TaxLevel_PerFlag!$A:$A,K$3,TaxLevel_PerFlag!$B:$B,$B$4,TaxLevel_PerFlag!$D:$D,$C7) -> 0.59791791 | L7: =_xlfn.MAXIFS(TaxLevel_PerFlag!$H:$H,TaxLevel_PerFlag!$A:$A,L$3,TaxLevel_PerFlag!$B:$B,$B$4,TaxLevel_PerFlag!$D:$D,$C7) -> 0.57107802 | M7: =_xlfn.MAXIFS(TaxLevel_PerFlag!$H:$H,TaxLevel_PerFlag!$A:$A,M$3,TaxLevel_PerFlag!$B:$B,$B$4,TaxLevel_PerFlag!$D:$D,$C7) -> 0.56936985 | N7: =_xlfn.MAXIFS(TaxLevel_PerFlag!$H:$H,TaxLevel_PerFlag!$A:$A,N$3,TaxLevel_PerFlag!$B:$B,$B$4,TaxLevel_PerFlag!$D:$D,$C7) -> 0.54890359 | O7: =_xlfn.MAXIFS(TaxLevel_PerFlag!$H:$H,TaxLevel_PerFlag!$A:$A,O$3,TaxLevel_PerFlag!$B:$B,$B$4,TaxLevel_PerFlag!$D:$D,$C7) -> 0.59006766 | P7: =_xlfn.MAXIFS(TaxLevel_PerFlag!$T:$T,TaxLevel_PerFlag!$A:$A,P$3,TaxLevel_PerFlag!$B:$B,$B$4,TaxLevel_PerFlag!$D:$D,$C7) -> 0.68507461 | Q7: =_xlfn.MAXIFS(TaxLevel_PerFlag!$T:$T,TaxLevel_PerFlag!$A:$A,Q$3,TaxLevel_PerFlag!$B:$B,$B$4,TaxLevel_PerFlag!$D:$D,$C7) -> 0.68070439 | R7: =_xlfn.MAXIFS(TaxLevel_PerFlag!$T:$T,TaxLevel_PerFlag!$A:$A,R$3,TaxLevel_PerFlag!$B:$B,$B$4,TaxLevel_PerFlag!$D:$D,$C7) -> 0.68951273 | S7: =_xlfn.MAXIFS(TaxLevel_PerFlag!$T:$T,TaxLevel_PerFlag!$A:$A,S$3,TaxLevel_PerFlag!$B:$B,$B$4,TaxLevel_PerFlag!$D:$D,$C7) -> 0.75760504 | T7: =_xlfn.MAXIFS(TaxLevel_PerFlag!$T:$T,TaxLevel_PerFlag!$A:$A,T$3,TaxLevel_PerFlag!$B:$B,$B$4,TaxLevel_PerFlag!$D:$D,$C7) -> 0.69868784 | V7: ammonia_toxicity | W7: 26 | X7: 0.1884058 | AA7: ammonia_toxicity | AB7: 26 | AC7: 0.1884058 | AD7: =SUMIFS(TaxLevel_PerFlag!$Q:$Q,TaxLevel_PerFlag!$A:$A,AD$3,TaxLevel_PerFlag!$B:$B,$Z$4,TaxLevel_PerFlag!$C:$C,"XGBoost",TaxLevel_PerFlag!$D:$D,$AA7) -> 0.45223521 | AE7: =SUMIFS(TaxLevel_PerFlag!$Q:$Q,TaxLevel_PerFlag!$A:$A,AE$3,TaxLevel_PerFlag!$B:$B,$Z$4,TaxLevel_PerFlag!$C:$C,"XGBoost",TaxLevel_PerFlag!$D:$D,$AA7) -> 0.45998774 | AF7: =SUMIFS(TaxLevel_PerFlag!$Q:$Q,TaxLevel_PerFlag!$A:$A,AF$3,TaxLevel_PerFlag!$B:$B,$Z$4,TaxLevel_PerFlag!$C:$C,"XGBoost",TaxLevel_PerFlag!$D:$D,$AA7) -> 0.46218151 | AG7: =SUMIFS(TaxLevel_PerFlag!$Q:$Q,TaxLevel_PerFlag!$A:$A,AG$3,TaxLevel_PerFlag!$B:$B,$Z$4,TaxLevel_PerFlag!$C:$C,"XGBoost",TaxLevel_PerFlag!$D:$D,$AA7) -> 0.41792079 | AH7: =SUMIFS(TaxLevel_PerFlag!$Q:$Q,TaxLevel_PerFlag!$A:$A,AH$3,TaxLevel_PerFlag!$B:$B,$Z$4,TaxLevel_PerFlag!$C:$C,"XGBoost",TaxLevel_PerFlag!$D:$D,$AA7) -> 0.47334208 | AI7: =SUMIFS(TaxLevel_PerFlag!$H:$H,TaxLevel_PerFlag!$A:$A,AI$3,TaxLevel_PerFlag!$B:$B,$Z$4,TaxLevel_PerFlag!$C:$C,"XGBoost",TaxLevel_PerFlag!$D:$D,$AA7) -> 0.59791791 | AJ7: =SUMIFS(TaxLevel_PerFlag!$H:$H,TaxLevel_PerFlag!$A:$A,AJ$3,TaxLevel_PerFlag!$B:$B,$Z$4,TaxLevel_PerFlag!$C:$C,"XGBoost",TaxLevel_PerFlag!$D:$D,$AA7) -> 0.57107802 | AK7: =SUMIFS(TaxLevel_PerFlag!$H:$H,TaxLevel_PerFlag!$A:$A,AK$3,TaxLevel_PerFlag!$B:$B,$Z$4,TaxLevel_PerFlag!$C:$C,"XGBoost",TaxLevel_PerFlag!$D:$D,$AA7) -> 0.56936985 | AL7: =SUMIFS(TaxLevel_PerFlag!$H:$H,TaxLevel_PerFlag!$A:$A,AL$3,TaxLevel_PerFlag!$B:$B,$Z$4,TaxLevel_PerFlag!$C:$C,"XGBoost",TaxLevel_PerFlag!$D:$D,$AA7) -> 0.54890359 | AM7: =SUMIFS(TaxLevel_PerFlag!$H:$H,TaxLevel_PerFlag!$A:$A,AM$3,TaxLevel_PerFlag!$B:$B,$Z$4,TaxLevel_PerFlag!$C:$C,"XGBoost",TaxLevel_PerFlag!$D:$D,$AA7) -> 0.59006766 | AN7: =SUMIFS(TaxLevel_PerFlag!$T:$T,TaxLevel_PerFlag!$A:$A,AN$3,TaxLevel_PerFlag!$B:$B,$Z$4,TaxLevel_PerFlag!$C:$C,"XGBoost",TaxLevel_PerFlag!$D:$D,$AA7) -> 0.56371431 | AO7: =SUMIFS(TaxLevel_PerFlag!$T:$T,TaxLevel_PerFlag!$A:$A,AO$3,TaxLevel_PerFlag!$B:$B,$Z$4,TaxLevel_PerFlag!$C:$C,"XGBoost",TaxLevel_PerFlag!$D:$D,$AA7) -> 0.6135198 | AP7: =SUMIFS(TaxLevel_PerFlag!$T:$T,TaxLevel_PerFlag!$A:$A,AP$3,TaxLevel_PerFlag!$B:$B,$Z$4,TaxLevel_PerFlag!$C:$C,"XGBoost",TaxLevel_PerFlag!$D:$D,$AA7) -> 0.63249039 | AQ7: =SUMIFS(TaxLevel_PerFlag!$T:$T,TaxLevel_PerFlag!$A:$A,AQ$3,TaxLevel_PerFlag!$B:$B,$Z$4,TaxLevel_PerFlag!$C:$C,"XGBoost",TaxLevel_PerFlag!$D:$D,$AA7) -> 0.62652937 | AR7: =SUMIFS(TaxLevel_PerFlag!$T:$T,TaxLevel_PerFlag!$A:$A,AR$3,TaxLevel_PerFlag!$B:$B,$Z$4,TaxLevel_PerFlag!$C:$C,"XGBoost",TaxLevel_PerFlag!$D:$D,$AA7) -> 0.68006909
C8: biogas_quality | D8: 7 | E8: 0.050724638 | F8: =_xlfn.MAXIFS(TaxLevel_PerFlag!$Q:$Q,TaxLevel_PerFlag!$A:$A,F$3,TaxLevel_PerFlag!$B:$B,$B$4,TaxLevel_PerFlag!$D:$D,$C8) -> 0.049277698 | G8: =_xlfn.MAXIFS(TaxLevel_PerFlag!$Q:$Q,TaxLevel_PerFlag!$A:$A,G$3,TaxLevel_PerFlag!$B:$B,$B$4,TaxLevel_PerFlag!$D:$D,$C8) -> 0 | H8: =_xlfn.MAXIFS(TaxLevel_PerFlag!$Q:$Q,TaxLevel_PerFlag!$A:$A,H$3,TaxLevel_PerFlag!$B:$B,$B$4,TaxLevel_PerFlag!$D:$D,$C8) -> 0.013320287 | I8: =_xlfn.MAXIFS(TaxLevel_PerFlag!$Q:$Q,TaxLevel_PerFlag!$A:$A,I$3,TaxLevel_PerFlag!$B:$B,$B$4,TaxLevel_PerFlag!$D:$D,$C8) -> 0.20836685 | J8: =_xlfn.MAXIFS(TaxLevel_PerFlag!$Q:$Q,TaxLevel_PerFlag!$A:$A,J$3,TaxLevel_PerFlag!$B:$B,$B$4,TaxLevel_PerFlag!$D:$D,$C8) -> 0.12262499 | K8: =_xlfn.MAXIFS(TaxLevel_PerFlag!$H:$H,TaxLevel_PerFlag!$A:$A,K$3,TaxLevel_PerFlag!$B:$B,$B$4,TaxLevel_PerFlag!$D:$D,$C8) -> 0.057821583 | L8: =_xlfn.MAXIFS(TaxLevel_PerFlag!$H:$H,TaxLevel_PerFlag!$A:$A,L$3,TaxLevel_PerFlag!$B:$B,$B$4,TaxLevel_PerFlag!$D:$D,$C8) -> 0.052781488 | M8: =_xlfn.MAXIFS(TaxLevel_PerFlag!$H:$H,TaxLevel_PerFlag!$A:$A,M$3,TaxLevel_PerFlag!$B:$B,$B$4,TaxLevel_PerFlag!$D:$D,$C8) -> 0.057096424 | N8: =_xlfn.MAXIFS(TaxLevel_PerFlag!$H:$H,TaxLevel_PerFlag!$A:$A,N$3,TaxLevel_PerFlag!$B:$B,$B$4,TaxLevel_PerFlag!$D:$D,$C8) -> 0.14743244 | O8: =_xlfn.MAXIFS(TaxLevel_PerFlag!$H:$H,TaxLevel_PerFlag!$A:$A,O$3,TaxLevel_PerFlag!$B:$B,$B$4,TaxLevel_PerFlag!$D:$D,$C8) -> 0.11805457 | P8: =_xlfn.MAXIFS(TaxLevel_PerFlag!$T:$T,TaxLevel_PerFlag!$A:$A,P$3,TaxLevel_PerFlag!$B:$B,$B$4,TaxLevel_PerFlag!$D:$D,$C8) -> 0.21691574 | Q8: =_xlfn.MAXIFS(TaxLevel_PerFlag!$T:$T,TaxLevel_PerFlag!$A:$A,Q$3,TaxLevel_PerFlag!$B:$B,$B$4,TaxLevel_PerFlag!$D:$D,$C8) -> 0.21084337 | R8: =_xlfn.MAXIFS(TaxLevel_PerFlag!$T:$T,TaxLevel_PerFlag!$A:$A,R$3,TaxLevel_PerFlag!$B:$B,$B$4,TaxLevel_PerFlag!$D:$D,$C8) -> 0.21084337 | S8: =_xlfn.MAXIFS(TaxLevel_PerFlag!$T:$T,TaxLevel_PerFlag!$A:$A,S$3,TaxLevel_PerFlag!$B:$B,$B$4,TaxLevel_PerFlag!$D:$D,$C8) -> 0.35505464 | T8: =_xlfn.MAXIFS(TaxLevel_PerFlag!$T:$T,TaxLevel_PerFlag!$A:$A,T$3,TaxLevel_PerFlag!$B:$B,$B$4,TaxLevel_PerFlag!$D:$D,$C8) -> 0.27793144 | V8: biogas_quality | W8: 7 | X8: 0.050724638 | AA8: biogas_quality | AB8: 7 | AC8: 0.050724638 | AD8: =SUMIFS(TaxLevel_PerFlag!$Q:$Q,TaxLevel_PerFlag!$A:$A,AD$3,TaxLevel_PerFlag!$B:$B,$Z$4,TaxLevel_PerFlag!$C:$C,"XGBoost",TaxLevel_PerFlag!$D:$D,$AA8) -> 0.049277698 | AE8: =SUMIFS(TaxLevel_PerFlag!$Q:$Q,TaxLevel_PerFlag!$A:$A,AE$3,TaxLevel_PerFlag!$B:$B,$Z$4,TaxLevel_PerFlag!$C:$C,"XGBoost",TaxLevel_PerFlag!$D:$D,$AA8) -> -0.041130405 | AF8: =SUMIFS(TaxLevel_PerFlag!$Q:$Q,TaxLevel_PerFlag!$A:$A,AF$3,TaxLevel_PerFlag!$B:$B,$Z$4,TaxLevel_PerFlag!$C:$C,"XGBoost",TaxLevel_PerFlag!$D:$D,$AA8) -> -0.035367223 | AG8: =SUMIFS(TaxLevel_PerFlag!$Q:$Q,TaxLevel_PerFlag!$A:$A,AG$3,TaxLevel_PerFlag!$B:$B,$Z$4,TaxLevel_PerFlag!$C:$C,"XGBoost",TaxLevel_PerFlag!$D:$D,$AA8) -> 0.10422556 | AH8: =SUMIFS(TaxLevel_PerFlag!$Q:$Q,TaxLevel_PerFlag!$A:$A,AH$3,TaxLevel_PerFlag!$B:$B,$Z$4,TaxLevel_PerFlag!$C:$C,"XGBoost",TaxLevel_PerFlag!$D:$D,$AA8) -> 0.12262499 | AI8: =SUMIFS(TaxLevel_PerFlag!$H:$H,TaxLevel_PerFlag!$A:$A,AI$3,TaxLevel_PerFlag!$B:$B,$Z$4,TaxLevel_PerFlag!$C:$C,"XGBoost",TaxLevel_PerFlag!$D:$D,$AA8) -> 0.057821583 | AJ8: =SUMIFS(TaxLevel_PerFlag!$H:$H,TaxLevel_PerFlag!$A:$A,AJ$3,TaxLevel_PerFlag!$B:$B,$Z$4,TaxLevel_PerFlag!$C:$C,"XGBoost",TaxLevel_PerFlag!$D:$D,$AA8) -> 0.046661294 | AK8: =SUMIFS(TaxLevel_PerFlag!$H:$H,TaxLevel_PerFlag!$A:$A,AK$3,TaxLevel_PerFlag!$B:$B,$Z$4,TaxLevel_PerFlag!$C:$C,"XGBoost",TaxLevel_PerFlag!$D:$D,$AA8) -> 0.050353838 | AL8: =SUMIFS(TaxLevel_PerFlag!$H:$H,TaxLevel_PerFlag!$A:$A,AL$3,TaxLevel_PerFlag!$B:$B,$Z$4,TaxLevel_PerFlag!$C:$C,"XGBoost",TaxLevel_PerFlag!$D:$D,$AA8) -> 0.084444115 | AM8: =SUMIFS(TaxLevel_PerFlag!$H:$H,TaxLevel_PerFlag!$A:$A,AM$3,TaxLevel_PerFlag!$B:$B,$Z$4,TaxLevel_PerFlag!$C:$C,"XGBoost",TaxLevel_PerFlag!$D:$D,$AA8) -> 0.11805457 | AN8: =SUMIFS(TaxLevel_PerFlag!$T:$T,TaxLevel_PerFlag!$A:$A,AN$3,TaxLevel_PerFlag!$B:$B,$Z$4,TaxLevel_PerFlag!$C:$C,"XGBoost",TaxLevel_PerFlag!$D:$D,$AA8) -> 0.21691574 | AO8: =SUMIFS(TaxLevel_PerFlag!$T:$T,TaxLevel_PerFlag!$A:$A,AO$3,TaxLevel_PerFlag!$B:$B,$Z$4,TaxLevel_PerFlag!$C:$C,"XGBoost",TaxLevel_PerFlag!$D:$D,$AA8) -> 0.15526106 | AP8: =SUMIFS(TaxLevel_PerFlag!$T:$T,TaxLevel_PerFlag!$A:$A,AP$3,TaxLevel_PerFlag!$B:$B,$Z$4,TaxLevel_PerFlag!$C:$C,"XGBoost",TaxLevel_PerFlag!$D:$D,$AA8) -> 0.18967535 | AQ8: =SUMIFS(TaxLevel_PerFlag!$T:$T,TaxLevel_PerFlag!$A:$A,AQ$3,TaxLevel_PerFlag!$B:$B,$Z$4,TaxLevel_PerFlag!$C:$C,"XGBoost",TaxLevel_PerFlag!$D:$D,$AA8) -> 0.25832778 | AR8: =SUMIFS(TaxLevel_PerFlag!$T:$T,TaxLevel_PerFlag!$A:$A,AR$3,TaxLevel_PerFlag!$B:$B,$Z$4,TaxLevel_PerFlag!$C:$C,"XGBoost",TaxLevel_PerFlag!$D:$D,$AA8) -> 0.27793144
C9: Macro-avg | F9: =AVERAGE(F4:F8) -> 0.17950692 | G9: =AVERAGE(G4:G8) -> 0.14799463 | H9: =AVERAGE(H4:H8) -> 0.16643229 | I9: =AVERAGE(I4:I8) -> 0.24238954 | J9: =AVERAGE(J4:J8) -> 0.21005756 | K9: =AVERAGE(K4:K8) -> 0.2267926 | L9: =AVERAGE(L4:L8) -> 0.21720493 | M9: =AVERAGE(M4:M8) -> 0.22107044 | ... T9: =AVERAGE(T4:T8) -> 0.37331872 | AA9: Macro-avg | AD9: =AVERAGE(AD4:AD8) -> 0.10891113 | AE9: =AVERAGE(AE4:AE8) -> 0.11233632 | AF9: =AVERAGE(AF4:AF8) -> 0.10459429 | AG9: =AVERAGE(AG4:AG8) -> 0.18233761 | AH9: =AVERAGE(AH4:AH8) -> 0.19494633 | AI9: =AVERAGE(AI4:AI8) -> 0.21404569 | AJ9: =AVERAGE(AJ4:AJ8) -> 0.20303535 | AK9: =AVERAGE(AK4:AK8) -> 0.20423565 | ... AR9: =AVERAGE(AR4:AR8) -> 0.36953436
B10: BAC | C10: buffer_capacity | D10: 9 | E10: 0.065217391 | F10: =_xlfn.MAXIFS(TaxLevel_PerFlag!$Q:$Q,TaxLevel_PerFlag!$A:$A,F$3,TaxLevel_PerFlag!$B:$B,$B$10,TaxLevel_PerFlag!$D:$D,$C10) -> 0.075404556 | G10: =_xlfn.MAXIFS(TaxLevel_PerFlag!$Q:$Q,TaxLevel_PerFlag!$A:$A,G$3,TaxLevel_PerFlag!$B:$B,$B$10,TaxLevel_PerFlag!$D:$D,$C10) -> 0.14698681 | H10: =_xlfn.MAXIFS(TaxLevel_PerFlag!$Q:$Q,TaxLevel_PerFlag!$A:$A,H$3,TaxLevel_PerFlag!$B:$B,$B$10,TaxLevel_PerFlag!$D:$D,$C10) -> 0.24853563 | I10: =_xlfn.MAXIFS(TaxLevel_PerFlag!$Q:$Q,TaxLevel_PerFlag!$A:$A,I$3,TaxLevel_PerFlag!$B:$B,$B$10,TaxLevel_PerFlag!$D:$D,$C10) -> 0.20785484 | J10: =_xlfn.MAXIFS(TaxLevel_PerFlag!$Q:$Q,TaxLevel_PerFlag!$A:$A,J$3,TaxLevel_PerFlag!$B:$B,$B$10,TaxLevel_PerFlag!$D:$D,$C10) -> 0.13959212 | K10: =_xlfn.MAXIFS(TaxLevel_PerFlag!$H:$H,TaxLevel_PerFlag!$A:$A,K$3,TaxLevel_PerFlag!$B:$B,$B$10,TaxLevel_PerFlag!$D:$D,$C10) -> 0.10318351 | L10: =_xlfn.MAXIFS(TaxLevel_PerFlag!$H:$H,TaxLevel_PerFlag!$A:$A,L$3,TaxLevel_PerFlag!$B:$B,$B$10,TaxLevel_PerFlag!$D:$D,$C10) -> 0.26336868 | M10: =_xlfn.MAXIFS(TaxLevel_PerFlag!$H:$H,TaxLevel_PerFlag!$A:$A,M$3,TaxLevel_PerFlag!$B:$B,$B$10,TaxLevel_PerFlag!$D:$D,$C10) -> 0.29836433 | N10: =_xlfn.MAXIFS(TaxLevel_PerFlag!$H:$H,TaxLevel_PerFlag!$A:$A,N$3,TaxLevel_PerFlag!$B:$B,$B$10,TaxLevel_PerFlag!$D:$D,$C10) -> 0.28419269 | O10: =_xlfn.MAXIFS(TaxLevel_PerFlag!$H:$H,TaxLevel_PerFlag!$A:$A,O$3,TaxLevel_PerFlag!$B:$B,$B$10,TaxLevel_PerFlag!$D:$D,$C10) -> 0.14883598 | P10: =_xlfn.MAXIFS(TaxLevel_PerFlag!$T:$T,TaxLevel_PerFlag!$A:$A,P$3,TaxLevel_PerFlag!$B:$B,$B$10,TaxLevel_PerFlag!$D:$D,$C10) -> 0.22979217 | Q10: =_xlfn.MAXIFS(TaxLevel_PerFlag!$T:$T,TaxLevel_PerFlag!$A:$A,Q$3,TaxLevel_PerFlag!$B:$B,$B$10,TaxLevel_PerFlag!$D:$D,$C10) -> 0.30430153 | R10: =_xlfn.MAXIFS(TaxLevel_PerFlag!$T:$T,TaxLevel_PerFlag!$A:$A,R$3,TaxLevel_PerFlag!$B:$B,$B$10,TaxLevel_PerFlag!$D:$D,$C10) -> 0.2833865 | S10: =_xlfn.MAXIFS(TaxLevel_PerFlag!$T:$T,TaxLevel_PerFlag!$A:$A,S$3,TaxLevel_PerFlag!$B:$B,$B$10,TaxLevel_PerFlag!$D:$D,$C10) -> 0.27012751 | T10: =_xlfn.MAXIFS(TaxLevel_PerFlag!$T:$T,TaxLevel_PerFlag!$A:$A,T$3,TaxLevel_PerFlag!$B:$B,$B$10,TaxLevel_PerFlag!$D:$D,$C10) -> 0.26432479 | Z10: BAC | AA10: buffer_capacity | AB10: 9 | AC10: 0.065217391 | AD10: =SUMIFS(TaxLevel_PerFlag!$Q:$Q,TaxLevel_PerFlag!$A:$A,AD$3,TaxLevel_PerFlag!$B:$B,$Z$10,TaxLevel_PerFlag!$C:$C,"XGBoost",TaxLevel_PerFlag!$D:$D,$AA10) -> 0.075404556 | AE10: =SUMIFS(TaxLevel_PerFlag!$Q:$Q,TaxLevel_PerFlag!$A:$A,AE$3,TaxLevel_PerFlag!$B:$B,$Z$10,TaxLevel_PerFlag!$C:$C,"XGBoost",TaxLevel_PerFlag!$D:$D,$AA10) -> 0.14152151 | AF10: =SUMIFS(TaxLevel_PerFlag!$Q:$Q,TaxLevel_PerFlag!$A:$A,AF$3,TaxLevel_PerFlag!$B:$B,$Z$10,TaxLevel_PerFlag!$C:$C,"XGBoost",TaxLevel_PerFlag!$D:$D,$AA10) -> 0.24853563 | AG10: =SUMIFS(TaxLevel_PerFlag!$Q:$Q,TaxLevel_PerFlag!$A:$A,AG$3,TaxLevel_PerFlag!$B:$B,$Z$10,TaxLevel_PerFlag!$C:$C,"XGBoost",TaxLevel_PerFlag!$D:$D,$AA10) -> 0.13088301 | AH10: =SUMIFS(TaxLevel_PerFlag!$Q:$Q,TaxLevel_PerFlag!$A:$A,AH$3,TaxLevel_PerFlag!$B:$B,$Z$10,TaxLevel_PerFlag!$C:$C,"XGBoost",TaxLevel_PerFlag!$D:$D,$AA10) -> 0.092762127 | AI10: =SUMIFS(TaxLevel_PerFlag!$H:$H,TaxLevel_PerFlag!$A:$A,AI$3,TaxLevel_PerFlag!$B:$B,$Z$10,TaxLevel_PerFlag!$C:$C,"XGBoost",TaxLevel_PerFlag!$D:$D,$AA10) -> 0.10318351 | AJ10: =SUMIFS(TaxLevel_PerFlag!$H:$H,TaxLevel_PerFlag!$A:$A,AJ$3,TaxLevel_PerFlag!$B:$B,$Z$10,TaxLevel_PerFlag!$C:$C,"XGBoost",TaxLevel_PerFlag!$D:$D,$AA10) -> 0.26336868 | AK10: =SUMIFS(TaxLevel_PerFlag!$H:$H,TaxLevel_PerFlag!$A:$A,AK$3,TaxLevel_PerFlag!$B:$B,$Z$10,TaxLevel_PerFlag!$C:$C,"XGBoost",TaxLevel_PerFlag!$D:$D,$AA10) -> 0.29836433 | AL10: =SUMIFS(TaxLevel_PerFlag!$H:$H,TaxLevel_PerFlag!$A:$A,AL$3,TaxLevel_PerFlag!$B:$B,$Z$10,TaxLevel_PerFlag!$C:$C,"XGBoost",TaxLevel_PerFlag!$D:$D,$AA10) -> 0.28419269 | AM10: =SUMIFS(TaxLevel_PerFlag!$H:$H,TaxLevel_PerFlag!$A:$A,AM$3,TaxLevel_PerFlag!$B:$B,$Z$10,TaxLevel_PerFlag!$C:$C,"XGBoost",TaxLevel_PerFlag!$D:$D,$AA10) -> 0.13196208 | AN10: =SUMIFS(TaxLevel_PerFlag!$T:$T,TaxLevel_PerFlag!$A:$A,AN$3,TaxLevel_PerFlag!$B:$B,$Z$10,TaxLevel_PerFlag!$C:$C,"XGBoost",TaxLevel_PerFlag!$D:$D,$AA10) -> 0.22410982 | AO10: =SUMIFS(TaxLevel_PerFlag!$T:$T,TaxLevel_PerFlag!$A:$A,AO$3,TaxLevel_PerFlag!$B:$B,$Z$10,TaxLevel_PerFlag!$C:$C,"XGBoost",TaxLevel_PerFlag!$D:$D,$AA10) -> 0.2741009 | AP10: =SUMIFS(TaxLevel_PerFlag!$T:$T,TaxLevel_PerFlag!$A:$A,AP$3,TaxLevel_PerFlag!$B:$B,$Z$10,TaxLevel_PerFlag!$C:$C,"XGBoost",TaxLevel_PerFlag!$D:$D,$AA10) -> 0.2833865 | AQ10: =SUMIFS(TaxLevel_PerFlag!$T:$T,TaxLevel_PerFlag!$A:$A,AQ$3,TaxLevel_PerFlag!$B:$B,$Z$10,TaxLevel_PerFlag!$C:$C,"XGBoost",TaxLevel_PerFlag!$D:$D,$AA10) -> 0.23260254 | AR10: =SUMIFS(TaxLevel_PerFlag!$T:$T,TaxLevel_PerFlag!$A:$A,AR$3,TaxLevel_PerFlag!$B:$B,$Z$10,TaxLevel_PerFlag!$C:$C,"XGBoost",TaxLevel_PerFlag!$D:$D,$AA10) -> 0.22433393
C11: acid_base_balance | D11: 4 | E11: 0.028985507 | F11: =_xlfn.MAXIFS(TaxLevel_PerFlag!$Q:$Q,TaxLevel_PerFlag!$A:$A,F$3,TaxLevel_PerFlag!$B:$B,$B$10,TaxLevel_PerFlag!$D:$D,$C11) -> 0.39098099 | G11: =_xlfn.MAXIFS(TaxLevel_PerFlag!$Q:$Q,TaxLevel_PerFlag!$A:$A,G$3,TaxLevel_PerFlag!$B:$B,$B$10,TaxLevel_PerFlag!$D:$D,$C11) -> 0.2971126 | H11: =_xlfn.MAXIFS(TaxLevel_PerFlag!$Q:$Q,TaxLevel_PerFlag!$A:$A,H$3,TaxLevel_PerFlag!$B:$B,$B$10,TaxLevel_PerFlag!$D:$D,$C11) -> 0.31271477 | I11: =_xlfn.MAXIFS(TaxLevel_PerFlag!$Q:$Q,TaxLevel_PerFlag!$A:$A,I$3,TaxLevel_PerFlag!$B:$B,$B$10,TaxLevel_PerFlag!$D:$D,$C11) -> 0.28811511 | J11: =_xlfn.MAXIFS(TaxLevel_PerFlag!$Q:$Q,TaxLevel_PerFlag!$A:$A,J$3,TaxLevel_PerFlag!$B:$B,$B$10,TaxLevel_PerFlag!$D:$D,$C11) -> 0.29764348 | K11: =_xlfn.MAXIFS(TaxLevel_PerFlag!$H:$H,TaxLevel_PerFlag!$A:$A,K$3,TaxLevel_PerFlag!$B:$B,$B$10,TaxLevel_PerFlag!$D:$D,$C11) -> 0.52102532 | L11: =_xlfn.MAXIFS(TaxLevel_PerFlag!$H:$H,TaxLevel_PerFlag!$A:$A,L$3,TaxLevel_PerFlag!$B:$B,$B$10,TaxLevel_PerFlag!$D:$D,$C11) -> 0.36604017 | M11: =_xlfn.MAXIFS(TaxLevel_PerFlag!$H:$H,TaxLevel_PerFlag!$A:$A,M$3,TaxLevel_PerFlag!$B:$B,$B$10,TaxLevel_PerFlag!$D:$D,$C11) -> 0.37704282 | N11: =_xlfn.MAXIFS(TaxLevel_PerFlag!$H:$H,TaxLevel_PerFlag!$A:$A,N$3,TaxLevel_PerFlag!$B:$B,$B$10,TaxLevel_PerFlag!$D:$D,$C11) -> 0.41313067 | O11: =_xlfn.MAXIFS(TaxLevel_PerFlag!$H:$H,TaxLevel_PerFlag!$A:$A,O$3,TaxLevel_PerFlag!$B:$B,$B$10,TaxLevel_PerFlag!$D:$D,$C11) -> 0.35625692 | P11: =_xlfn.MAXIFS(TaxLevel_PerFlag!$T:$T,TaxLevel_PerFlag!$A:$A,P$3,TaxLevel_PerFlag!$B:$B,$B$10,TaxLevel_PerFlag!$D:$D,$C11) -> 0.45972538 | Q11: =_xlfn.MAXIFS(TaxLevel_PerFlag!$T:$T,TaxLevel_PerFlag!$A:$A,Q$3,TaxLevel_PerFlag!$B:$B,$B$10,TaxLevel_PerFlag!$D:$D,$C11) -> 0.52889 | R11: =_xlfn.MAXIFS(TaxLevel_PerFlag!$T:$T,TaxLevel_PerFlag!$A:$A,R$3,TaxLevel_PerFlag!$B:$B,$B$10,TaxLevel_PerFlag!$D:$D,$C11) -> 0.50575728 | S11: =_xlfn.MAXIFS(TaxLevel_PerFlag!$T:$T,TaxLevel_PerFlag!$A:$A,S$3,TaxLevel_PerFlag!$B:$B,$B$10,TaxLevel_PerFlag!$D:$D,$C11) -> 0.52202302 | T11: =_xlfn.MAXIFS(TaxLevel_PerFlag!$T:$T,TaxLevel_PerFlag!$A:$A,T$3,TaxLevel_PerFlag!$B:$B,$B$10,TaxLevel_PerFlag!$D:$D,$C11) -> 0.54487282 | AA11: acid_base_balance | AB11: 4 | AC11: 0.028985507 | AD11: =SUMIFS(TaxLevel_PerFlag!$Q:$Q,TaxLevel_PerFlag!$A:$A,AD$3,TaxLevel_PerFlag!$B:$B,$Z$10,TaxLevel_PerFlag!$C:$C,"XGBoost",TaxLevel_PerFlag!$D:$D,$AA11) -> 0.39098099 | AE11: =SUMIFS(TaxLevel_PerFlag!$Q:$Q,TaxLevel_PerFlag!$A:$A,AE$3,TaxLevel_PerFlag!$B:$B,$Z$10,TaxLevel_PerFlag!$C:$C,"XGBoost",TaxLevel_PerFlag!$D:$D,$AA11) -> 0.2394256 | AF11: =SUMIFS(TaxLevel_PerFlag!$Q:$Q,TaxLevel_PerFlag!$A:$A,AF$3,TaxLevel_PerFlag!$B:$B,$Z$10,TaxLevel_PerFlag!$C:$C,"XGBoost",TaxLevel_PerFlag!$D:$D,$AA11) -> 0.31271477 | AG11: =SUMIFS(TaxLevel_PerFlag!$Q:$Q,TaxLevel_PerFlag!$A:$A,AG$3,TaxLevel_PerFlag!$B:$B,$Z$10,TaxLevel_PerFlag!$C:$C,"XGBoost",TaxLevel_PerFlag!$D:$D,$AA11) -> 0.26595297 | AH11: =SUMIFS(TaxLevel_PerFlag!$Q:$Q,TaxLevel_PerFlag!$A:$A,AH$3,TaxLevel_PerFlag!$B:$B,$Z$10,TaxLevel_PerFlag!$C:$C,"XGBoost",TaxLevel_PerFlag!$D:$D,$AA11) -> 0.22924259 | AI11: =SUMIFS(TaxLevel_PerFlag!$H:$H,TaxLevel_PerFlag!$A:$A,AI$3,TaxLevel_PerFlag!$B:$B,$Z$10,TaxLevel_PerFlag!$C:$C,"XGBoost",TaxLevel_PerFlag!$D:$D,$AA11) -> 0.52102532 | AJ11: =SUMIFS(TaxLevel_PerFlag!$H:$H,TaxLevel_PerFlag!$A:$A,AJ$3,TaxLevel_PerFlag!$B:$B,$Z$10,TaxLevel_PerFlag!$C:$C,"XGBoost",TaxLevel_PerFlag!$D:$D,$AA11) -> 0.36604017 | AK11: =SUMIFS(TaxLevel_PerFlag!$H:$H,TaxLevel_PerFlag!$A:$A,AK$3,TaxLevel_PerFlag!$B:$B,$Z$10,TaxLevel_PerFlag!$C:$C,"XGBoost",TaxLevel_PerFlag!$D:$D,$AA11) -> 0.32250783 | AL11: =SUMIFS(TaxLevel_PerFlag!$H:$H,TaxLevel_PerFlag!$A:$A,AL$3,TaxLevel_PerFlag!$B:$B,$Z$10,TaxLevel_PerFlag!$C:$C,"XGBoost",TaxLevel_PerFlag!$D:$D,$AA11) -> 0.37938306 | AM11: =SUMIFS(TaxLevel_PerFlag!$H:$H,TaxLevel_PerFlag!$A:$A,AM$3,TaxLevel_PerFlag!$B:$B,$Z$10,TaxLevel_PerFlag!$C:$C,"XGBoost",TaxLevel_PerFlag!$D:$D,$AA11) -> 0.33458035 | AN11: =SUMIFS(TaxLevel_PerFlag!$T:$T,TaxLevel_PerFlag!$A:$A,AN$3,TaxLevel_PerFlag!$B:$B,$Z$10,TaxLevel_PerFlag!$C:$C,"XGBoost",TaxLevel_PerFlag!$D:$D,$AA11) -> 0.45630622 | AO11: =SUMIFS(TaxLevel_PerFlag!$T:$T,TaxLevel_PerFlag!$A:$A,AO$3,TaxLevel_PerFlag!$B:$B,$Z$10,TaxLevel_PerFlag!$C:$C,"XGBoost",TaxLevel_PerFlag!$D:$D,$AA11) -> 0.45536352 | AP11: =SUMIFS(TaxLevel_PerFlag!$T:$T,TaxLevel_PerFlag!$A:$A,AP$3,TaxLevel_PerFlag!$B:$B,$Z$10,TaxLevel_PerFlag!$C:$C,"XGBoost",TaxLevel_PerFlag!$D:$D,$AA11) -> 0.47570618 | AQ11: =SUMIFS(TaxLevel_PerFlag!$T:$T,TaxLevel_PerFlag!$A:$A,AQ$3,TaxLevel_PerFlag!$B:$B,$Z$10,TaxLevel_PerFlag!$C:$C,"XGBoost",TaxLevel_PerFlag!$D:$D,$AA11) -> 0.42925616 | AR11: =SUMIFS(TaxLevel_PerFlag!$T:$T,TaxLevel_PerFlag!$A:$A,AR$3,TaxLevel_PerFlag!$B:$B,$Z$10,TaxLevel_PerFlag!$C:$C,"XGBoost",TaxLevel_PerFlag!$D:$D,$AA11) -> 0.37210216
C12: acid_accumulation | D12: 20 | E12: 0.14492754 | F12: =_xlfn.MAXIFS(TaxLevel_PerFlag!$Q:$Q,TaxLevel_PerFlag!$A:$A,F$3,TaxLevel_PerFlag!$B:$B,$B$10,TaxLevel_PerFlag!$D:$D,$C12) -> 0.19242043 | G12: =_xlfn.MAXIFS(TaxLevel_PerFlag!$Q:$Q,TaxLevel_PerFlag!$A:$A,G$3,TaxLevel_PerFlag!$B:$B,$B$10,TaxLevel_PerFlag!$D:$D,$C12) -> 0.16146929 | H12: =_xlfn.MAXIFS(TaxLevel_PerFlag!$Q:$Q,TaxLevel_PerFlag!$A:$A,H$3,TaxLevel_PerFlag!$B:$B,$B$10,TaxLevel_PerFlag!$D:$D,$C12) -> 0.56878149 | I12: =_xlfn.MAXIFS(TaxLevel_PerFlag!$Q:$Q,TaxLevel_PerFlag!$A:$A,I$3,TaxLevel_PerFlag!$B:$B,$B$10,TaxLevel_PerFlag!$D:$D,$C12) -> 0.18864023 | J12: =_xlfn.MAXIFS(TaxLevel_PerFlag!$Q:$Q,TaxLevel_PerFlag!$A:$A,J$3,TaxLevel_PerFlag!$B:$B,$B$10,TaxLevel_PerFlag!$D:$D,$C12) -> 0.23061453 | K12: =_xlfn.MAXIFS(TaxLevel_PerFlag!$H:$H,TaxLevel_PerFlag!$A:$A,K$3,TaxLevel_PerFlag!$B:$B,$B$10,TaxLevel_PerFlag!$D:$D,$C12) -> 0.26896825 | L12: =_xlfn.MAXIFS(TaxLevel_PerFlag!$H:$H,TaxLevel_PerFlag!$A:$A,L$3,TaxLevel_PerFlag!$B:$B,$B$10,TaxLevel_PerFlag!$D:$D,$C12) -> 0.22260586 | M12: =_xlfn.MAXIFS(TaxLevel_PerFlag!$H:$H,TaxLevel_PerFlag!$A:$A,M$3,TaxLevel_PerFlag!$B:$B,$B$10,TaxLevel_PerFlag!$D:$D,$C12) -> 0.47601162 | N12: =_xlfn.MAXIFS(TaxLevel_PerFlag!$H:$H,TaxLevel_PerFlag!$A:$A,N$3,TaxLevel_PerFlag!$B:$B,$B$10,TaxLevel_PerFlag!$D:$D,$C12) -> 0.3250534 | O12: =_xlfn.MAXIFS(TaxLevel_PerFlag!$H:$H,TaxLevel_PerFlag!$A:$A,O$3,TaxLevel_PerFlag!$B:$B,$B$10,TaxLevel_PerFlag!$D:$D,$C12) -> 0.31477276 | P12: =_xlfn.MAXIFS(TaxLevel_PerFlag!$T:$T,TaxLevel_PerFlag!$A:$A,P$3,TaxLevel_PerFlag!$B:$B,$B$10,TaxLevel_PerFlag!$D:$D,$C12) -> 0.28596219 | Q12: =_xlfn.MAXIFS(TaxLevel_PerFlag!$T:$T,TaxLevel_PerFlag!$A:$A,Q$3,TaxLevel_PerFlag!$B:$B,$B$10,TaxLevel_PerFlag!$D:$D,$C12) -> 0.25680584 | R12: =_xlfn.MAXIFS(TaxLevel_PerFlag!$T:$T,TaxLevel_PerFlag!$A:$A,R$3,TaxLevel_PerFlag!$B:$B,$B$10,TaxLevel_PerFlag!$D:$D,$C12) -> 0.58909774 | S12: =_xlfn.MAXIFS(TaxLevel_PerFlag!$T:$T,TaxLevel_PerFlag!$A:$A,S$3,TaxLevel_PerFlag!$B:$B,$B$10,TaxLevel_PerFlag!$D:$D,$C12) -> 0.21379119 | T12: =_xlfn.MAXIFS(TaxLevel_PerFlag!$T:$T,TaxLevel_PerFlag!$A:$A,T$3,TaxLevel_PerFlag!$B:$B,$B$10,TaxLevel_PerFlag!$D:$D,$C12) -> 0.24166985 | AA12: acid_accumulation | AB12: 20 | AC12: 0.14492754 | AD12: =SUMIFS(TaxLevel_PerFlag!$Q:$Q,TaxLevel_PerFlag!$A:$A,AD$3,TaxLevel_PerFlag!$B:$B,$Z$10,TaxLevel_PerFlag!$C:$C,"XGBoost",TaxLevel_PerFlag!$D:$D,$AA12) -> 0.10345807 | AE12: =SUMIFS(TaxLevel_PerFlag!$Q:$Q,TaxLevel_PerFlag!$A:$A,AE$3,TaxLevel_PerFlag!$B:$B,$Z$10,TaxLevel_PerFlag!$C:$C,"XGBoost",TaxLevel_PerFlag!$D:$D,$AA12) -> 0.16146929 | AF12: =SUMIFS(TaxLevel_PerFlag!$Q:$Q,TaxLevel_PerFlag!$A:$A,AF$3,TaxLevel_PerFlag!$B:$B,$Z$10,TaxLevel_PerFlag!$C:$C,"XGBoost",TaxLevel_PerFlag!$D:$D,$AA12) -> 0.56878149 | AG12: =SUMIFS(TaxLevel_PerFlag!$Q:$Q,TaxLevel_PerFlag!$A:$A,AG$3,TaxLevel_PerFlag!$B:$B,$Z$10,TaxLevel_PerFlag!$C:$C,"XGBoost",TaxLevel_PerFlag!$D:$D,$AA12) -> 0.045013009 | AH12: =SUMIFS(TaxLevel_PerFlag!$Q:$Q,TaxLevel_PerFlag!$A:$A,AH$3,TaxLevel_PerFlag!$B:$B,$Z$10,TaxLevel_PerFlag!$C:$C,"XGBoost",TaxLevel_PerFlag!$D:$D,$AA12) -> 0.095352691 | AI12: =SUMIFS(TaxLevel_PerFlag!$H:$H,TaxLevel_PerFlag!$A:$A,AI$3,TaxLevel_PerFlag!$B:$B,$Z$10,TaxLevel_PerFlag!$C:$C,"XGBoost",TaxLevel_PerFlag!$D:$D,$AA12) -> 0.11100671 | AJ12: =SUMIFS(TaxLevel_PerFlag!$H:$H,TaxLevel_PerFlag!$A:$A,AJ$3,TaxLevel_PerFlag!$B:$B,$Z$10,TaxLevel_PerFlag!$C:$C,"XGBoost",TaxLevel_PerFlag!$D:$D,$AA12) -> 0.12507044 | AK12: =SUMIFS(TaxLevel_PerFlag!$H:$H,TaxLevel_PerFlag!$A:$A,AK$3,TaxLevel_PerFlag!$B:$B,$Z$10,TaxLevel_PerFlag!$C:$C,"XGBoost",TaxLevel_PerFlag!$D:$D,$AA12) -> 0.47601162 | AL12: =SUMIFS(TaxLevel_PerFlag!$H:$H,TaxLevel_PerFlag!$A:$A,AL$3,TaxLevel_PerFlag!$B:$B,$Z$10,TaxLevel_PerFlag!$C:$C,"XGBoost",TaxLevel_PerFlag!$D:$D,$AA12) -> 0.10434477 | AM12: =SUMIFS(TaxLevel_PerFlag!$H:$H,TaxLevel_PerFlag!$A:$A,AM$3,TaxLevel_PerFlag!$B:$B,$Z$10,TaxLevel_PerFlag!$C:$C,"XGBoost",TaxLevel_PerFlag!$D:$D,$AA12) -> 0.10765794 | AN12: =SUMIFS(TaxLevel_PerFlag!$T:$T,TaxLevel_PerFlag!$A:$A,AN$3,TaxLevel_PerFlag!$B:$B,$Z$10,TaxLevel_PerFlag!$C:$C,"XGBoost",TaxLevel_PerFlag!$D:$D,$AA12) -> 0.15342556 | AO12: =SUMIFS(TaxLevel_PerFlag!$T:$T,TaxLevel_PerFlag!$A:$A,AO$3,TaxLevel_PerFlag!$B:$B,$Z$10,TaxLevel_PerFlag!$C:$C,"XGBoost",TaxLevel_PerFlag!$D:$D,$AA12) -> 0.2439443 | AP12: =SUMIFS(TaxLevel_PerFlag!$T:$T,TaxLevel_PerFlag!$A:$A,AP$3,TaxLevel_PerFlag!$B:$B,$Z$10,TaxLevel_PerFlag!$C:$C,"XGBoost",TaxLevel_PerFlag!$D:$D,$AA12) -> 0.58909774 | AQ12: =SUMIFS(TaxLevel_PerFlag!$T:$T,TaxLevel_PerFlag!$A:$A,AQ$3,TaxLevel_PerFlag!$B:$B,$Z$10,TaxLevel_PerFlag!$C:$C,"XGBoost",TaxLevel_PerFlag!$D:$D,$AA12) -> 0.14791825 | AR12: =SUMIFS(TaxLevel_PerFlag!$T:$T,TaxLevel_PerFlag!$A:$A,AR$3,TaxLevel_PerFlag!$B:$B,$Z$10,TaxLevel_PerFlag!$C:$C,"XGBoost",TaxLevel_PerFlag!$D:$D,$AA12) -> 0.17774929
C13: ammonia_toxicity | D13: 26 | E13: 0.1884058 | F13: =_xlfn.MAXIFS(TaxLevel_PerFlag!$Q:$Q,TaxLevel_PerFlag!$A:$A,F$3,TaxLevel_PerFlag!$B:$B,$B$10,TaxLevel_PerFlag!$D:$D,$C13) -> 0.6496494 | G13: =_xlfn.MAXIFS(TaxLevel_PerFlag!$Q:$Q,TaxLevel_PerFlag!$A:$A,G$3,TaxLevel_PerFlag!$B:$B,$B$10,TaxLevel_PerFlag!$D:$D,$C13) -> 0.69051723 | H13: =_xlfn.MAXIFS(TaxLevel_PerFlag!$Q:$Q,TaxLevel_PerFlag!$A:$A,H$3,TaxLevel_PerFlag!$B:$B,$B$10,TaxLevel_PerFlag!$D:$D,$C13) -> 0.6765276 | I13: =_xlfn.MAXIFS(TaxLevel_PerFlag!$Q:$Q,TaxLevel_PerFlag!$A:$A,I$3,TaxLevel_PerFlag!$B:$B,$B$10,TaxLevel_PerFlag!$D:$D,$C13) -> 0.68344736 | J13: =_xlfn.MAXIFS(TaxLevel_PerFlag!$Q:$Q,TaxLevel_PerFlag!$A:$A,J$3,TaxLevel_PerFlag!$B:$B,$B$10,TaxLevel_PerFlag!$D:$D,$C13) -> 0.63886488 | K13: =_xlfn.MAXIFS(TaxLevel_PerFlag!$H:$H,TaxLevel_PerFlag!$A:$A,K$3,TaxLevel_PerFlag!$B:$B,$B$10,TaxLevel_PerFlag!$D:$D,$C13) -> 0.62860735 | L13: =_xlfn.MAXIFS(TaxLevel_PerFlag!$H:$H,TaxLevel_PerFlag!$A:$A,L$3,TaxLevel_PerFlag!$B:$B,$B$10,TaxLevel_PerFlag!$D:$D,$C13) -> 0.7167336 | M13: =_xlfn.MAXIFS(TaxLevel_PerFlag!$H:$H,TaxLevel_PerFlag!$A:$A,M$3,TaxLevel_PerFlag!$B:$B,$B$10,TaxLevel_PerFlag!$D:$D,$C13) -> 0.68593956 | N13: =_xlfn.MAXIFS(TaxLevel_PerFlag!$H:$H,TaxLevel_PerFlag!$A:$A,N$3,TaxLevel_PerFlag!$B:$B,$B$10,TaxLevel_PerFlag!$D:$D,$C13) -> 0.6402158 | O13: =_xlfn.MAXIFS(TaxLevel_PerFlag!$H:$H,TaxLevel_PerFlag!$A:$A,O$3,TaxLevel_PerFlag!$B:$B,$B$10,TaxLevel_PerFlag!$D:$D,$C13) -> 0.60239952 | P13: =_xlfn.MAXIFS(TaxLevel_PerFlag!$T:$T,TaxLevel_PerFlag!$A:$A,P$3,TaxLevel_PerFlag!$B:$B,$B$10,TaxLevel_PerFlag!$D:$D,$C13) -> 0.82776918 | Q13: =_xlfn.MAXIFS(TaxLevel_PerFlag!$T:$T,TaxLevel_PerFlag!$A:$A,Q$3,TaxLevel_PerFlag!$B:$B,$B$10,TaxLevel_PerFlag!$D:$D,$C13) -> 0.84706074 | R13: =_xlfn.MAXIFS(TaxLevel_PerFlag!$T:$T,TaxLevel_PerFlag!$A:$A,R$3,TaxLevel_PerFlag!$B:$B,$B$10,TaxLevel_PerFlag!$D:$D,$C13) -> 0.84546763 | S13: =_xlfn.MAXIFS(TaxLevel_PerFlag!$T:$T,TaxLevel_PerFlag!$A:$A,S$3,TaxLevel_PerFlag!$B:$B,$B$10,TaxLevel_PerFlag!$D:$D,$C13) -> 0.85269483 | T13: =_xlfn.MAXIFS(TaxLevel_PerFlag!$T:$T,TaxLevel_PerFlag!$A:$A,T$3,TaxLevel_PerFlag!$B:$B,$B$10,TaxLevel_PerFlag!$D:$D,$C13) -> 0.79363919 | AA13: ammonia_toxicity | AB13: 26 | AC13: 0.1884058 | AD13: =SUMIFS(TaxLevel_PerFlag!$Q:$Q,TaxLevel_PerFlag!$A:$A,AD$3,TaxLevel_PerFlag!$B:$B,$Z$10,TaxLevel_PerFlag!$C:$C,"XGBoost",TaxLevel_PerFlag!$D:$D,$AA13) -> 0.59016947 | AE13: =SUMIFS(TaxLevel_PerFlag!$Q:$Q,TaxLevel_PerFlag!$A:$A,AE$3,TaxLevel_PerFlag!$B:$B,$Z$10,TaxLevel_PerFlag!$C:$C,"XGBoost",TaxLevel_PerFlag!$D:$D,$AA13) -> 0.54226443 | AF13: =SUMIFS(TaxLevel_PerFlag!$Q:$Q,TaxLevel_PerFlag!$A:$A,AF$3,TaxLevel_PerFlag!$B:$B,$Z$10,TaxLevel_PerFlag!$C:$C,"XGBoost",TaxLevel_PerFlag!$D:$D,$AA13) -> 0.58680827 | AG13: =SUMIFS(TaxLevel_PerFlag!$Q:$Q,TaxLevel_PerFlag!$A:$A,AG$3,TaxLevel_PerFlag!$B:$B,$Z$10,TaxLevel_PerFlag!$C:$C,"XGBoost",TaxLevel_PerFlag!$D:$D,$AA13) -> 0.61549812 | AH13: =SUMIFS(TaxLevel_PerFlag!$Q:$Q,TaxLevel_PerFlag!$A:$A,AH$3,TaxLevel_PerFlag!$B:$B,$Z$10,TaxLevel_PerFlag!$C:$C,"XGBoost",TaxLevel_PerFlag!$D:$D,$AA13) -> 0.59582099 | AI13: =SUMIFS(TaxLevel_PerFlag!$H:$H,TaxLevel_PerFlag!$A:$A,AI$3,TaxLevel_PerFlag!$B:$B,$Z$10,TaxLevel_PerFlag!$C:$C,"XGBoost",TaxLevel_PerFlag!$D:$D,$AA13) -> 0.62860735 | AJ13: =SUMIFS(TaxLevel_PerFlag!$H:$H,TaxLevel_PerFlag!$A:$A,AJ$3,TaxLevel_PerFlag!$B:$B,$Z$10,TaxLevel_PerFlag!$C:$C,"XGBoost",TaxLevel_PerFlag!$D:$D,$AA13) -> 0.7167336 | AK13: =SUMIFS(TaxLevel_PerFlag!$H:$H,TaxLevel_PerFlag!$A:$A,AK$3,TaxLevel_PerFlag!$B:$B,$Z$10,TaxLevel_PerFlag!$C:$C,"XGBoost",TaxLevel_PerFlag!$D:$D,$AA13) -> 0.6408588 | AL13: =SUMIFS(TaxLevel_PerFlag!$H:$H,TaxLevel_PerFlag!$A:$A,AL$3,TaxLevel_PerFlag!$B:$B,$Z$10,TaxLevel_PerFlag!$C:$C,"XGBoost",TaxLevel_PerFlag!$D:$D,$AA13) -> 0.6402158 | AM13: =SUMIFS(TaxLevel_PerFlag!$H:$H,TaxLevel_PerFlag!$A:$A,AM$3,TaxLevel_PerFlag!$B:$B,$Z$10,TaxLevel_PerFlag!$C:$C,"XGBoost",TaxLevel_PerFlag!$D:$D,$AA13) -> 0.57203215 | AN13: =SUMIFS(TaxLevel_PerFlag!$T:$T,TaxLevel_PerFlag!$A:$A,AN$3,TaxLevel_PerFlag!$B:$B,$Z$10,TaxLevel_PerFlag!$C:$C,"XGBoost",TaxLevel_PerFlag!$D:$D,$AA13) -> 0.79379911 | AO13: =SUMIFS(TaxLevel_PerFlag!$T:$T,TaxLevel_PerFlag!$A:$A,AO$3,TaxLevel_PerFlag!$B:$B,$Z$10,TaxLevel_PerFlag!$C:$C,"XGBoost",TaxLevel_PerFlag!$D:$D,$AA13) -> 0.69603432 | AP13: =SUMIFS(TaxLevel_PerFlag!$T:$T,TaxLevel_PerFlag!$A:$A,AP$3,TaxLevel_PerFlag!$B:$B,$Z$10,TaxLevel_PerFlag!$C:$C,"XGBoost",TaxLevel_PerFlag!$D:$D,$AA13) -> 0.76749946 | AQ13: =SUMIFS(TaxLevel_PerFlag!$T:$T,TaxLevel_PerFlag!$A:$A,AQ$3,TaxLevel_PerFlag!$B:$B,$Z$10,TaxLevel_PerFlag!$C:$C,"XGBoost",TaxLevel_PerFlag!$D:$D,$AA13) -> 0.81693981 | AR13: =SUMIFS(TaxLevel_PerFlag!$T:$T,TaxLevel_PerFlag!$A:$A,AR$3,TaxLevel_PerFlag!$B:$B,$Z$10,TaxLevel_PerFlag!$C:$C,"XGBoost",TaxLevel_PerFlag!$D:$D,$AA13) -> 0.77290626
C14: biogas_quality | D14: 7 | E14: 0.050724638 | F14: =_xlfn.MAXIFS(TaxLevel_PerFlag!$Q:$Q,TaxLevel_PerFlag!$A:$A,F$3,TaxLevel_PerFlag!$B:$B,$B$10,TaxLevel_PerFlag!$D:$D,$C14) -> 0.064920691 | G14: =_xlfn.MAXIFS(TaxLevel_PerFlag!$Q:$Q,TaxLevel_PerFlag!$A:$A,G$3,TaxLevel_PerFlag!$B:$B,$B$10,TaxLevel_PerFlag!$D:$D,$C14) -> 0.19159217 | H14: =_xlfn.MAXIFS(TaxLevel_PerFlag!$Q:$Q,TaxLevel_PerFlag!$A:$A,H$3,TaxLevel_PerFlag!$B:$B,$B$10,TaxLevel_PerFlag!$D:$D,$C14) -> 0.25214974 | I14: =_xlfn.MAXIFS(TaxLevel_PerFlag!$Q:$Q,TaxLevel_PerFlag!$A:$A,I$3,TaxLevel_PerFlag!$B:$B,$B$10,TaxLevel_PerFlag!$D:$D,$C14) -> 0.31749024 | J14: =_xlfn.MAXIFS(TaxLevel_PerFlag!$Q:$Q,TaxLevel_PerFlag!$A:$A,J$3,TaxLevel_PerFlag!$B:$B,$B$10,TaxLevel_PerFlag!$D:$D,$C14) -> 0.39139016 | K14: =_xlfn.MAXIFS(TaxLevel_PerFlag!$H:$H,TaxLevel_PerFlag!$A:$A,K$3,TaxLevel_PerFlag!$B:$B,$B$10,TaxLevel_PerFlag!$D:$D,$C14) -> 0.10649359 | L14: =_xlfn.MAXIFS(TaxLevel_PerFlag!$H:$H,TaxLevel_PerFlag!$A:$A,L$3,TaxLevel_PerFlag!$B:$B,$B$10,TaxLevel_PerFlag!$D:$D,$C14) -> 0.27851699 | M14: =_xlfn.MAXIFS(TaxLevel_PerFlag!$H:$H,TaxLevel_PerFlag!$A:$A,M$3,TaxLevel_PerFlag!$B:$B,$B$10,TaxLevel_PerFlag!$D:$D,$C14) -> 0.30891156 | N14: =_xlfn.MAXIFS(TaxLevel_PerFlag!$H:$H,TaxLevel_PerFlag!$A:$A,N$3,TaxLevel_PerFlag!$B:$B,$B$10,TaxLevel_PerFlag!$D:$D,$C14) -> 0.32108844 | O14: =_xlfn.MAXIFS(TaxLevel_PerFlag!$H:$H,TaxLevel_PerFlag!$A:$A,O$3,TaxLevel_PerFlag!$B:$B,$B$10,TaxLevel_PerFlag!$D:$D,$C14) -> 0.35482956 | P14: =_xlfn.MAXIFS(TaxLevel_PerFlag!$T:$T,TaxLevel_PerFlag!$A:$A,P$3,TaxLevel_PerFlag!$B:$B,$B$10,TaxLevel_PerFlag!$D:$D,$C14) -> 0.20833333 | Q14: =_xlfn.MAXIFS(TaxLevel_PerFlag!$T:$T,TaxLevel_PerFlag!$A:$A,Q$3,TaxLevel_PerFlag!$B:$B,$B$10,TaxLevel_PerFlag!$D:$D,$C14) -> 0.30514535 | R14: =_xlfn.MAXIFS(TaxLevel_PerFlag!$T:$T,TaxLevel_PerFlag!$A:$A,R$3,TaxLevel_PerFlag!$B:$B,$B$10,TaxLevel_PerFlag!$D:$D,$C14) -> 0.340885 | S14: =_xlfn.MAXIFS(TaxLevel_PerFlag!$T:$T,TaxLevel_PerFlag!$A:$A,S$3,TaxLevel_PerFlag!$B:$B,$B$10,TaxLevel_PerFlag!$D:$D,$C14) -> 0.38194946 | T14: =_xlfn.MAXIFS(TaxLevel_PerFlag!$T:$T,TaxLevel_PerFlag!$A:$A,T$3,TaxLevel_PerFlag!$B:$B,$B$10,TaxLevel_PerFlag!$D:$D,$C14) -> 0.47449803 | AA14: biogas_quality | AB14: 7 | AC14: 0.050724638 | AD14: =SUMIFS(TaxLevel_PerFlag!$Q:$Q,TaxLevel_PerFlag!$A:$A,AD$3,TaxLevel_PerFlag!$B:$B,$Z$10,TaxLevel_PerFlag!$C:$C,"XGBoost",TaxLevel_PerFlag!$D:$D,$AA14) -> 0.033888659 | AE14: =SUMIFS(TaxLevel_PerFlag!$Q:$Q,TaxLevel_PerFlag!$A:$A,AE$3,TaxLevel_PerFlag!$B:$B,$Z$10,TaxLevel_PerFlag!$C:$C,"XGBoost",TaxLevel_PerFlag!$D:$D,$AA14) -> 0.19159217 | AF14: =SUMIFS(TaxLevel_PerFlag!$Q:$Q,TaxLevel_PerFlag!$A:$A,AF$3,TaxLevel_PerFlag!$B:$B,$Z$10,TaxLevel_PerFlag!$C:$C,"XGBoost",TaxLevel_PerFlag!$D:$D,$AA14) -> 0.10128758 | AG14: =SUMIFS(TaxLevel_PerFlag!$Q:$Q,TaxLevel_PerFlag!$A:$A,AG$3,TaxLevel_PerFlag!$B:$B,$Z$10,TaxLevel_PerFlag!$C:$C,"XGBoost",TaxLevel_PerFlag!$D:$D,$AA14) -> 0.10899697 | AH14: =SUMIFS(TaxLevel_PerFlag!$Q:$Q,TaxLevel_PerFlag!$A:$A,AH$3,TaxLevel_PerFlag!$B:$B,$Z$10,TaxLevel_PerFlag!$C:$C,"XGBoost",TaxLevel_PerFlag!$D:$D,$AA14) -> 0.075373519 | AI14: =SUMIFS(TaxLevel_PerFlag!$H:$H,TaxLevel_PerFlag!$A:$A,AI$3,TaxLevel_PerFlag!$B:$B,$Z$10,TaxLevel_PerFlag!$C:$C,"XGBoost",TaxLevel_PerFlag!$D:$D,$AA14) -> 0.062512513 | AJ14: =SUMIFS(TaxLevel_PerFlag!$H:$H,TaxLevel_PerFlag!$A:$A,AJ$3,TaxLevel_PerFlag!$B:$B,$Z$10,TaxLevel_PerFlag!$C:$C,"XGBoost",TaxLevel_PerFlag!$D:$D,$AA14) -> 0.20184714 | AK14: =SUMIFS(TaxLevel_PerFlag!$H:$H,TaxLevel_PerFlag!$A:$A,AK$3,TaxLevel_PerFlag!$B:$B,$Z$10,TaxLevel_PerFlag!$C:$C,"XGBoost",TaxLevel_PerFlag!$D:$D,$AA14) -> 0.12090753 | AL14: =SUMIFS(TaxLevel_PerFlag!$H:$H,TaxLevel_PerFlag!$A:$A,AL$3,TaxLevel_PerFlag!$B:$B,$Z$10,TaxLevel_PerFlag!$C:$C,"XGBoost",TaxLevel_PerFlag!$D:$D,$AA14) -> 0.166902 | AM14: =SUMIFS(TaxLevel_PerFlag!$H:$H,TaxLevel_PerFlag!$A:$A,AM$3,TaxLevel_PerFlag!$B:$B,$Z$10,TaxLevel_PerFlag!$C:$C,"XGBoost",TaxLevel_PerFlag!$D:$D,$AA14) -> 0.11772906 | AN14: =SUMIFS(TaxLevel_PerFlag!$T:$T,TaxLevel_PerFlag!$A:$A,AN$3,TaxLevel_PerFlag!$B:$B,$Z$10,TaxLevel_PerFlag!$C:$C,"XGBoost",TaxLevel_PerFlag!$D:$D,$AA14) -> 0.2039629 | AO14: =SUMIFS(TaxLevel_PerFlag!$T:$T,TaxLevel_PerFlag!$A:$A,AO$3,TaxLevel_PerFlag!$B:$B,$Z$10,TaxLevel_PerFlag!$C:$C,"XGBoost",TaxLevel_PerFlag!$D:$D,$AA14) -> 0.30514535 | AP14: =SUMIFS(TaxLevel_PerFlag!$T:$T,TaxLevel_PerFlag!$A:$A,AP$3,TaxLevel_PerFlag!$B:$B,$Z$10,TaxLevel_PerFlag!$C:$C,"XGBoost",TaxLevel_PerFlag!$D:$D,$AA14) -> 0.23614021 | AQ14: =SUMIFS(TaxLevel_PerFlag!$T:$T,TaxLevel_PerFlag!$A:$A,AQ$3,TaxLevel_PerFlag!$B:$B,$Z$10,TaxLevel_PerFlag!$C:$C,"XGBoost",TaxLevel_PerFlag!$D:$D,$AA14) -> 0.18576408 | AR14: =SUMIFS(TaxLevel_PerFlag!$T:$T,TaxLevel_PerFlag!$A:$A,AR$3,TaxLevel_PerFlag!$B:$B,$Z$10,TaxLevel_PerFlag!$C:$C,"XGBoost",TaxLevel_PerFlag!$D:$D,$AA14) -> 0.23579278
C15: Macro-avg | F15: =AVERAGE(F10:F14) -> 0.27467521 | G15: =AVERAGE(G10:G14) -> 0.29753562 | H15: =AVERAGE(H10:H14) -> 0.41174185 | I15: =AVERAGE(I10:I14) -> 0.33710956 | J15: =AVERAGE(J10:J14) -> 0.33962103 | K15: =AVERAGE(K10:K14) -> 0.32565561 | L15: =AVERAGE(L10:L14) -> 0.36945306 | M15: =AVERAGE(M10:M14) -> 0.42925398 | ... T15: =AVERAGE(T10:T14) -> 0.46380093 | AA15: Macro-avg | AD15: =AVERAGE(AD10:AD14) -> 0.23878035 | AE15: =AVERAGE(AE10:AE14) -> 0.2552546 | AF15: =AVERAGE(AF10:AF14) -> 0.36362555 | AG15: =AVERAGE(AG10:AG14) -> 0.23326882 | AH15: =AVERAGE(AH10:AH14) -> 0.21771038 | AI15: =AVERAGE(AI10:AI14) -> 0.28526708 | AJ15: =AVERAGE(AJ10:AJ14) -> 0.334612 | AK15: =AVERAGE(AK10:AK14) -> 0.37173002 | ... AR15: =AVERAGE(AR10:AR14) -> 0.35657688
B16: merged | C16: buffer_capacity | D16: 9 | E16: 0.065217391 | F16: =_xlfn.MAXIFS(TaxLevel_PerFlag!$Q:$Q,TaxLevel_PerFlag!$A:$A,F$3,TaxLevel_PerFlag!$B:$B,$B$16,TaxLevel_PerFlag!$D:$D,$C16) -> 0.02219103 | G16: =_xlfn.MAXIFS(TaxLevel_PerFlag!$Q:$Q,TaxLevel_PerFlag!$A:$A,G$3,TaxLevel_PerFlag!$B:$B,$B$16,TaxLevel_PerFlag!$D:$D,$C16) -> 0.16747737 | H16: =_xlfn.MAXIFS(TaxLevel_PerFlag!$Q:$Q,TaxLevel_PerFlag!$A:$A,H$3,TaxLevel_PerFlag!$B:$B,$B$16,TaxLevel_PerFlag!$D:$D,$C16) -> 0.2081668 | I16: =_xlfn.MAXIFS(TaxLevel_PerFlag!$Q:$Q,TaxLevel_PerFlag!$A:$A,I$3,TaxLevel_PerFlag!$B:$B,$B$16,TaxLevel_PerFlag!$D:$D,$C16) -> 0.16938385 | J16: =_xlfn.MAXIFS(TaxLevel_PerFlag!$Q:$Q,TaxLevel_PerFlag!$A:$A,J$3,TaxLevel_PerFlag!$B:$B,$B$16,TaxLevel_PerFlag!$D:$D,$C16) -> 0.16055595 | K16: =_xlfn.MAXIFS(TaxLevel_PerFlag!$H:$H,TaxLevel_PerFlag!$A:$A,K$3,TaxLevel_PerFlag!$B:$B,$B$16,TaxLevel_PerFlag!$D:$D,$C16) -> 0.090168821 | L16: =_xlfn.MAXIFS(TaxLevel_PerFlag!$H:$H,TaxLevel_PerFlag!$A:$A,L$3,TaxLevel_PerFlag!$B:$B,$B$16,TaxLevel_PerFlag!$D:$D,$C16) -> 0.22388642 | M16: =_xlfn.MAXIFS(TaxLevel_PerFlag!$H:$H,TaxLevel_PerFlag!$A:$A,M$3,TaxLevel_PerFlag!$B:$B,$B$16,TaxLevel_PerFlag!$D:$D,$C16) -> 0.28386697 | N16: =_xlfn.MAXIFS(TaxLevel_PerFlag!$H:$H,TaxLevel_PerFlag!$A:$A,N$3,TaxLevel_PerFlag!$B:$B,$B$16,TaxLevel_PerFlag!$D:$D,$C16) -> 0.29031379 | O16: =_xlfn.MAXIFS(TaxLevel_PerFlag!$H:$H,TaxLevel_PerFlag!$A:$A,O$3,TaxLevel_PerFlag!$B:$B,$B$16,TaxLevel_PerFlag!$D:$D,$C16) -> 0.13869465 | P16: =_xlfn.MAXIFS(TaxLevel_PerFlag!$T:$T,TaxLevel_PerFlag!$A:$A,P$3,TaxLevel_PerFlag!$B:$B,$B$16,TaxLevel_PerFlag!$D:$D,$C16) -> 0.24850649 | Q16: =_xlfn.MAXIFS(TaxLevel_PerFlag!$T:$T,TaxLevel_PerFlag!$A:$A,Q$3,TaxLevel_PerFlag!$B:$B,$B$16,TaxLevel_PerFlag!$D:$D,$C16) -> 0.2612902 | R16: =_xlfn.MAXIFS(TaxLevel_PerFlag!$T:$T,TaxLevel_PerFlag!$A:$A,R$3,TaxLevel_PerFlag!$B:$B,$B$16,TaxLevel_PerFlag!$D:$D,$C16) -> 0.30246955 | S16: =_xlfn.MAXIFS(TaxLevel_PerFlag!$T:$T,TaxLevel_PerFlag!$A:$A,S$3,TaxLevel_PerFlag!$B:$B,$B$16,TaxLevel_PerFlag!$D:$D,$C16) -> 0.28910522 | T16: =_xlfn.MAXIFS(TaxLevel_PerFlag!$T:$T,TaxLevel_PerFlag!$A:$A,T$3,TaxLevel_PerFlag!$B:$B,$B$16,TaxLevel_PerFlag!$D:$D,$C16) -> 0.29618276 | Z16: merged | AA16: buffer_capacity | AB16: 9 | AC16: 0.065217391 | AD16: =SUMIFS(TaxLevel_PerFlag!$Q:$Q,TaxLevel_PerFlag!$A:$A,AD$3,TaxLevel_PerFlag!$B:$B,$Z$16,TaxLevel_PerFlag!$C:$C,"XGBoost",TaxLevel_PerFlag!$D:$D,$AA16) -> 0.0071316288 | AE16: =SUMIFS(TaxLevel_PerFlag!$Q:$Q,TaxLevel_PerFlag!$A:$A,AE$3,TaxLevel_PerFlag!$B:$B,$Z$16,TaxLevel_PerFlag!$C:$C,"XGBoost",TaxLevel_PerFlag!$D:$D,$AA16) -> 0.11104297 | AF16: =SUMIFS(TaxLevel_PerFlag!$Q:$Q,TaxLevel_PerFlag!$A:$A,AF$3,TaxLevel_PerFlag!$B:$B,$Z$16,TaxLevel_PerFlag!$C:$C,"XGBoost",TaxLevel_PerFlag!$D:$D,$AA16) -> 0.2081668 | AG16: =SUMIFS(TaxLevel_PerFlag!$Q:$Q,TaxLevel_PerFlag!$A:$A,AG$3,TaxLevel_PerFlag!$B:$B,$Z$16,TaxLevel_PerFlag!$C:$C,"XGBoost",TaxLevel_PerFlag!$D:$D,$AA16) -> 0.16938385 | AH16: =SUMIFS(TaxLevel_PerFlag!$Q:$Q,TaxLevel_PerFlag!$A:$A,AH$3,TaxLevel_PerFlag!$B:$B,$Z$16,TaxLevel_PerFlag!$C:$C,"XGBoost",TaxLevel_PerFlag!$D:$D,$AA16) -> 0.053484994 | AI16: =SUMIFS(TaxLevel_PerFlag!$H:$H,TaxLevel_PerFlag!$A:$A,AI$3,TaxLevel_PerFlag!$B:$B,$Z$16,TaxLevel_PerFlag!$C:$C,"XGBoost",TaxLevel_PerFlag!$D:$D,$AA16) -> 0.08908743 | AJ16: =SUMIFS(TaxLevel_PerFlag!$H:$H,TaxLevel_PerFlag!$A:$A,AJ$3,TaxLevel_PerFlag!$B:$B,$Z$16,TaxLevel_PerFlag!$C:$C,"XGBoost",TaxLevel_PerFlag!$D:$D,$AA16) -> 0.22388642 | AK16: =SUMIFS(TaxLevel_PerFlag!$H:$H,TaxLevel_PerFlag!$A:$A,AK$3,TaxLevel_PerFlag!$B:$B,$Z$16,TaxLevel_PerFlag!$C:$C,"XGBoost",TaxLevel_PerFlag!$D:$D,$AA16) -> 0.28386697 | AL16: =SUMIFS(TaxLevel_PerFlag!$H:$H,TaxLevel_PerFlag!$A:$A,AL$3,TaxLevel_PerFlag!$B:$B,$Z$16,TaxLevel_PerFlag!$C:$C,"XGBoost",TaxLevel_PerFlag!$D:$D,$AA16) -> 0.25533913 | AM16: =SUMIFS(TaxLevel_PerFlag!$H:$H,TaxLevel_PerFlag!$A:$A,AM$3,TaxLevel_PerFlag!$B:$B,$Z$16,TaxLevel_PerFlag!$C:$C,"XGBoost",TaxLevel_PerFlag!$D:$D,$AA16) -> 0.092606123 | AN16: =SUMIFS(TaxLevel_PerFlag!$T:$T,TaxLevel_PerFlag!$A:$A,AN$3,TaxLevel_PerFlag!$B:$B,$Z$16,TaxLevel_PerFlag!$C:$C,"XGBoost",TaxLevel_PerFlag!$D:$D,$AA16) -> 0.16689257 | AO16: =SUMIFS(TaxLevel_PerFlag!$T:$T,TaxLevel_PerFlag!$A:$A,AO$3,TaxLevel_PerFlag!$B:$B,$Z$16,TaxLevel_PerFlag!$C:$C,"XGBoost",TaxLevel_PerFlag!$D:$D,$AA16) -> 0.25697636 | AP16: =SUMIFS(TaxLevel_PerFlag!$T:$T,TaxLevel_PerFlag!$A:$A,AP$3,TaxLevel_PerFlag!$B:$B,$Z$16,TaxLevel_PerFlag!$C:$C,"XGBoost",TaxLevel_PerFlag!$D:$D,$AA16) -> 0.26619362 | AQ16: =SUMIFS(TaxLevel_PerFlag!$T:$T,TaxLevel_PerFlag!$A:$A,AQ$3,TaxLevel_PerFlag!$B:$B,$Z$16,TaxLevel_PerFlag!$C:$C,"XGBoost",TaxLevel_PerFlag!$D:$D,$AA16) -> 0.22242494 | AR16: =SUMIFS(TaxLevel_PerFlag!$T:$T,TaxLevel_PerFlag!$A:$A,AR$3,TaxLevel_PerFlag!$B:$B,$Z$16,TaxLevel_PerFlag!$C:$C,"XGBoost",TaxLevel_PerFlag!$D:$D,$AA16) -> 0.18559751
