Workbook

Sheet Sheet2
A1: Result
A2: 1) TaxLevel
A3: Dataset | B3: Flag | C3: n_pos | D3: prevalence | E3: MCC | J3: AUPR | O3: F2
E4: Phylum | F4: Class | G4: Order | H4: Family | I4: Genus | J4: Phylum | K4: Class | L4: Order | M4: Family | N4: Genus | O4: Phylum | P4: Class | Q4: Order | R4: Family | S4: Genus
A5: ARC | B5: buffer_capacity | C5: 9 | D5: 0.065217391 | E5: -0.11561046 | F5: -0.001990389 | G5: -0.082215456 | H5: 0.023245518 | I5: 0.10923279 | J5: 0.061493256 | K5: 0.079390186 | L5: 0.070087325 | M5: 0.094839488 | N5: 0.11746652 | O5: 0.18514024 | P5: 0.15918056 | Q5: 0.21807405 | R5: 0.22221159 | S5: 0.27722369
B6: acid_base_balance | C6: 20 | D6: 0.14 | E6: 0.1251079 | F6: 0.16507893 | G6: 0.15984085 | H6: 0.17721741 | I6: 0.1184265 | J6: 0.30912546 | K6: 0.28527646 | L6: 0.29751069 | M6: 0.2954604 | N6: 0.2753116 | O6: 0.26945282 | P6: 0.33463072 | Q6: 0.29195855 | R6: 0.40671579 | S6: 0.37723278
B7: acid_accumulation | C7: 4 | D7: 0.03 | E7: 0.033545319 | F7: -0.020264268 | G7: 0.018531783 | H7: 0.18907876 | I7: 0.15110532 | J7: 0.04387025 | K7: 0.032770812 | L7: 0.033856557 | M7: 0.24138277 | N7: 0.12146046 | O7: 0.13018025 | P7: 0.10049034 | Q7: 0.1180865 | R7: 0.27017967 | S7: 0.2352148
B8: ammonia_toxicity | C8: 26 | D8: 0.1884058 | E8: 0.45223521 | F8: 0.45998774 | G8: 0.46218151 | H8: 0.41792079 | I8: 0.47334208 | J8: 0.59791791 | K8: 0.57107802 | L8: 0.56936985 | M8: 0.54890359 | N8: 0.59006766 | O8: 0.56371431 | P8: 0.6135198 | Q8: 0.63249039 | R8: 0.62652937 | S8: 0.68006909
B9: biogas_quality | C9: 7 | D9: 0.050724638 | E9: 0.049277698 | F9: -0.041130405 | G9: -0.035367223 | H9: 0.10422556 | I9: 0.12262499 | J9: 0.057821583 | K9: 0.046661294 | L9: 0.050353838 | M9: 0.084444115 | N9: 0.11805457 | O9: 0.21691574 | P9: 0.15526106 | Q9: 0.18967535 | R9: 0.25832778 | S9: 0.27793144
B10: Macro-avg | E10: =AVERAGE(E6:E9) -> 0.16504153 | F10: =AVERAGE(F6:F9) -> 0.140918 | G10: =AVERAGE(G6:G9) -> 0.15129673 | H10: =AVERAGE(H6:H9) -> 0.22211063 | I10: =AVERAGE(I6:I9) -> 0.21637472 | J10: =AVERAGE(J6:J9) -> 0.2521838 | K10: =AVERAGE(K6:K9) -> 0.23394665 | L10: =AVERAGE(L6:L9) -> 0.23777274 | ... S10: =AVERAGE(S6:S9) -> 0.39261203
A11: BAC | B11: buffer_capacity | C11: 9 | D11: 0.065217391 | E11: 0.075404556 | F11: 0.14152151 | G11: 0.24853563 | H11: 0.20785484 | I11: 0.11093278 | J11: 0.10318351 | K11: 0.26336868 | L11: 0.29836433 | M11: 0.22453617 | N11: 0.13930316 | O11: 0.22410982 | P11: 0.2741009 | Q11: 0.2833865 | R11: 0.27012751 | S11: 0.20878282
B12: acid_base_balance | C12: 20 | D12: 0.14 | E12: 0.39098099 | F12: 0.2394256 | G12: 0.31271477 | H12: 0.28442837 | I12: 0.15053237 | J12: 0.52102532 | K12: 0.36604017 | L12: 0.32250783 | M12: 0.41313067 | N12: 0.27518425 | O12: 0.45630622 | P12: 0.45536352 | Q12: 0.47570618 | R12: 0.34693556 | S12: 0.30433811
B13: acid_accumulation | C13: 4 | D13: 0.03 | E13: 0.10345807 | F13: 0.16146929 | G13: 0.56878149 | H13: 0.18864023 | I13: 0.23061453 | J13: 0.11100671 | K13: 0.12507044 | L13: 0.47601162 | M13: 0.3250534 | N13: 0.31477276 | O13: 0.15342556 | P13: 0.2439443 | Q13: 0.58909774 | R13: 0.21379119 | S13: 0.24166985
B14: ammonia_toxicity | C14: 26 | D14: 0.1884058 | E14: 0.59016947 | F14: 0.54226443 | G14: 0.58680827 | H14: 0.52900518 | I14: 0.46969523 | J14: 0.62860735 | K14: 0.7167336 | L14: 0.6408588 | M14: 0.54247206 | N14: 0.45518907 | O14: 0.79379911 | P14: 0.69603432 | Q14: 0.76749946 | R14: 0.72638855 | S14: 0.67603125
B15: biogas_quality | C15: 7 | D15: 0.050724638 | E15: 0.033888659 | F15: 0.19159217 | G15: 0.10128758 | H15: 0.29606592 | I15: 0.25697955 | J15: 0.062512513 | K15: 0.20184714 | L15: 0.12090753 | M15: 0.30685601 | N15: 0.35482956 | O15: 0.2039629 | P15: 0.30514535 | Q15: 0.23614021 | R15: 0.30879165 | S15: 0.31587757
B16: Macro-avg | E16: =AVERAGE(E12:E15) -> 0.2796243 | F16: =AVERAGE(F12:F15) -> 0.28368787 | G16: =AVERAGE(G12:G15) -> 0.39239803 | H16: =AVERAGE(H12:H15) -> 0.32453492 | I16: =AVERAGE(I12:I15) -> 0.27695542 | J16: =AVERAGE(J12:J15) -> 0.33078797 | K16: =AVERAGE(K12:K15) -> 0.35242284 | L16: =AVERAGE(L12:L15) -> 0.39007145 | ... S16: =AVERAGE(S12:S15) -> 0.3844792
A17: merged | B17: buffer_capacity | C17: 9 | D17: 0.065217391 | E17: -0.022928959 | F17: 0.11104297 | G17: 0.2081668 | H17: 0.1462054 | I17: 0.10817977 | J17: 0.080466329 | K17: 0.22388642 | L17: 0.28386697 | M17: 0.29031379 | N17: 0.134938 | O17: 0.15419839 | P17: 0.25697636 | Q17: 0.26619362 | R17: 0.23560755 | S17: 0.23368366
B18: acid_base_balance | C18: 20 | D18: 0.14 | E18: 0.37489882 | F18: 0.25499828 | G18: 0.26534498 | H18: 0.26365068 | I18: 0.11459664 | J18: 0.4428282 | K18: 0.33047091 | L18: 0.28956776 | M18: 0.36612731 | N18: 0.24454188 | O18: 0.51875783 | P18: 0.41333699 | Q18: 0.42605597 | R18: 0.29370168 | S18: 0.25246204
B19: acid_accumulation | C19: 4 | D19: 0.03 | E19: 0.12874781 | F19: 0.10028394 | G19: 0.5998391 | H19: 0.23352612 | I19: 0.15956732 | J19: 0.11283035 | K19: 0.11767013 | L19: 0.53659149 | M19: 0.32220543 | N19: 0.25000163 | O19: 0.19913209 | P19: 0.18389577 | Q19: 0.62920138 | R19: 0.23388541 | S19: 0.22296157
B20: ammonia_toxicity | C20: 26 | D20: 0.1884058 | E20: 0.65994753 | F20: 0.56752175 | G20: 0.57332093 | H20: 0.5428725 | I20: 0.47163898 | J20: 0.58843232 | K20: 0.71171151 | L20: 0.63834224 | M20: 0.53750188 | N20: 0.4724747 | O20: 0.82981746 | P20: 0.72256782 | Q20: 0.76356147 | R20: 0.75422242 | S20: 0.66673056
B21: biogas_quality | C21: 7 | D21: 0.050724638 | E21: 0.0028856522 | F21: 0.14240259 | G21: 0.01703934 | H21: 0.31921754 | I21: 0.32018091 | J21: 0.058338377 | K21: 0.10071107 | L21: 0.095524987 | M21: 0.39878438 | N21: 0.41246008 | O21: 0.14540284 | P21: 0.28450924 | Q21: 0.18273851 | R21: 0.30896739 | S21: 0.31583269
B22: Macro-avg | E22: =AVERAGE(E18:E21) -> 0.29161995 | F22: =AVERAGE(F18:F21) -> 0.26630164 | G22: =AVERAGE(G18:G21) -> 0.36388609 | H22: =AVERAGE(H18:H21) -> 0.33981671 | I22: =AVERAGE(I18:I21) -> 0.26649596 | J22: =AVERAGE(J18:J21) -> 0.30060731 | K22: =AVERAGE(K18:K21) -> 0.31514091 | L22: =AVERAGE(L18:L21) -> 0.39000662 | ... S22: =AVERAGE(S18:S21) -> 0.36449671
A23: 2) ASV-tree
A24: Dataset | B24: Flag | C24: n_pos | D24: prevalence | E24: MCC | H24: AUPR | K24: F2
E25: DeepPhylo | F25: MetaDR | G25: Phylospec | H25: DeepPhylo | I25: MetaDR | J25: Phylospec | K25: DeepPhylo | L25: MetaDR | M25: Phylospec
A26: ARC | B26: buffer_capacity | C26: 9 | D26: 0.065217391 | E26: -0.11 | F26: -0.07 | G26: -0.11 | H26: 0.06 | I26: 0.06 | J26: 0.06 | K26: 0.17 | L26: 0.15 | M26: 0.2
B27: acid_base_balance | C27: 20 | D27: 0.14 | E27: 0.15 | F27: 0.07 | G27: 0.18 | H27: 0.26 | I27: 0.23 | J27: 0.25 | K27: 0.42 | L27: 0.34 | M27: 0.42
B28: acid_accumulation | C28: 4 | D28: 0.03 | E28: 0.02 | F28: 0 | G28: 0.05 | H28: 0.06 | I28: 0.04 | J28: 0.23 | K28: 0.13 | L28: 0.1 | M28: 0.11
B29: ammonia_toxicity | C29: 26 | D29: 0.1884058 | E29: 0.53 | F29: 0.43 | G29: 0.6 | H29: 0.64 | I29: 0.55629374 | J29: 0.67 | K29: 0.71 | L29: 0.59 | M29: 0.77
B30: biogas_quality | C30: 7 | D30: 0.050724638 | E30: -0.04 | F30: 0.06 | G30: 0.02 | H30: 0.08 | I30: 0.10677999 | J30: 0.06 | K30: 0.12 | L30: 0.2 | M30: 0.16
B31: Macro-avg | E31: =AVERAGE(E27:E30) -> 0.165 | F31: =AVERAGE(F27:F30) -> 0.14 | G31: =AVERAGE(G27:G30) -> 0.2125 | H31: =AVERAGE(H27:H30) -> 0.26 | I31: =AVERAGE(I27:I30) -> 0.23326843 | J31: =AVERAGE(J27:J30) -> 0.3025 | K31: =AVERAGE(K27:K30) -> 0.345 | L31: =AVERAGE(L27:L30) -> 0.3075 | M31: =AVERAGE(M27:M30) -> 0.365
A32: BAC | B32: buffer_capacity | C32: 9 | D32: 0.065217391 | E32: -0.05 | F32: -0.02 | G32: -0.16 | H32: 0.08 | I32: 0.06 | J32: 0.07 | K32: 0.11 | L32: 0.19 | M32: 0.11
B33: acid_base_balance | C33: 20 | D33: 0.14 | E33: 0.28 | F33: 0.27 | G33: 0.24 | H33: 0.33 | I33: 0.28 | J33: 0.44 | K33: 0.48 | L33: 0.48 | M33: 0.4
B34: acid_accumulation | C34: 4 | D34: 0.03 | E34: 0.05 | F34: 0.03 | G34: -0.06 | H34: 0.048920377 | I34: 0.05 | J34: 0.09 | K34: 0.14 | L34: 0.12 | M34: 0.09
B35: ammonia_toxicity | C35: 26 | D35: 0.1884058 | E35: 0.61 | F35: 0.67 | G35: 0.47 | H35: 0.56 | I35: 0.72 | J35: 0.48 | K35: 0.77 | L35: 0.83 | M35: 0.67
B36: biogas_quality | C36: 7 | D36: 0.050724638 | E36: 0.04 | F36: -0.02 | G36: -0.28 | H36: 0.08 | I36: 0.06 | J36: 0.04 | K36: 0.18 | L36: 0.12 | M36: 0.12
B37: Macro-avg | E37: =AVERAGE(E33:E36) -> 0.245 | F37: =AVERAGE(F33:F36) -> 0.2375 | G37: =AVERAGE(G33:G36) -> 0.0925 | H37: =AVERAGE(H33:H36) -> 0.25473009 | I37: =AVERAGE(I33:I36) -> 0.2775 | J37: =AVERAGE(J33:J36) -> 0.2625 | K37: =AVERAGE(K33:K36) -> 0.3925 | L37: =AVERAGE(L33:L36) -> 0.3875 | M37: =AVERAGE(M33:M36) -> 0.32
A38: merged | B38: buffer_capacity | C38: 9 | D38: 0.065217391 | E38: -0.04 | F38: -0.03 | G38: -0.1 | H38: 0.06 | I38: 0.06 | J38: 0.05 | K38: 0.18 | L38: 0.16 | M38: 0.19
B39: acid_base_balance | C39: 20 | D39: 0.14 | E39: 0.35 | F39: 0.18 | G39: 0.3 | H39: 0.36 | I39: 0.28 | J39: 0.43 | K39: 0.56 | L39: 0.41 | M39: 0.47
B40: acid_accumulation | C40: 4 | D40: 0.03 | E40: 0.04 | F40: -0.02 | G40: 0.03 | H40: 0.06 | I40: 0.04 | J40: 0.05 | K40: 0.13 | L40: 0.08 | M40: 0.12
...

Sheet Sheet1
B2: Introduction
B3: 1) Background
B4: - Conventionally, when using genomic datasets as input features, many research made each feature variable independently {a1,a2,b1,b2 …}
B5: - this does not capture the relationship between taxon which can cause information loss
B6: - 미생물 데이터와 같이 계층 구조 (Hierarchy)를 가진 데이터의 표현 학습
B7: - 계층상 가까운 노드는 표현 공간에서도 가깝게 위치해야함
B8: - 혐기소화 미생물 특징: Bacteria, Archaea가 공존/상호의존하며 메탄 생성 메커니즘 이룸. 둘은 계통학적으로는 멀리 떨어져 있지만 이러한 관계로 인해 syntrophic relation을 갖는 bacteria 와 archaea 는 embedding space 에서 고유한 매핑 관계를 형성할 것
B9: - relative abundance 만 넣게 되면 미생물 군집 간의 관계성에 대한 정보 x, hierarchy가 고려되면 space 안에서 비슷한 미생물 군집이 비슷한 원인을 제공하여 결과를 제시
B11: 0) Dataset
B12: - low resolution at species level (~ 80% unclassified), high dimensional => built trees, taxonomic classification at genus level
B13: - same sites sampled under same type of train/test data since they are dependent
B15: type | C15: nwk
B16: single domain | C16: root = BAC/ARC
B17: merged domain | C17: root = domain | D17: -> simply grafting two top tips will give L=2 -> larger distance than actual tips distance (1.35) -> Fragment insertion (SEPP) based on SILVA database
B20: 1) Stability indicator | I20: [result] | L20: imbalanced dataset handling in multi-output classification
B21: Indicator | C21: Parameter / Metric | D21: Normal Range | E21: Warning Flag Threshold | F21: Associated Risk | G21: ref | I21: Positive | J21: negative | L21: 1) loss fucntion: nn.BCEWithLogitsLoss with pos_weight [1],[2]
B22: Acid-Base Balance | C22: pH | D22: 6.8 – 7.8 | E22: < 6.5 or > 8.0 | F22: Souring or free ammonia toxicity | G22: [1] | I22: 21 | J22: 119 | L22: 2) evaluation metrics: mcc, AUPR [3][4]
B23: Buffer Capacity | C23: TVFA/Alk | D23: < 0.30 | E23: >=0.30 | F23: Destruction of bicarbonate buffer | G23: [1],[2] | I23: 9 | J23: 131
B24: Acid Accumulation | C24: HPr/Hac | D24: < 1.0 | E24: (> 1.4 and HPr > 0.1) or HPr >=0.8 | F24: Syntrophic acetogenesis failure | G24: [1],[3] | I24: 4 | J24: 136 | L24: [1] Cui, Y., Jia, M., Lin, T. Y., Song, Y., & Belongie, S. (2019, June). Class-balanced loss based on effective number of samples. In 2019 IEEE/CVF conference on computer vision and pattern recognition (CVPR) (pp. 9260-9269). IEEE.
B25: Ammonia Toxicity | C25: TAN | D25: < 1,500mg/L | E25: > 2,500 mg/L | F25: Methanogenic growth inhibition | G25: [3] | I25: 26 | J25: 114 | L25: [2] Lin, T. Y., Goyal, P., Girshick, R., He, K., & Dollár, P. (2017). Focal loss for dense object detection. In Proceedings of the IEEE international conference on computer vision (pp. 2980-2988).
B26: Biogas Quality | C26: CH4 | D26: 55% - 70% | E26: < 50% | F26: Shift to acidogenesis / gas loss | G26: [1] | I26: 7 | J26: 133 | L26: [3] Richardson, E., Trevizani, R., Greenbaum, J. A., Carter, H., Nielsen, M., & Peters, B. (2024). The receiver operating characteristic curve accurately assesses imbalanced datasets. Patterns, 5(6).
I27: challenge: imbalanced result | L27: [4] Chicco, D., & Jurman, G. (2020). The advantages of the Matthews correlation coefficient (MCC) over F1 score and accuracy in binary classification evaluation. BMC genomics, 21(1), 6.
B28: ref
B29: [1] Boe, K., Batstone, D. J., Steyer, J.-P., & Angelidaki, I. (2010). State indicators for monitoring the anaerobic digestion process. Water Research, 44(20), 5973–5980. https://doi.org/10.1016/j.watres.2010.07.043
B30: [2] Chen, L., Zheng, T., Cao, Q., Zhou, Y., Liu, X., & Li, D. (2020). Early warning of instability during mesophilic anaerobic digestion of chicken manure. Applied Ecology and Environmental Research, 18(1), 331–343. https://doi.org/10.15666/aeer/1801_331343
B31: [3] Singh, A., Schnürer, A., Dolfing, J., & Westerholm, M. (2023). Syntrophic entanglements for propionate and acetate oxidation under thermophilic and high-ammonia conditions. The ISME Journal, 17(11), 1966–1978. https://doi.org/10.1038/s41396-023-01504-y
B33: 2) Benchmark model
I34: Model | J34: Relative abundance | K34: hierarchical topology | L34: branch length | M34: BAC&ARC
B35: 1. Taxlevel (Random Forest, KNN, NNET, XGBoost, GLMNET) relative abundance | I35: ML model | J35: o | K35: x | L35: x | M35: x
B36: 2. hierarchy (tree) + relative abundance | I36: MetaDR | J36: o | K36: o | L36: x | M36: x
B37: 3. hierahcy (tree) + cross-domain + relative abundance | I37: DeepPhylo | J37: o | K37: x | L37: o | M37: x | N37: tree -> distance matrix , PCA embedding
I38: Phylo-spec | J38: o | K38: o | L38: o | M38: x | N38: tree -> keep as live scaffold -> 1D convolution
B39: 60epoch, 10 patience, early stopping
B42: Evaluation metric for multiple output classification
B43: - cross validation (5 folds): small number of samples
B44: - MCC : optimized threshold for each target variable
B45: - F2 score: emphasize the Recall since FN is more 치명적 than FP when assessing digesters' state
B46: - AUPR: threshold independent -> good for baseline since if AUPR 상승중 but MCC 낮음 -> 모델 성능은 좋지만 threshold 잘못 선택된 것; TN 수가 너무 커서 지표를 왜곡시키는 것 방지 since it neglects TN value,
B47: - macro average
B48: - workflow : AUPR 기반 모델 선택 -> 검증 시점 MCC 기반 threshold 최적화 -> test data: multiple evaluation metrics
...

Sheet Comparison
A1: Evaluation metric comparison (source: Sheet2)
A3: MCC
E4: TaxLevel | J4: DeepPhylo | N4: MetaDR | R4: Phylospec
A5: Dataset | B5: Flag | C5: n_pos | D5: prevalence | E5: Phylum | F5: Class | G5: Order | H5: Family | I5: Genus | J5: ASV-tree | K5: Genus-tree | L5: Genus-tree + cross-domain | M5: ASV-tree + cross-domain | N5: ASV-tree | O5: Genus-tree | P5: Genus-tree + cross-domain | Q5: ASV-tree + cross-domain | R5: ASV-tree | S5: Genus-tree | T5: Genus-tree + cross-domain | U5: ASV-tree + cross-domain
A6: ARC | B6: buffer_capacity | C6: =Sheet2!C5 -> 9 | D6: =Sheet2!D5 -> 0.065217391 | E6: =Sheet2!E5 -> -0.11561046 | F6: =Sheet2!F5 -> -0.001990389 | G6: =Sheet2!G5 -> -0.082215456 | H6: =Sheet2!H5 -> 0.023245518 | I6: =Sheet2!I5 -> 0.10923279 | J6: =Sheet2!E26 -> -0.11 | K6: =Sheet2!E47 -> -0.083852988 | N6: =Sheet2!F26 -> -0.07 | O6: =Sheet2!F47 -> -0.039655772 | R6: =Sheet2!G26 -> -0.11 | S6: =Sheet2!G47 -> -0.03
A7: ARC | B7: acid_base_balance | C7: =Sheet2!C6 -> 20 | D7: =Sheet2!D6 -> 0.14 | E7: =Sheet2!E6 -> 0.1251079 | F7: =Sheet2!F6 -> 0.16507893 | G7: =Sheet2!G6 -> 0.15984085 | H7: =Sheet2!H6 -> 0.17721741 | I7: =Sheet2!I6 -> 0.1184265 | J7: =Sheet2!E27 -> 0.15 | K7: =Sheet2!E48 -> 0.11111674 | N7: =Sheet2!F27 -> 0.07 | O7: =Sheet2!F48 -> 0.28011091 | R7: =Sheet2!G27 -> 0.18 | S7: =Sheet2!G48 -> 0.23
A8: ARC | B8: acid_accumulation | C8: =Sheet2!C7 -> 4 | D8: =Sheet2!D7 -> 0.03 | E8: =Sheet2!E7 -> 0.033545319 | F8: =Sheet2!F7 -> -0.020264268 | G8: =Sheet2!G7 -> 0.018531783 | H8: =Sheet2!H7 -> 0.18907876 | I8: =Sheet2!I7 -> 0.15110532 | J8: =Sheet2!E28 -> 0.02 | K8: =Sheet2!E49 -> -0.018766489 | N8: =Sheet2!F28 -> 0 | O8: =Sheet2!F49 -> 0.1623832 | R8: =Sheet2!G28 -> 0.05 | S8: =Sheet2!G49 -> 0.13
A9: ARC | B9: ammonia_toxicity | C9: =Sheet2!C8 -> 26 | D9: =Sheet2!D8 -> 0.1884058 | E9: =Sheet2!E8 -> 0.45223521 | F9: =Sheet2!F8 -> 0.45998774 | G9: =Sheet2!G8 -> 0.46218151 | H9: =Sheet2!H8 -> 0.41792079 | I9: =Sheet2!I8 -> 0.47334208 | J9: =Sheet2!E29 -> 0.53 | K9: =Sheet2!E50 -> 0.074796835 | N9: =Sheet2!F29 -> 0.43 | O9: =Sheet2!F50 -> 0.46595376 | R9: =Sheet2!G29 -> 0.6 | S9: =Sheet2!G50 -> 0.44
A10: ARC | B10: biogas_quality | C10: =Sheet2!C9 -> 7 | D10: =Sheet2!D9 -> 0.050724638 | E10: =Sheet2!E9 -> 0.049277698 | F10: =Sheet2!F9 -> -0.041130405 | G10: =Sheet2!G9 -> -0.035367223 | H10: =Sheet2!H9 -> 0.10422556 | I10: =Sheet2!I9 -> 0.12262499 | J10: =Sheet2!E30 -> -0.04 | K10: =Sheet2!E51 -> -0.00068404397 | N10: =Sheet2!F30 -> 0.06 | O10: =Sheet2!F51 -> 0.10413199 | R10: =Sheet2!G30 -> 0.02 | S10: =Sheet2!G51 -> 0.07
A11: ARC | B11: Macro-avg | E11: =Sheet2!E10 -> 0.16504153 | F11: =Sheet2!F10 -> 0.140918 | G11: =Sheet2!G10 -> 0.15129673 | H11: =Sheet2!H10 -> 0.22211063 | I11: =Sheet2!I10 -> 0.21637472 | J11: =Sheet2!E31 -> 0.165 | K11: =Sheet2!E52 -> 0.041615761 | N11: =Sheet2!F31 -> 0.14 | O11: =Sheet2!F52 -> 0.25314496 | R11: =Sheet2!G31 -> 0.2125 | S11: =Sheet2!G52 -> 0.2175
A12: BAC | B12: buffer_capacity | C12: =Sheet2!C11 -> 9 | D12: =Sheet2!D11 -> 0.065217391 | E12: =Sheet2!E11 -> 0.075404556 | F12: =Sheet2!F11 -> 0.14152151 | G12: =Sheet2!G11 -> 0.24853563 | H12: =Sheet2!H11 -> 0.20785484 | I12: =Sheet2!I11 -> 0.11093278 | J12: =Sheet2!E32 -> -0.05 | K12: =Sheet2!E53 -> -0.038786086 | N12: =Sheet2!F32 -> -0.02 | O12: =Sheet2!F53 -> 0.020037117 | R12: =Sheet2!G32 -> -0.16 | S12: =Sheet2!G53 -> 0.07
A13: BAC | B13: acid_base_balance | C13: =Sheet2!C12 -> 20 | D13: =Sheet2!D12 -> 0.14 | E13: =Sheet2!E12 -> 0.39098099 | F13: =Sheet2!F12 -> 0.2394256 | G13: =Sheet2!G12 -> 0.31271477 | H13: =Sheet2!H12 -> 0.28442837 | I13: =Sheet2!I12 -> 0.15053237 | J13: =Sheet2!E33 -> 0.28 | K13: =Sheet2!E54 -> 0.22045016 | N13: =Sheet2!F33 -> 0.27 | O13: =Sheet2!F54 -> 0.28248574 | R13: =Sheet2!G33 -> 0.24 | S13: =Sheet2!G54 -> 0.34
A14: BAC | B14: acid_accumulation | C14: =Sheet2!C13 -> 4 | D14: =Sheet2!D13 -> 0.03 | E14: =Sheet2!E13 -> 0.10345807 | F14: =Sheet2!F13 -> 0.16146929 | G14: =Sheet2!G13 -> 0.56878149 | H14: =Sheet2!H13 -> 0.18864023 | I14: =Sheet2!I13 -> 0.23061453 | J14: =Sheet2!E34 -> 0.05 | K14: =Sheet2!E55 -> 0.095461363 | N14: =Sheet2!F34 -> 0.03 | O14: =Sheet2!F55 -> 0.051701861 | R14: =Sheet2!G34 -> -0.06 | S14: =Sheet2!G55 -> 0.13
A15: BAC | B15: ammonia_toxicity | C15: =Sheet2!C14 -> 26 | D15: =Sheet2!D14 -> 0.1884058 | E15: =Sheet2!E14 -> 0.59016947 | F15: =Sheet2!F14 -> 0.54226443 | G15: =Sheet2!G14 -> 0.58680827 | H15: =Sheet2!H14 -> 0.52900518 | I15: =Sheet2!I14 -> 0.46969523 | J15: =Sheet2!E35 -> 0.61 | K15: =Sheet2!E56 -> 0.45708668 | N15: =Sheet2!F35 -> 0.67 | O15: =Sheet2!F56 -> 0.64317581 | R15: =Sheet2!G35 -> 0.47 | S15: =Sheet2!G56 -> 0.56
A16: BAC | B16: biogas_quality | C16: =Sheet2!C15 -> 7 | D16: =Sheet2!D15 -> 0.050724638 | E16: =Sheet2!E15 -> 0.033888659 | F16: =Sheet2!F15 -> 0.19159217 | G16: =Sheet2!G15 -> 0.10128758 | H16: =Sheet2!H15 -> 0.29606592 | I16: =Sheet2!I15 -> 0.25697955 | J16: =Sheet2!E36 -> 0.04 | K16: =Sheet2!E57 -> 0.0096090909 | N16: =Sheet2!F36 -> -0.02 | O16: =Sheet2!F57 -> 0.066668166 | R16: =Sheet2!G36 -> -0.28 | S16: =Sheet2!G57 -> 0.05
A17: BAC | B17: Macro-avg | E17: =Sheet2!E16 -> 0.2796243 | F17: =Sheet2!F16 -> 0.28368787 | G17: =Sheet2!G16 -> 0.39239803 | H17: =Sheet2!H16 -> 0.32453492 | I17: =Sheet2!I16 -> 0.27695542 | J17: =Sheet2!E37 -> 0.245 | K17: =Sheet2!E58 -> 0.19565182 | N17: =Sheet2!F37 -> 0.2375 | O17: =Sheet2!F58 -> 0.26100789 | R17: =Sheet2!G37 -> 0.0925 | S17: =Sheet2!G58 -> 0.27
A18: merged | B18: buffer_capacity | C18: =Sheet2!C17 -> 9 | D18: =Sheet2!D17 -> 0.065217391 | E18: =Sheet2!E17 -> -0.022928959 | F18: =Sheet2!F17 -> 0.11104297 | G18: =Sheet2!G17 -> 0.2081668 | H18: =Sheet2!H17 -> 0.1462054 | I18: =Sheet2!I17 -> 0.10817977 | J18: =Sheet2!E38 -> -0.04 | K18: =Sheet2!E59 -> -0.013729353 | L18: =Sheet2!E77 -> -0.01 | M18: =Sheet2!E68 -> -0.0382 | N18: =Sheet2!F38 -> -0.03 | O18: =Sheet2!F59 -> -0.1054096 | P18: =Sheet2!F77 -> -0.0913 | Q18: =Sheet2!F68 -> -0.0434 | R18: =Sheet2!G38 -> -0.1 | S18: =Sheet2!G59 -> -0.04 | T18: =Sheet2!G77 -> 0 | U18: =Sheet2!G68 -> -0.1084
A19: merged | B19: acid_base_balance | C19: =Sheet2!C18 -> 20 | D19: =Sheet2!D18 -> 0.14 | E19: =Sheet2!E18 -> 0.37489882 | F19: =Sheet2!F18 -> 0.25499828 | G19: =Sheet2!G18 -> 0.26534498 | H19: =Sheet2!H18 -> 0.26365068 | I19: =Sheet2!I18 -> 0.11459664 | J19: =Sheet2!E39 -> 0.35 | K19: =Sheet2!E60 -> 0.244939 | L19: =Sheet2!E78 -> 0.27 | M19: =Sheet2!E69 -> 0.2555 | N19: =Sheet2!F39 -> 0.18 | O19: =Sheet2!F60 -> 0.31782198 | P19: =Sheet2!F78 -> 0.2838 | Q19: =Sheet2!F69 -> 0.1458 | R19: =Sheet2!G39 -> 0.3 | S19: =Sheet2!G60 -> 0.32 | T19: =Sheet2!G78 -> 0.35 | U19: =Sheet2!G69 -> 0.311
A20: merged | B20: acid_accumulation | C20: =Sheet2!C19 -> 4 | D20: =Sheet2!D19 -> 0.03 | E20: =Sheet2!E19 -> 0.12874781 | F20: =Sheet2!F19 -> 0.10028394 | G20: =Sheet2!G19 -> 0.5998391 | H20: =Sheet2!H19 -> 0.23352612 | I20: =Sheet2!I19 -> 0.15956732 | J20: =Sheet2!E40 -> 0.04 | K20: =Sheet2!E61 -> 0.09426337 | L20: =Sheet2!E79 -> 0.07 | M20: =Sheet2!E70 -> 0.1241 | N20: =Sheet2!F40 -> -0.02 | O20: =Sheet2!F61 -> 0.15957805 | P20: =Sheet2!F79 -> 0.0232 | Q20: =Sheet2!F70 -> -0.0267 | R20: =Sheet2!G40 -> 0.03 | S20: =Sheet2!G61 -> 0.1 | T20: =Sheet2!G79 -> 0.04 | U20: =Sheet2!G70 -> 0.0132
A21: merged | B21: ammonia_toxicity | C21: =Sheet2!C20 -> 26 | D21: =Sheet2!D20 -> 0.1884058 | E21: =Sheet2!E20 -> 0.65994753 | F21: =Sheet2!F20 -> 0.56752175 | G21: =Sheet2!G20 -> 0.57332093 | H21: =Sheet2!H20 -> 0.5428725 | I21: =Sheet2!I20 -> 0.47163898 | J21: =Sheet2!E41 -> 0.61 | K21: =Sheet2!E62 -> 0.36399765 | L21: =Sheet2!E80 -> 0.57 | M21: =Sheet2!E71 -> 0.5697 | N21: =Sheet2!F41 -> 0.56 | O21: =Sheet2!F62 -> 0.62256924 | P21: =Sheet2!F80 -> 0.5984 | Q21: =Sheet2!F71 -> 0.5309 | R21: =Sheet2!G41 -> 0.6 | S21: =Sheet2!G62 -> 0.47 | T21: =Sheet2!G80 -> 0.5121 | U21: =Sheet2!G71 -> 0.6091
A22: merged | B22: biogas_quality | C22: =Sheet2!C21 -> 7 | D22: =Sheet2!D21 -> 0.050724638 | E22: =Sheet2!E21 -> 0.0028856522 | F22: =Sheet2!F21 -> 0.14240259 | G22: =Sheet2!G21 -> 0.01703934 | H22: =Sheet2!H21 -> 0.31921754 | I22: =Sheet2!I21 -> 0.32018091 | J22: =Sheet2!E42 -> 0.08 | K22: =Sheet2!E63 -> 0.090873257 | L22: =Sheet2!E81 -> 0.08 | M22: =Sheet2!E72 -> 0.1117 | N22: =Sheet2!F42 -> -0.04 | O22: =Sheet2!F63 -> -0.0072669714 | P22: =Sheet2!F81 -> 0.0368 | Q22: =Sheet2!F72 -> -0.042 | R22: =Sheet2!G42 -> -0.17 | S22: =Sheet2!G63 -> 0.07 | T22: =Sheet2!G81 -> 0.03 | U22: =Sheet2!G72 -> -0.1155
A23: merged | B23: Macro-avg | E23: =Sheet2!E22 -> 0.29161995 | F23: =Sheet2!F22 -> 0.26630164 | G23: =Sheet2!G22 -> 0.36388609 | H23: =Sheet2!H22 -> 0.33981671 | I23: =Sheet2!I22 -> 0.26649596 | J23: =Sheet2!E43 -> 0.27 | K23: =Sheet2!E64 -> 0.19851832 | L23: =Sheet2!E82 -> 0.2475 | M23: =Sheet2!E73 -> 0.26525 | N23: =Sheet2!F43 -> 0.17 | O23: =Sheet2!F64 -> 0.27317557 | P23: =Sheet2!F82 -> 0.23555 | Q23: =Sheet2!F73 -> 0.152 | R23: =Sheet2!G43 -> 0.19 | S23: =Sheet2!G64 -> 0.24 | T23: =Sheet2!G82 -> 0.233025 | U23: =Sheet2!G73 -> 0.20445
A25: AUPR
E26: TaxLevel | J26: DeepPhylo | N26: MetaDR | R26: Phylospec
A27: Dataset | B27: Flag | C27: n_pos | D27: prevalence | E27: Phylum | F27: Class | G27: Order | H27: Family | I27: Genus | J27: ASV-tree | K27: Genus-tree | L27: Genus-tree + cross-domain | M27: ASV-tree + cross-domain | N27: ASV-tree | O27: Genus-tree | P27: Genus-tree + cross-domain | Q27: ASV-tree + cross-domain | R27: ASV-tree | S27: Genus-tree | T27: Genus-tree + cross-domain | U27: ASV-tree + cross-domain
A28: ARC | B28: buffer_capacity | C28: =Sheet2!C5 -> 9 | D28: =Sheet2!D5 -> 0.065217391 | E28: =Sheet2!J5 -> 0.061493256 | F28: =Sheet2!K5 -> 0.079390186 | G28: =Sheet2!L5 -> 0.070087325 | H28: =Sheet2!M5 -> 0.094839488 | I28: =Sheet2!N5 -> 0.11746652 | J28: =Sheet2!H26 -> 0.06 | K28: =Sheet2!H47 -> 0.055015568 | N28: =Sheet2!I26 -> 0.06 | O28: =Sheet2!I47 -> 0.069544204 | R28: =Sheet2!J26 -> 0.06 | S28: =Sheet2!J47 -> 0.06
A29: ARC | B29: acid_base_balance | C29: =Sheet2!C6 -> 20 | D29: =Sheet2!D6 -> 0.14 | E29: =Sheet2!J6 -> 0.30912546 | F29: =Sheet2!K6 -> 0.28527646 | G29: =Sheet2!L6 -> 0.29751069 | H29: =Sheet2!M6 -> 0.2954604 | I29: =Sheet2!N6 -> 0.2753116 | J29: =Sheet2!H27 -> 0.26 | K29: =Sheet2!H48 -> 0.19914532 | N29: =Sheet2!I27 -> 0.23 | O29: =Sheet2!I48 -> 0.26310702 | R29: =Sheet2!J27 -> 0.25 | S29: =Sheet2!J48 -> 0.25
A30: ARC | B30: acid_accumulation | C30: =Sheet2!C7 -> 4 | D30: =Sheet2!D7 -> 0.03 | E30: =Sheet2!J7 -> 0.04387025 | F30: =Sheet2!K7 -> 0.032770812 | G30: =Sheet2!L7 -> 0.033856557 | H30: =Sheet2!M7 -> 0.24138277 | I30: =Sheet2!N7 -> 0.12146046 | J30: =Sheet2!H28 -> 0.06 | K30: =Sheet2!H49 -> 0.0290697 | N30: =Sheet2!I28 -> 0.04 | O30: =Sheet2!I49 -> 0.090836132 | R30: =Sheet2!J28 -> 0.23 | S30: =Sheet2!J49 -> 0.09
A31: ARC | B31: ammonia_toxicity | C31: =Sheet2!C8 -> 26 | D31: =Sheet2!D8 -> 0.1884058 | E31: =Sheet2!J8 -> 0.59791791 | F31: =Sheet2!K8 -> 0.57107802 | G31: =Sheet2!L8 -> 0.56936985 | H31: =Sheet2!M8 -> 0.54890359 | I31: =Sheet2!N8 -> 0.59006766 | J31: =Sheet2!H29 -> 0.64 | K31: =Sheet2!H50 -> 0.24415475 | N31: =Sheet2!I29 -> 0.55629374 | O31: =Sheet2!I50 -> 0.55629374 | R31: =Sheet2!J29 -> 0.67 | S31: =Sheet2!J50 -> 0.49
A32: ARC | B32: biogas_quality | C32: =Sheet2!C9 -> 7 | D32: =Sheet2!D9 -> 0.050724638 | E32: =Sheet2!J9 -> 0.057821583 | F32: =Sheet2!K9 -> 0.046661294 | G32: =Sheet2!L9 -> 0.050353838 | H32: =Sheet2!M9 -> 0.084444115 | I32: =Sheet2!N9 -> 0.11805457 | J32: =Sheet2!H30 -> 0.08 | K32: =Sheet2!H51 -> 0.049622288 | N32: =Sheet2!I30 -> 0.10677999 | O32: =Sheet2!I51 -> 0.10677999 | R32: =Sheet2!J30 -> 0.06 | S32: =Sheet2!J51 -> 0.07
A33: ARC | B33: Macro-avg | E33: =Sheet2!J10 -> 0.2521838 | F33: =Sheet2!K10 -> 0.23394665 | G33: =Sheet2!L10 -> 0.23777274 | H33: =Sheet2!M10 -> 0.29254772 | I33: =Sheet2!N10 -> 0.27622357 | J33: =Sheet2!H31 -> 0.26 | K33: =Sheet2!H52 -> 0.13049801 | N33: =Sheet2!I31 -> 0.23326843 | O33: =Sheet2!I52 -> 0.25425422 | R33: =Sheet2!J31 -> 0.3025 | S33: =Sheet2!J52 -> 0.225
A34: BAC | B34: buffer_capacity | C34: =Sheet2!C11 -> 9 | D34: =Sheet2!D11 -> 0.065217391 | E34: =Sheet2!J11 -> 0.10318351 | F34: =Sheet2!K11 -> 0.26336868 | G34: =Sheet2!L11 -> 0.29836433 | H34: =Sheet2!M11 -> 0.22453617 | I34: =Sheet2!N11 -> 0.13930316 | J34: =Sheet2!H32 -> 0.08 | K34: =Sheet2!H53 -> 0.067531353 | N34: =Sheet2!I32 -> 0.06 | O34: =Sheet2!I53 -> 0.079371599 | R34: =Sheet2!J32 -> 0.07 | S34: =Sheet2!J53 -> 0.09
A35: BAC | B35: acid_base_balance | C35: =Sheet2!C12 -> 20 | D35: =Sheet2!D12 -> 0.14 | E35: =Sheet2!J12 -> 0.52102532 | F35: =Sheet2!K12 -> 0.36604017 | G35: =Sheet2!L12 -> 0.32250783 | H35: =Sheet2!M12 -> 0.41313067 | I35: =Sheet2!N12 -> 0.27518425 | J35: =Sheet2!H33 -> 0.33 | K35: =Sheet2!H54 -> 0.31113045 | N35: =Sheet2!I33 -> 0.28 | O35: =Sheet2!I54 -> 0.35132294 | R35: =Sheet2!J33 -> 0.44 | S35: =Sheet2!J54 -> 0.49
A36: BAC | B36: acid_accumulation | C36: =Sheet2!C13 -> 4 | D36: =Sheet2!D13 -> 0.03 | E36: =Sheet2!J13 -> 0.11100671 | F36: =Sheet2!K13 -> 0.12507044 | G36: =Sheet2!L13 -> 0.47601162 | H36: =Sheet2!M13 -> 0.3250534 | I36: =Sheet2!N13 -> 0.31477276 | J36: =Sheet2!H34 -> 0.048920377 | K36: =Sheet2!H55 -> 0.048920377 | N36: =Sheet2!I34 -> 0.05 | O36: =Sheet2!I55 -> 0.068876451 | R36: =Sheet2!J34 -> 0.09 | S36: =Sheet2!J55 -> 0.21
A37: BAC | B37: ammonia_toxicity | C37: =Sheet2!C14 -> 26 | D37: =Sheet2!D14 -> 0.1884058 | E37: =Sheet2!J14 -> 0.62860735 | F37: =Sheet2!K14 -> 0.7167336 | G37: =Sheet2!L14 -> 0.6408588 | H37: =Sheet2!M14 -> 0.54247206 | I37: =Sheet2!N14 -> 0.45518907 | J37: =Sheet2!H35 -> 0.56 | K37: =Sheet2!H56 -> 0.40498547 | N37: =Sheet2!I35 -> 0.72 | O37: =Sheet2!I56 -> 0.60006945 | R37: =Sheet2!J35 -> 0.48 | S37: =Sheet2!J56 -> 0.52
A38: BAC | B38: biogas_quality | C38: =Sheet2!C15 -> 7 | D38: =Sheet2!D15 -> 0.050724638 | E38: =Sheet2!J15 -> 0.062512513 | F38: =Sheet2!K15 -> 0.20184714 | G38: =Sheet2!L15 -> 0.12090753 | H38: =Sheet2!M15 -> 0.30685601 | I38: =Sheet2!N15 -> 0.35482956 | J38: =Sheet2!H36 -> 0.08 | K38: =Sheet2!H57 -> 0.069311934 | N38: =Sheet2!I36 -> 0.06 | O38: =Sheet2!I57 -> 0.079542316 | R38: =Sheet2!J36 -> 0.04 | S38: =Sheet2!J57 -> 0.08
A39: BAC | B39: Macro-avg | E39: =Sheet2!J16 -> 0.33078797 | F39: =Sheet2!K16 -> 0.35242284 | G39: =Sheet2!L16 -> 0.39007145 | H39: =Sheet2!M16 -> 0.39687803 | I39: =Sheet2!N16 -> 0.34999391 | J39: =Sheet2!H37 -> 0.25473009 | K39: =Sheet2!H58 -> 0.20858706 | N39: =Sheet2!I37 -> 0.2775 | O39: =Sheet2!I58 -> 0.27495279 | R39: =Sheet2!J37 -> 0.2625 | S39: =Sheet2!J58 -> 0.325
A40: merged | B40: buffer_capacity | C40: =Sheet2!C17 -> 9 | D40: =Sheet2!D17 -> 0.065217391 | E40: =Sheet2!J17 -> 0.080466329 | F40: =Sheet2!K17 -> 0.22388642 | G40: =Sheet2!L17 -> 0.28386697 | H40: =Sheet2!M17 -> 0.29031379 | I40: =Sheet2!N17 -> 0.134938 | J40: =Sheet2!H38 -> 0.06 | K40: =Sheet2!H59 -> 0.10620651 | L40: =Sheet2!H77 -> 0.11 | M40: =Sheet2!H68 -> 0.0708 | N40: =Sheet2!I38 -> 0.06 | O40: =Sheet2!I59 -> 0.053302311 | P40: =Sheet2!I77 -> 0.0573 | Q40: =Sheet2!I68 -> 0.0731 | R40: =Sheet2!J38 -> 0.05 | S40: =Sheet2!J59 -> 0.06 | T40: =Sheet2!J77 -> 0.0565 | U40: =Sheet2!J68 -> 0.0773
A41: merged | B41: acid_base_balance | C41: =Sheet2!C18 -> 20 | D41: =Sheet2!D18 -> 0.14 | E41: =Sheet2!J18 -> 0.4428282 | F41: =Sheet2!K18 -> 0.33047091 | G41: =Sheet2!L18 -> 0.28956776 | H41: =Sheet2!M18 -> 0.36612731 | I41: =Sheet2!N18 -> 0.24454188 | J41: =Sheet2!H39 -> 0.36 | K41: =Sheet2!H60 -> 0.2758899 | L41: =Sheet2!H78 -> 0.29 | M41: =Sheet2!H69 -> 0.3119 | N41: =Sheet2!I39 -> 0.28 | O41: =Sheet2!I60 -> 0.32762517 | P41: =Sheet2!I78 -> 0.3175 | Q41: =Sheet2!I69 -> 0.253 | R41: =Sheet2!J39 -> 0.43 | S41: =Sheet2!J60 -> 0.4 | T41: =Sheet2!J78 -> 0.39 | U41: =Sheet2!J69 -> 0.4619
A42: merged | B42: acid_accumulation | C42: =Sheet2!C19 -> 4 | D42: =Sheet2!D19 -> 0.03 | E42: =Sheet2!J19 -> 0.11283035 | F42: =Sheet2!K19 -> 0.11767013 | G42: =Sheet2!L19 -> 0.53659149 | H42: =Sheet2!M19 -> 0.32220543 | I42: =Sheet2!N19 -> 0.25000163 | J42: =Sheet2!H40 -> 0.06 | K42: =Sheet2!H61 -> 0.13327345 | L42: =Sheet2!H79 -> 0.14 | M42: =Sheet2!H70 -> 0.0886 | N42: =Sheet2!I40 -> 0.04 | O42: =Sheet2!I61 -> 0.060043342 | P42: =Sheet2!I79 -> 0.0441 | Q42: =Sheet2!I70 -> 0.0387 | R42: =Sheet2!J40 -> 0.05 | S42: =Sheet2!J61 -> 0.16 | T42: =Sheet2!J79 -> 0.04 | U42: =Sheet2!J70 -> 0.0532
...

Sheet data set 별 정리
B2: MCC | E2: TaxLevel | J2: DeepPhylo | N2: MetaDR | P2: Phylospec
A3: dataset | B3: flag | E3: Phylum | F3: Class | G3: Order | H3: Family | I3: Genus | J3: ASV-tree | K3: Genus-tree | L3: Genus-tree + cross-domain | M3: ASV-tree + cross-domain | N3: ASV-tree | O3: Genus-tree | P3: ASV-tree | Q3: Genus-tree | T3: DeepPhylo | U3: ARC | V3: BAC | W3: merged | X3: cross domain | Z3: MetaDR | AA3: ARC | AB3: BAC | AC3: merged | AE3: Phylospec | AF3: ARC | AG3: BAC | AH3: merged
A4: ARC | B4: acid_base_balance | C4: 20 | D4: 0.14 | E4: 0.1251079 | F4: 0.16507893 | G4: 0.15984085 | H4: 0.17721741 | I4: 0.1184265 | J4: 0.15 | K4: 0.11111674 | N4: 0.07 | O4: 0.28011091 | P4: 0.18 | Q4: 0.23 | T4: acid_base_balance | U4: 0.15 | V4: 0.28 | W4: 0.35 | X4: 0.2555 | Z4: acid_base_balance | AA4: 0.28011091 | AB4: 0.28248574 | AC4: 0.31782198 | AE4: acid_base_balance | AF4: 0.23 | AG4: 0.34 | AH4: 0.32
A5: ARC | B5: acid_accumulation | C5: 4 | D5: 0.03 | E5: 0.033545319 | F5: -0.020264268 | G5: 0.018531783 | H5: 0.18907876 | I5: 0.15110532 | J5: 0.02 | K5: -0.018766489 | N5: 0 | O5: 0.1623832 | P5: 0.05 | Q5: 0.13 | T5: acid_accumulation | U5: 0.02 | V5: 0.05 | W5: 0.04 | X5: 0.1241 | Z5: acid_accumulation | AA5: 0.1623832 | AB5: 0.051701861 | AC5: 0.15957805 | AE5: acid_accumulation | AF5: 0.13 | AG5: 0.13 | AH5: 0.1
A6: ARC | B6: ammonia_toxicity | C6: 26 | D6: 0.1884058 | E6: 0.45223521 | F6: 0.45998774 | G6: 0.46218151 | H6: 0.41792079 | I6: 0.47334208 | J6: 0.53 | K6: 0.074796835 | N6: 0.43 | O6: 0.46595376 | P6: 0.6 | Q6: 0.44 | T6: ammonia_toxicity | U6: 0.53 | V6: 0.61 | W6: 0.61 | X6: 0.5697 | Z6: ammonia_toxicity | AA6: 0.46595376 | AB6: 0.64317581 | AC6: 0.62256924 | AE6: ammonia_toxicity | AF6: 0.44 | AG6: 0.56 | AH6: 0.47
A10: BAC | B10: acid_base_balance | C10: 20 | D10: 0.14 | E10: 0.39098099 | F10: 0.2394256 | G10: 0.31271477 | H10: 0.28442837 | I10: 0.15053237 | J10: 0.28 | K10: 0.22045016 | N10: 0.27 | O10: 0.28248574 | P10: 0.24 | Q10: 0.34
A11: BAC | B11: acid_accumulation | C11: 4 | D11: 0.03 | E11: 0.10345807 | F11: 0.16146929 | G11: 0.56878149 | H11: 0.18864023 | I11: 0.23061453 | J11: 0.05 | K11: 0.095461363 | N11: 0.03 | O11: 0.051701861 | P11: -0.06 | Q11: 0.13
A12: BAC | B12: ammonia_toxicity | C12: 26 | D12: 0.1884058 | E12: 0.59016947 | F12: 0.54226443 | G12: 0.58680827 | H12: 0.52900518 | I12: 0.46969523 | J12: 0.61 | K12: 0.45708668 | N12: 0.67 | O12: 0.64317581 | P12: 0.47 | Q12: 0.56
A16: merged | B16: acid_base_balance | C16: 20 | D16: 0.14 | E16: 0.37489882 | F16: 0.25499828 | G16: 0.26534498 | H16: 0.26365068 | I16: 0.11459664 | J16: 0.35 | K16: 0.244939 | L16: 0.27 | M16: 0.2555 | N16: 0.18 | O16: 0.31782198 | P16: 0.3 | Q16: 0.32
A17: merged | B17: acid_accumulation | C17: 4 | D17: 0.03 | E17: 0.12874781 | F17: 0.10028394 | G17: 0.5998391 | H17: 0.23352612 | I17: 0.15956732 | J17: 0.04 | K17: 0.09426337 | L17: 0.07 | M17: 0.1241 | N17: -0.02 | O17: 0.15957805 | P17: 0.03 | Q17: 0.1
A18: merged | B18: ammonia_toxicity | C18: 26 | D18: 0.1884058 | E18: 0.65994753 | F18: 0.56752175 | G18: 0.57332093 | H18: 0.5428725 | I18: 0.47163898 | J18: 0.61 | K18: 0.36399765 | L18: 0.57 | M18: 0.5697 | N18: 0.56 | O18: 0.62256924 | P18: 0.6 | Q18: 0.47
B22: AUPR | E22: TaxLevel | J22: DeepPhylo | N22: MetaDR | P22: Phylospec
E23: Phylum | F23: Class | G23: Order | H23: Family | I23: Genus | J23: ASV-tree | K23: Genus-tree | L23: Genus-tree + cross-domain | M23: ASV-tree + cross-domain | N23: ASV-tree | O23: Genus-tree | P23: ASV-tree | Q23: Genus-tree
A24: ARC | B24: acid_base_balance | C24: 20 | D24: 0.14 | E24: 0.30912546 | F24: 0.28527646 | G24: 0.29751069 | H24: 0.2954604 | I24: 0.2753116 | J24: 0.26 | K24: 0.19914532 | N24: 0.23 | O24: 0.26310702 | P24: 0.25 | Q24: 0.25
A25: ARC | B25: acid_accumulation | C25: 4 | D25: 0.03 | E25: 0.04387025 | F25: 0.032770812 | G25: 0.033856557 | H25: 0.24138277 | I25: 0.12146046 | J25: 0.06 | K25: 0.0290697 | N25: 0.04 | O25: 0.090836132 | P25: 0.23 | Q25: 0.09
A26: ARC | B26: ammonia_toxicity | C26: 26 | D26: 0.1884058 | E26: 0.59791791 | F26: 0.57107802 | G26: 0.56936985 | H26: 0.54890359 | I26: 0.59006766 | J26: 0.64 | K26: 0.24415475 | N26: 0.55629374 | O26: 0.55629374 | P26: 0.67 | Q26: 0.49
A30: BAC | B30: acid_base_balance | C30: 20 | D30: 0.14 | E30: 0.52102532 | F30: 0.36604017 | G30: 0.32250783 | H30: 0.41313067 | I30: 0.27518425 | J30: 0.33 | K30: 0.31113045 | N30: 0.28 | O30: 0.35132294 | P30: 0.44 | Q30: 0.49
A31: BAC | B31: acid_accumulation | C31: 4 | D31: 0.03 | E31: 0.11100671 | F31: 0.12507044 | G31: 0.47601162 | H31: 0.3250534 | I31: 0.31477276 | J31: 0.048920377 | K31: 0.048920377 | N31: 0.05 | O31: 0.068876451 | P31: 0.09 | Q31: 0.21
A32: BAC | B32: ammonia_toxicity | C32: 26 | D32: 0.1884058 | E32: 0.62860735 | F32: 0.7167336 | G32: 0.6408588 | H32: 0.54247206 | I32: 0.45518907 | J32: 0.56 | K32: 0.40498547 | N32: 0.72 | O32: 0.60006945 | P32: 0.48 | Q32: 0.52
A36: merged | B36: acid_base_balance | C36: 20 | D36: 0.14 | E36: 0.4428282 | F36: 0.33047091 | G36: 0.28956776 | H36: 0.36612731 | I36: 0.24454188 | J36: 0.36 | K36: 0.2758899 | L36: 0.29 | M36: 0.3119 | N36: 0.28 | O36: 0.32762517 | P36: 0.43 | Q36: 0.4
A37: merged | B37: acid_accumulation | C37: 4 | D37: 0.03 | E37: 0.11283035 | F37: 0.11767013 | G37: 0.53659149 | H37: 0.32220543 | I37: 0.25000163 | J37: 0.06 | K37: 0.13327345 | L37: 0.14 | M37: 0.0886 | N37: 0.04 | O37: 0.060043342 | P37: 0.05 | Q37: 0.16
A38: merged | B38: ammonia_toxicity | C38: 26 | D38: 0.1884058 | E38: 0.58843232 | F38: 0.71171151 | G38: 0.63834224 | H38: 0.53750188 | I38: 0.4724747 | J38: 0.66 | K38: 0.43211204 | L38: 0.57 | M38: 0.5965 | N38: 0.62 | O38: 0.56640214 | P38: 0.53 | Q38: 0.5
B43: F2 | E43: TaxLevel | J43: DeepPhylo | N43: MetaDR | P43: Phylospec
E44: Phylum | F44: Class | G44: Order | H44: Family | I44: Genus | J44: ASV-tree | K44: Genus-tree | L44: Genus-tree + cross-domain | M44: ASV-tree + cross-domain | N44: ASV-tree | O44: Genus-tree | P44: ASV-tree | Q44: Genus-tree
A45: ARC | B45: acid_base_balance | C45: 20 | D45: 0.14 | E45: 0.26945282 | F45: 0.33463072 | G45: 0.29195855 | H45: 0.40671579 | I45: 0.37723278 | J45: 0.42 | K45: 0.33115727 | N45: 0.34 | O45: 0.52966107 | P45: 0.42 | Q45: 0.46
A46: ARC | B46: acid_accumulation | C46: 4 | D46: 0.03 | E46: 0.13018025 | F46: 0.10049034 | G46: 0.1180865 | H46: 0.27017967 | I46: 0.2352148 | J46: 0.13 | K46: 0.088391463 | N46: 0.1 | O46: 0.23627994 | P46: 0.11 | Q46: 0.22
A47: ARC | B47: ammonia_toxicity | C47: 26 | D47: 0.1884058 | E47: 0.56371431 | F47: 0.6135198 | G47: 0.63249039 | H47: 0.62652937 | I47: 0.68006909 | J47: 0.71 | K47: 0.32400065 | N47: 0.59 | O47: 0.69562618 | P47: 0.77 | Q47: 0.66
A51: BAC | B51: acid_base_balance | C51: 20 | D51: 0.14 | E51: 0.45630622 | F51: 0.45536352 | G51: 0.47570618 | H51: 0.34693556 | I51: 0.30433811 | J51: 0.48 | K51: 0.42475531 | N51: 0.48 | O51: 0.50416698 | P51: 0.4 | Q51: 0.5
A52: BAC | B52: acid_accumulation | C52: 4 | D52: 0.03 | E52: 0.15342556 | F52: 0.2439443 | G52: 0.58909774 | H52: 0.21379119 | I52: 0.24166985 | J52: 0.14 | K52: 0.17273735 | N52: 0.12 | O52: 0.13503095 | P52: 0.09 | Q52: 0.19
A53: BAC | B53: ammonia_toxicity | C53: 26 | D53: 0.1884058 | E53: 0.79379911 | F53: 0.69603432 | G53: 0.76749946 | H53: 0.72638855 | I53: 0.67603125 | J53: 0.77 | K53: 0.72180247 | N53: 0.83 | O53: 0.80882128 | P53: 0.67 | Q53: 0.78
A57: merged | B57: acid_base_balance | C57: 20 | D57: 0.14 | E57: 0.51875783 | F57: 0.41333699 | G57: 0.42605597 | H57: 0.29370168 | I57: 0.25246204 | J57: 0.56 | K57: 0.50816554 | L57: 0.5 | M57: 0.4614 | N57: 0.41 | O57: 0.57748119 | P57: 0.47 | Q57: 0.54
A58: merged | B58: acid_accumulation | C58: 4 | D58: 0.03 | E58: 0.19913209 | F58: 0.18389577 | G58: 0.62920138 | H58: 0.23388541 | I58: 0.22296157 | J58: 0.13 | K58: 0.16534392 | L58: 0.15 | M58: 0.2096 | N58: 0.08 | O58: 0.22257602 | P58: 0.12 | Q58: 0.17
A59: merged | B59: ammonia_toxicity | C59: 26 | D59: 0.1884058 | E59: 0.82981746 | F59: 0.72256782 | G59: 0.76356147 | H59: 0.75422242 | I59: 0.66673056 | J59: 0.79 | K59: 0.58761899 | L59: 0.77 | M59: 0.7643 | N59: 0.72 | O59: 0.81184608 | P59: 0.81 | Q59: 0.67

Sheet Flag 별 정리
AF1: Fig 1 — Genus-tree vs ASV-tree by model (avg over the 3 flags)
AF2: MCC
AF3: Model / Dataset | AG3: ASV-tree | AH3: Genus-tree | AI3: Δ (Genus − ASV)
E4: TaxLevel | J4: DeepPhylo | N4: MetaDR | R4: Phylospec | X4: DeepPhylo | Y4: DeepPhylo | AF4: DeepPhylo – ARC | AG4: =AVERAGE(J6,J12,J18) -> 0.23333333 | AH4: =AVERAGE(K6,K12,K18) -> 0.055715696 | AI4: =AH4-AG4 -> -0.17761764
E5: Phylum | F5: Class | G5: Order | H5: Family | I5: Genus | J5: ASV-tree | K5: Genus-tree | L5: Genus-tree + cross-domain | M5: ASV-tree + cross-domain | N5: ASV-tree | O5: Genus-tree | P5: Genus-tree + cross-domain | Q5: ASV-tree + cross-domain | R5: ASV-tree | S5: Genus-tree | T5: Genus-tree + cross-domain | U5: ASV-tree + cross-domain | AF5: DeepPhylo – BAC | AG5: =AVERAGE(J7,J13,J19) -> 0.31333333 | AH5: =AVERAGE(K7,K13,K19) -> 0.25766607 | AI5: =AH5-AG5 -> -0.055667266
A6: ARC | B6: acid_base_balance | C6: 20 | D6: 0.14 | E6: 0.1251079 | F6: 0.16507893 | G6: 0.15984085 | H6: 0.17721741 | I6: 0.1184265 | J6: 0.15 | K6: 0.11111674 | N6: 0.07 | O6: 0.28011091 | R6: 0.18 | S6: 0.23 | W6: ARC | X6: 0.15 | Y6: 0.11111674 | AF6: DeepPhylo – merged | AG6: =AVERAGE(J8,J14,J20) -> 0.33333333 | AH6: =AVERAGE(K8,K14,K20) -> 0.23440001 | AI6: =AH6-AG6 -> -0.098933325
A7: BAC | B7: acid_base_balance | C7: =Sheet2!C6 -> 20 | D7: =Sheet2!D6 -> 0.14 | E7: 0.39098099 | F7: 0.2394256 | G7: 0.31271477 | H7: 0.28442837 | I7: 0.15053237 | J7: 0.28 | K7: 0.22045016 | N7: 0.27 | O7: 0.28248574 | R7: 0.24 | S7: 0.34 | W7: BAC | X7: 0.28 | Y7: 0.22045016 | AF7: MetaDR – ARC | AG7: =AVERAGE(N6,N12,N18) -> 0.16666667 | AH7: =AVERAGE(O6,O12,O18) -> 0.30281596 | AI7: =AH7-AG7 -> 0.13614929
A8: merged | B8: acid_base_balance | C8: 20 | D8: 0.14 | E8: 0.37489882 | F8: 0.25499828 | G8: 0.26534498 | H8: 0.26365068 | I8: 0.11459664 | J8: 0.35 | K8: 0.244939 | L8: 0.27 | M8: 0.2555 | N8: 0.18 | O8: 0.31782198 | P8: 0.2838 | Q8: 0.1458 | R8: 0.3 | S8: 0.32 | T8: 0.35 | U8: 0.311 | AF8: MetaDR – BAC | AG8: =AVERAGE(N7,N13,N19) -> 0.32333333 | AH8: =AVERAGE(O7,O13,O19) -> 0.3257878 | AI8: =AH8-AG8 -> 0.0024544691
AF9: MetaDR – merged | AG9: =AVERAGE(N8,N14,N20) -> 0.24 | AH9: =AVERAGE(O8,O14,O20) -> 0.36665642 | AI9: =AH9-AG9 -> 0.12665642
X10: acid_base_balance | Z10: acid_accumulation | AB10: ammonia_toxicity | AF10: Phylospec – ARC | AG10: =AVERAGE(R6,R12,R18) -> 0.27666667 | AH10: =AVERAGE(S6,S12,S18) -> 0.26666667 | AI10: =AH10-AG10 -> -0.01
X11: ASV | Y11: Genus | Z11: ASV | AA11: Genus | AB11: ASV | AC11: Genus | AF11: Phylospec – BAC | AG11: =AVERAGE(R7,R13,R19) -> 0.21666667 | AH11: =AVERAGE(S7,S13,S19) -> 0.34333333 | AI11: =AH11-AG11 -> 0.12666667
A12: ARC | B12: acid_accumulation | C12: 4 | D12: 0.03 | E12: 0.033545319 | F12: -0.020264268 | G12: 0.018531783 | H12: 0.18907876 | I12: 0.15110532 | J12: 0.02 | K12: -0.018766489 | N12: 0 | O12: 0.1623832 | R12: 0.05 | S12: 0.13 | W12: DeepPhylo | X12: 0.35 | Y12: 0.244939 | Z12: 0.04 | AA12: 0.09426337 | AB12: 0.61 | AC12: 0.36399765 | AF12: Phylospec – merged | AG12: =AVERAGE(R8,R14,R20) -> 0.31 | AH12: =AVERAGE(S8,S14,S20) -> 0.29666667 | AI12: =AH12-AG12 -> -0.013333333
A13: BAC | B13: acid_accumulation | C13: 4 | D13: 0.03 | E13: 0.10345807 | F13: 0.16146929 | G13: 0.56878149 | H13: 0.18864023 | I13: 0.23061453 | J13: 0.05 | K13: 0.095461363 | N13: 0.03 | O13: 0.051701861 | R13: -0.06 | S13: 0.13 | W13: MetaDR | X13: 0.18 | Y13: 0.31782198 | Z13: -0.02 | AA13: 0.15957805 | AB13: 0.56 | AC13: 0.62256924
A14: merged | B14: acid_accumulation | C14: 4 | D14: 0.03 | E14: 0.12874781 | F14: 0.10028394 | G14: 0.5998391 | H14: 0.23352612 | I14: 0.15956732 | J14: 0.04 | K14: 0.09426337 | L14: 0.07 | M14: 0.1241 | N14: -0.02 | O14: 0.15957805 | P14: 0.0232 | Q14: -0.0267 | R14: 0.03 | S14: 0.1 | T14: 0.04 | U14: 0.0132 | W14: Phylospec | X14: 0.3 | Y14: 0.32 | Z14: 0.03 | AA14: 0.1 | AB14: 0.6 | AC14: 0.47
AF15: AUPR
AF16: Model / Dataset | AG16: ASV-tree | AH16: Genus-tree | AI16: Δ (Genus − ASV)
AF17: DeepPhylo – ARC | AG17: =AVERAGE(J27,J33,J39) -> 0.32 | AH17: =AVERAGE(K27,K33,K39) -> 0.15745659 | AI17: =AH17-AG17 -> -0.16254341
A18: ARC | B18: ammonia_toxicity | C18: 26 | D18: 0.1884058 | E18: 0.45223521 | F18: 0.45998774 | G18: 0.46218151 | H18: 0.41792079 | I18: 0.47334208 | J18: 0.53 | K18: 0.074796835 | N18: 0.43 | O18: 0.46595376 | R18: 0.6 | S18: 0.44 | AF18: DeepPhylo – BAC | AG18: =AVERAGE(J28,J34,J40) -> 0.31297346 | AH18: =AVERAGE(K28,K34,K40) -> 0.2550121 | AI18: =AH18-AG18 -> -0.05796136
A19: BAC | B19: ammonia_toxicity | C19: 26 | D19: 0.1884058 | E19: 0.59016947 | F19: 0.54226443 | G19: 0.58680827 | H19: 0.52900518 | I19: 0.46969523 | J19: 0.61 | K19: 0.45708668 | N19: 0.67 | O19: 0.64317581 | R19: 0.47 | S19: 0.56 | AF19: DeepPhylo – merged | AG19: =AVERAGE(J29,J35,J41) -> 0.36 | AH19: =AVERAGE(K29,K35,K41) -> 0.28042513 | AI19: =AH19-AG19 -> -0.079574867
A20: merged | B20: ammonia_toxicity | C20: 26 | D20: 0.1884058 | E20: 0.65994753 | F20: 0.56752175 | G20: 0.57332093 | H20: 0.5428725 | I20: 0.47163898 | J20: 0.61 | K20: 0.36399765 | L20: 0.57 | M20: 0.5697 | N20: 0.56 | O20: 0.62256924 | P20: 0.5984 | Q20: 0.5309 | R20: 0.6 | S20: 0.47 | T20: 0.5121 | U20: 0.6091 | AF20: MetaDR – ARC | AG20: =AVERAGE(N27,N33,N39) -> 0.27543125 | AH20: =AVERAGE(O27,O33,O39) -> 0.3034123 | AI20: =AH20-AG20 -> 0.027981049
AF21: MetaDR – BAC | AG21: =AVERAGE(N28,N34,N40) -> 0.35 | AH21: =AVERAGE(O28,O34,O40) -> 0.34008961 | AI21: =AH21-AG21 -> -0.0099103871
AF22: MetaDR – merged | AG22: =AVERAGE(N29,N35,N41) -> 0.31333333 | AH22: =AVERAGE(O29,O35,O41) -> 0.31802355 | AI22: =AH22-AG22 -> 0.0046902195
AF23: Phylospec – ARC | AG23: =AVERAGE(R27,R33,R39) -> 0.38333333 | AH23: =AVERAGE(S27,S33,S39) -> 0.27666667 | AI23: =AH23-AG23 -> -0.10666667
B24: AUPR | AF24: Phylospec – BAC | AG24: =AVERAGE(R28,R34,R40) -> 0.33666667 | AH24: =AVERAGE(S28,S34,S40) -> 0.40666667 | AI24: =AH24-AG24 -> 0.07
E25: TaxLevel | J25: DeepPhylo | N25: MetaDR | R25: Phylospec | AF25: Phylospec – merged | AG25: =AVERAGE(R29,R35,R41) -> 0.33666667 | AH25: =AVERAGE(S29,S35,S41) -> 0.35333333 | AI25: =AH25-AG25 -> 0.016666667
E26: Phylum | F26: Class | G26: Order | H26: Family | I26: Genus | J26: ASV-tree | K26: Genus-tree | L26: Genus-tree + cross-domain | M26: ASV-tree + cross-domain | N26: ASV-tree | O26: Genus-tree | P26: Genus-tree + cross-domain | Q26: ASV-tree + cross-domain | R26: ASV-tree | S26: Genus-tree | T26: Genus-tree + cross-domain | U26: ASV-tree + cross-domain
A27: ARC | B27: acid_base_balance | C27: 20 | D27: 0.14 | E27: 0.30912546 | F27: 0.28527646 | G27: 0.29751069 | H27: 0.2954604 | I27: 0.2753116 | J27: 0.26 | K27: 0.19914532 | N27: 0.23 | O27: 0.26310702 | R27: 0.25 | S27: 0.25
A28: BAC | B28: acid_base_balance | C28: 20 | D28: 0.14 | E28: 0.52102532 | F28: 0.36604017 | G28: 0.32250783 | H28: 0.41313067 | I28: 0.27518425 | J28: 0.33 | K28: 0.31113045 | N28: 0.28 | O28: 0.35132294 | R28: 0.44 | S28: 0.49 | AF28: F2
A29: merged | B29: acid_base_balance | C29: 20 | D29: 0.14 | E29: 0.4428282 | F29: 0.33047091 | G29: 0.28956776 | H29: 0.36612731 | I29: 0.24454188 | J29: 0.36 | K29: 0.2758899 | L29: 0.29 | M29: 0.3119 | N29: 0.28 | O29: 0.32762517 | P29: 0.3175 | Q29: 0.253 | R29: 0.43 | S29: 0.4 | T29: 0.39 | U29: 0.4619 | AF29: Model / Dataset | AG29: ASV-tree | AH29: Genus-tree | AI29: Δ (Genus − ASV)
AF30: DeepPhylo – ARC | AG30: =AVERAGE(J49,J55,J61) -> 0.42 | AH30: =AVERAGE(K49,K55,K61) -> 0.2478498 | AI30: =AH30-AG30 -> -0.1721502
AF31: DeepPhylo – BAC | AG31: =AVERAGE(J50,J56,J62) -> 0.46333333 | AH31: =AVERAGE(K50,K56,K62) -> 0.43976504 | AI31: =AH31-AG31 -> -0.023568291
AF32: DeepPhylo – merged | AG32: =AVERAGE(J51,J57,J63) -> 0.49333333 | AH32: =AVERAGE(K51,K57,K63) -> 0.42037615 | AI32: =AH32-AG32 -> -0.072957183
A33: ARC | B33: acid_accumulation | C33: 4 | D33: 0.03 | E33: 0.04387025 | F33: 0.032770812 | G33: 0.033856557 | H33: 0.24138277 | I33: 0.12146046 | J33: 0.06 | K33: 0.0290697 | N33: 0.04 | O33: 0.090836132 | R33: 0.23 | S33: 0.09 | AF33: MetaDR – ARC | AG33: =AVERAGE(N49,N55,N61) -> 0.34333333 | AH33: =AVERAGE(O49,O55,O61) -> 0.48718906 | AI33: =AH33-AG33 -> 0.14385573
A34: BAC | B34: acid_accumulation | C34: 4 | D34: 0.03 | E34: 0.11100671 | F34: 0.12507044 | G34: 0.47601162 | H34: 0.3250534 | I34: 0.31477276 | J34: 0.048920377 | K34: 0.048920377 | N34: 0.05 | O34: 0.068876451 | R34: 0.09 | S34: 0.21 | AF34: MetaDR – BAC | AG34: =AVERAGE(N50,N56,N62) -> 0.47666667 | AH34: =AVERAGE(O50,O56,O62) -> 0.48267307 | AI34: =AH34-AG34 -> 0.0060064022
A35: merged | B35: acid_accumulation | C35: 4 | D35: 0.03 | E35: 0.11283035 | F35: 0.11767013 | G35: 0.53659149 | H35: 0.32220543 | I35: 0.25000163 | J35: 0.06 | K35: 0.13327345 | L35: 0.14 | M35: 0.0886 | N35: 0.04 | O35: 0.060043342 | P35: 0.0441 | Q35: 0.0387 | R35: 0.05 | S35: 0.16 | T35: 0.04 | U35: 0.0532 | AF35: MetaDR – merged | AG35: =AVERAGE(N51,N57,N63) -> 0.40333333 | AH35: =AVERAGE(O51,O57,O63) -> 0.5373011 | AI35: =AH35-AG35 -> 0.13396776
AF36: Phylospec – ARC | AG36: =AVERAGE(R49,R55,R61) -> 0.43333333 | AH36: =AVERAGE(S49,S55,S61) -> 0.44666667 | AI36: =AH36-AG36 -> 0.013333333
AF37: Phylospec – BAC | AG37: =AVERAGE(R50,R56,R62) -> 0.38666667 | AH37: =AVERAGE(S50,S56,S62) -> 0.49 | AI37: =AH37-AG37 -> 0.10333333
AF38: Phylospec – merged | AG38: =AVERAGE(R51,R57,R63) -> 0.46666667 | AH38: =AVERAGE(S51,S57,S63) -> 0.46 | AI38: =AH38-AG38 -> -0.0066666667
A39: ARC | B39: ammonia_toxicity | C39: 26 | D39: 0.1884058 | E39: 0.59791791 | F39: 0.57107802 | G39: 0.56936985 | H39: 0.54890359 | I39: 0.59006766 | J39: 0.64 | K39: 0.24415475 | N39: 0.55629374 | O39: 0.55629374 | R39: 0.67 | S39: 0.49
A40: BAC | B40: ammonia_toxicity | C40: 26 | D40: 0.1884058 | E40: 0.62860735 | F40: 0.7167336 | G40: 0.6408588 | H40: 0.54247206 | I40: 0.45518907 | J40: 0.56 | K40: 0.40498547 | N40: 0.72 | O40: 0.60006945 | R40: 0.48 | S40: 0.52 | AF40: Note: each value = mean of the 3 flags for that model/dataset. Δ > 0 (green) = Genus-tree better.
...
